Workbook

Sheet equipo1
A1: CORPORACION CRIOLLITOS DE VENEZUELA
A2: LIGA DE BEISBOL MENOR JUAN GUILLERMO GUZMAN
B4: CATEGORIA : INFANTIL
A6: Equipo 1 | C6: O F E N S I V A I N D I V I D U A L
A7: NOMBRE | B7: No | C7: VB | D7: CA | E7: H | F7: 2B | G7: 3B | H7: HR | I7: CI | J7: K | K7: BB | L7: BR | M7: GP | N7: SH | O7: SF | P7: INT | Q7: BAL | R7: AL | T7: VB | U7: CA | V7: H | W7: 2B | X7: 3B | Y7: HR | Z7: CI | AA7: K | AB7: BB | AC7: BR | AD7: GP | AE7: SH | AF7: SF | AG7: INT | AH7: BAL | AI7: AL | AK7: VB | AL7: CA | AM7: H | AN7: 2B | AO7: 3B | AP7: HR | AQ7: CI | AR7: K | AS7: BB | AT7: BR | AU7: GP | AV7: SH | AW7: SF | AX7: INT | AY7: BAL | AZ7: AL | BB7: VB | BC7: CA | BD7: H | BE7: 2B | BF7: 3B | BG7: HR | BH7: CI | BI7: K | BJ7: BB | BK7: BR | BL7: GP | BM7: SH | BN7: SF | BO7: INT | BP7: BAL | BQ7: AL | BS7: VB | BT7: CA | BU7: H | BV7: 2B | BW7: 3B | BX7: HR | BY7: CI | BZ7: K | CA7: BB | CB7: BR | CC7: GP | CD7: SH | CE7: SF | CF7: INT | CG7: BAL | CH7: AL | CJ7: VB | CK7: CA | CL7: H | CM7: 2B | CN7: 3B | CO7: HR | CP7: CI | CQ7: K | CR7: BB | CS7: BR | CT7: GP | CU7: SH | CV7: SF | CW7: INT | CX7: BAL | CY7: AL | DA7: VB | DB7: CA | DC7: H | DD7: 2B | DE7: 3B | DF7: HR | DG7: CI | DH7: K | DI7: BB | DJ7: BR | DK7: GP | DL7: SH | DM7: SF | DN7: INT | DO7: BAL | DP7: AL | DR7: VB | DS7: CA | DT7: H | DU7: 2B | DV7: 3B | DW7: HR | DX7: CI | DY7: K | DZ7: BB | EA7: BR | EB7: GP | EC7: SH | ED7: SF | EE7: INT | EF7: BAL | EG7: AL | EI7: VB | EJ7: CA | EK7: H | EL7: 2B | EM7: 3B | EN7: HR | EO7: CI | EP7: K | EQ7: BB | ER7: BR | ES7: GP | ET7: SH | EU7: SF | EV7: INT | EW7: BAL | EX7: AL | EZ7: VB | FA7: CA | FB7: H | FC7: 2B | FD7: 3B | FE7: HR | FF7: CI | FG7: K | FH7: BB | FI7: BR | FJ7: GP | FK7: SH | FL7: SF | FM7: INT | FN7: BAL | FO7: AL | FQ7: VB | FR7: CA | FS7: H | FT7: 2B | FU7: 3B | FV7: HR | FW7: CI | FX7: K | FY7: BB | FZ7: BR | GA7: GP | GB7: SH | GC7: SF | GD7: INT | GE7: BAL | GF7: AL | GH7: VB | GI7: CA | GJ7: H | GK7: 2B | GL7: 3B | GM7: HR | GN7: CI | GO7: K | GP7: BB | GQ7: BR | GR7: GP | GS7: SH | GT7: SF | GU7: INT | GV7: BAL | GW7: AL | GY7: VB | GZ7: CA | HA7: H | HB7: 2B | HC7: 3B | HD7: HR | HE7: CI | HF7: K | HG7: BB | HH7: BR | HI7: GP | HJ7: SH | HK7: SF | HL7: INT | HM7: BAL | HN7: AL | HP7: VB | HQ7: CA | HR7: H | HS7: 2B | HT7: 3B | HU7: HR | HV7: CI | HW7: K | HX7: BB | HY7: BR | HZ7: GP | IA7: SH | IB7: SF | IC7: INT | ID7: BAL | IE7: AL | IG7: VB | IH7: CA | II7: H | IJ7: 2B | IK7: 3B | IL7: HR | IM7: CI | IN7: K | IO7: BB | IP7: BR | IQ7: GP | IR7: SH | IS7: SF | IT7: INT | IU7: BAL | IV7: AL
A8: Luis Garcia | B8: 1 | C8: 5 | D8: 4 | E8: 0 | F8: 0 | G8: 0 | H8: 0 | I8: 0 | J8: 2 | K8: 2 | L8: 0 | M8: 0 | N8: 1 | O8: 0 | P8: 0 | Q8: =(E8-(F8+G8+H8))+(F8*2)+(G8*3)+(H8*4) -> 0 | R8: =C8+K8+M8+N8+O8+P8 -> 8 | T8: 2 | U8: 1 | V8: 0 | W8: 0 | X8: 0 | Y8: 0 | Z8: 1 | AA8: 0 | AB8: 0 | AC8: 0 | AD8: 0 | AE8: 0 | AF8: 1 | AG8: 0 | AH8: =(V8-(W8+X8+Y8))+(W8*2)+(X8*3)+(Y8*4) -> 0 | AI8: =T8+AB8+AD8+AE8+AF8+AG8 -> 3
A9: Luis Rodriguez | B9: 2 | C9: 2 | D9: 1 | E9: 1 | F9: 0 | G9: 0 | H9: 0 | I9: 1 | J9: 0 | K9: 2 | L9: 0 | M9: 1 | N9: 0 | O9: 0 | P9: 0 | Q9: =(E9-(F9+G9+H9))+(F9*2)+(G9*3)+(H9*4) -> 1 | R9: =C9+K9+M9+N9+O9+P9 -> 5 | T9: 2 | U9: 0 | V9: 1 | W9: 0 | X9: 0 | Y9: 0 | Z9: 0 | AA9: 2 | AB9: 1 | AC9: 0 | AD9: 0 | AE9: 0 | AF9: 0 | AG9: 0 | AH9: =(V9-(W9+X9+Y9))+(W9*2)+(X9*3)+(Y9*4) -> 1 | AI9: =T9+AB9+AD9+AE9+AF9+AG9 -> 3
A10: Luis Martinez | B10: 3 | C10: 5 | D10: 2 | E10: 0 | F10: 0 | G10: 0 | H10: 0 | I10: 0 | J10: 1 | K10: 0 | L10: 1 | M10: 0 | N10: 1 | O10: 1 | P10: 0 | Q10: =(E10-(F10+G10+H10))+(F10*2)+(G10*3)+(H10*4) -> 0 | R10: =C10+K10+M10+N10+O10+P10 -> 7 | T10: 5 | U10: 3 | V10: 2 | W10: 0 | X10: 0 | Y10: 1 | Z10: 1 | AA10: 1 | AB10: 2 | AC10: 1 | AD10: 1 | AE10: 1 | AF10: 0 | AG10: 0 | AH10: =(V10-(W10+X10+Y10))+(W10*2)+(X10*3)+(Y10*4) -> 5 | AI10: =T10+AB10+AD10+AE10+AF10+AG10 -> 9
A11: Luis Hernandez | B11: 4 | C11: 4 | D11: 1 | E11: 1 | F11: 0 | G11: 0 | H11: 0 | I11: 2 | J11: 1 | K11: 0 | L11: 1 | M11: 1 | N11: 0 | O11: 0 | P11: 0 | Q11: =(E11-(F11+G11+H11))+(F11*2)+(G11*3)+(H11*4) -> 1 | R11: =C11+K11+M11+N11+O11+P11 -> 5 | T11: 5 | U11: 4 | V11: 1 | W11: 1 | X11: 0 | Y11: 0 | Z11: 0 | AA11: 2 | AB11: 1 | AC11: 1 | AD11: 1 | AE11: 0 | AF11: 1 | AG11: 0 | AH11: =(V11-(W11+X11+Y11))+(W11*2)+(X11*3)+(Y11*4) -> 2 | AI11: =T11+AB11+AD11+AE11+AF11+AG11 -> 8
A12: Luis Lopez | B12: 5 | C12: 3 | D12: 1 | E12: 0 | F12: 0 | G12: 0 | H12: 0 | I12: 1 | J12: 0 | K12: 2 | L12: 1 | M12: 0 | N12: 0 | O12: 1 | P12: 0 | Q12: =(E12-(F12+G12+H12))+(F12*2)+(G12*3)+(H12*4) -> 0 | R12: =C12+K12+M12+N12+O12+P12 -> 6 | T12: 2 | U12: 2 | V12: 1 | W12: 0 | X12: 0 | Y12: 0 | Z12: 1 | AA12: 1 | AB12: 0 | AC12: 0 | AD12: 0 | AE12: 0 | AF12: 0 | AG12: 0 | AH12: =(V12-(W12+X12+Y12))+(W12*2)+(X12*3)+(Y12*4) -> 1 | AI12: =T12+AB12+AD12+AE12+AF12+AG12 -> 2
A13: Luis Gonzalez | B13: 6 | C13: 2 | D13: 0 | E13: 2 | F13: 1 | G13: 0 | H13: 0 | I13: 3 | J13: 1 | K13: 2 | L13: 1 | M13: 0 | N13: 1 | O13: 1 | P13: 0 | Q13: =(E13-(F13+G13+H13))+(F13*2)+(G13*3)+(H13*4) -> 3 | R13: =C13+K13+M13+N13+O13+P13 -> 6 | T13: 4 | U13: 4 | V13: 3 | W13: 0 | X13: 0 | Y13: 0 | Z13: 0 | AA13: 1 | AB13: 1 | AC13: 1 | AD13: 1 | AE13: 1 | AF13: 0 | AG13: 0 | AH13: =(V13-(W13+X13+Y13))+(W13*2)+(X13*3)+(Y13*4) -> 3 | AI13: =T13+AB13+AD13+AE13+AF13+AG13 -> 7
A14: Luis Perez | B14: 7 | C14: 4 | D14: 0 | E14: 3 | F14: 0 | G14: 0 | H14: 0 | I14: 0 | J14: 1 | K14: 1 | L14: 1 | M14: 1 | N14: 1 | O14: 0 | P14: 0 | Q14: =(E14-(F14+G14+H14))+(F14*2)+(G14*3)+(H14*4) -> 3 | R14: =C14+K14+M14+N14+O14+P14 -> 7 | T14: 5 | U14: 4 | V14: 5 | W14: 0 | X14: 0 | Y14: 0 | Z14: 2 | AA14: 0 | AB14: 0 | AC14: 1 | AD14: 1 | AE14: 0 | AF14: 1 | AG14: 0 | AH14: =(V14-(W14+X14+Y14))+(W14*2)+(X14*3)+(Y14*4) -> 5 | AI14: =T14+AB14+AD14+AE14+AF14+AG14 -> 7
A15: Luis Sanchez | B15: 8 | C15: 4 | D15: 4 | E15: 2 | F15: 0 | G15: 0 | H15: 0 | I15: 2 | J15: 2 | K15: 1 | L15: 0 | M15: 1 | N15: 0 | O15: 0 | P15: 0 | Q15: =(E15-(F15+G15+H15))+(F15*2)+(G15*3)+(H15*4) -> 2 | R15: =C15+K15+M15+N15+O15+P15 -> 6 | T15: 4 | U15: 4 | V15: 4 | W15: 0 | X15: 0 | Y15: 0 | Z15: 4 | AA15: 2 | AB15: 2 | AC15: 0 | AD15: 0 | AE15: 1 | AF15: 1 | AG15: 0 | AH15: =(V15-(W15+X15+Y15))+(W15*2)+(X15*3)+(Y15*4) -> 4 | AI15: =T15+AB15+AD15+AE15+AF15+AG15 -> 8
A16: Luis Ramirez | B16: 9 | C16: 3 | D16: 0 | E16: 2 | F16: 0 | G16: 0 | H16: 0 | I16: 2 | J16: 1 | K16: 2 | L16: 1 | M16: 0 | N16: 1 | O16: 0 | P16: 0 | Q16: =(E16-(F16+G16+H16))+(F16*2)+(G16*3)+(H16*4) -> 2 | R16: =C16+K16+M16+N16+O16+P16 -> 6 | T16: 2 | U16: 1 | V16: 2 | W16: 0 | X16: 0 | Y16: 0 | Z16: 3 | AA16: 2 | AB16: 2 | AC16: 0 | AD16: 0 | AE16: 0 | AF16: 0 | AG16: 0 | AH16: =(V16-(W16+X16+Y16))+(W16*2)+(X16*3)+(Y16*4) -> 2 | AI16: =T16+AB16+AD16+AE16+AF16+AG16 -> 4
A17: Luis Torres | B17: 10 | C17: 5 | D17: 4 | E17: 2 | F17: 0 | G17: 0 | H17: 0 | I17: 3 | J17: 0 | K17: 1 | L17: 0 | M17: 1 | N17: 1 | O17: 0 | P17: 0 | Q17: =(E17-(F17+G17+H17))+(F17*2)+(G17*3)+(H17*4) -> 2 | R17: =C17+K17+M17+N17+O17+P17 -> 8 | T17: 2 | U17: 2 | V17: 1 | W17: 0 | X17: 0 | Y17: 0 | Z17: 2 | AA17: 1 | AB17: 2 | AC17: 1 | AD17: 0 | AE17: 0 | AF17: 1 | AG17: 0 | AH17: =(V17-(W17+X17+Y17))+(W17*2)+(X17*3)+(Y17*4) -> 1 | AI17: =T17+AB17+AD17+AE17+AF17+AG17 -> 5
A18: Luis Flores | B18: 11 | C18: 5 | D18: 5 | E18: 2 | F18: 0 | G18: 0 | H18: 0 | I18: 0 | J18: 2 | K18: 1 | L18: 1 | M18: 1 | N18: 0 | O18: 0 | P18: 0 | Q18: =(E18-(F18+G18+H18))+(F18*2)+(G18*3)+(H18*4) -> 2 | R18: =C18+K18+M18+N18+O18+P18 -> 7 | T18: 2 | U18: 2 | V18: 0 | W18: 0 | X18: 0 | Y18: 0 | Z18: 0 | AA18: 2 | AB18: 0 | AC18: 1 | AD18: 0 | AE18: 1 | AF18: 1 | AG18: 0 | AH18: =(V18-(W18+X18+Y18))+(W18*2)+(X18*3)+(Y18*4) -> 0 | AI18: =T18+AB18+AD18+AE18+AF18+AG18 -> 4
A19: Luis Rivera | B19: 12 | C19: 2 | D19: 0 | E19: 1 | F19: 0 | G19: 0 | H19: 0 | I19: 0 | J19: 2 | K19: 2 | L19: 1 | M19: 0 | N19: 1 | O19: 1 | P19: 0 | Q19: =(E19-(F19+G19+H19))+(F19*2)+(G19*3)+(H19*4) -> 1 | R19: =C19+K19+M19+N19+O19+P19 -> 6 | T19: 4 | U19: 1 | V19: 2 | W19: 0 | X19: 0 | Y19: 0 | Z19: 0 | AA19: 2 | AB19: 2 | AC19: 1 | AD19: 0 | AE19: 0 | AF19: 1 | AG19: 0 | AH19: =(V19-(W19+X19+Y19))+(W19*2)+(X19*3)+(Y19*4) -> 2 | AI19: =T19+AB19+AD19+AE19+AF19+AG19 -> 7
... A32: Carlos Lopez | B32: 25 | C32: 2 | D32: 1 | E32: 1 | F32: 0 | G32: 0 | H32: 0 | I32: 2 | J32: 1 | K32: 1 | L32: 0 | M32: 1 | N32: 1 | O32: 0 | P32: 0 | Q32: =(E32-(F32+G32+H32))+(F32*2)+(G32*3)+(H32*4) -> 1 | R32: =C32+K32+M32+N32+O32+P32 -> 5 | T32: 3 | U32: 1 | V32: 0 | W32: 0 | X32: 0 | Y32: 0 | Z32: 0 | AA32: 1 | AB32: 1 | AC32: 1 | AD32: 1 | AE32: 1 | AF32: 0 | AG32: 0 | AH32: =(V32-(W32+X32+Y32))+(W32*2)+(X32*3)+(Y32*4) -> 0 | AI32: =T32+AB32+AD32+AE32+AF32+AG32 -> 6
A33: TOTALES : | C33: =SUM(C8:C32) -> 92 | D33: =SUM(D8:D32) -> 48 | E33: =SUM(E8:E32) -> 39 | F33: =SUM(F8:F32) -> 2 | G33: =SUM(G8:G32) -> 2 | H33: =SUM(H8:H32) -> 0 | I33: =SUM(I8:I32) -> 29 | J33: =SUM(J8:J32) -> 26 | ... R33: =SUM(R8:R32) -> 159 | T33: =SUM(T8:T32) -> 87 | U33: =SUM(U8:U32) -> 54 | V33: =SUM(V8:V32) -> 49 | W33: =SUM(W8:W32) -> 1 | X33: =SUM(X8:X32) -> 1 | Y33: =SUM(Y8:Y32) -> 1 | Z33: =SUM(Z8:Z32) -> 41 | AA33: =SUM(AA8:AA32) -> 34 | ... AI33: =SUM(AI8:AI32) -> 153 | AK33: =SUM(AK8:AK32) -> 0 | AL33: =SUM(AL8:AL32) -> 0 | AM33: =SUM(AM8:AM32) -> 0 | AN33: =SUM(AN8:AN32) -> 0 | AO33: =SUM(AO8:AO32) -> 0 | AP33: =SUM(AP8:AP32) -> 0 | AQ33: =SUM(AQ8:AQ32) -> 0 | AR33: =SUM(AR8:AR32) -> 0 | ... AZ33: =SUM(AZ8:AZ32) -> 0 | BB33: =SUM(BB8:BB32) -> 0 | BC33: =SUM(BC8:BC32) -> 0 | BD33: =SUM(BD8:BD32) -> 0 | BE33: =SUM(BE8:BE32) -> 0 | BF33: =SUM(BF8:BF32) -> 0 | BG33: =SUM(BG8:BG32) -> 0 | BH33: =SUM(BH8:BH32) -> 0 | BI33: =SUM(BI8:BI32) -> 0 | ... BQ33: =SUM(BQ8:BQ32) -> 0 | BS33: =SUM(BS8:BS32) -> 0 | BT33: =SUM(BT8:BT32) -> 0 | BU33: =SUM(BU8:BU32) -> 0 | BV33: =SUM(BV8:BV32) -> 0 | BW33: =SUM(BW8:BW32) -> 0 | BX33: =SUM(BX8:BX32) -> 0 | BY33: =SUM(BY8:BY32) -> 0 | BZ33: =SUM(BZ8:BZ32) -> 0 | ... CH33: =SUM(CH8:CH32) -> 0 | CJ33: =SUM(CJ8:CJ32) -> 0 | CK33: =SUM(CK8:CK32) -> 0 | CL33: =SUM(CL8:CL32) -> 0 | CM33: =SUM(CM8:CM32) -> 0 | CN33: =SUM(CN8:CN32) -> 0 | CO33: =SUM(CO8:CO32) -> 0 | CP33: =SUM(CP8:CP32) -> 0 | CQ33: =SUM(CQ8:CQ32) -> 0 | ... CY33: =SUM(CY8:CY32) -> 0 | DA33: =SUM(DA8:DA32) -> 0 | DB33: =SUM(DB8:DB32) -> 0 | DC33: =SUM(DC8:DC32) -> 0 | DD33: =SUM(DD8:DD32) -> 0 | DE33: =SUM(DE8:DE32) -> 0 | DF33: =SUM(DF8:DF32) -> 0 | DG33: =SUM(DG8:DG32) -> 0 | DH33: =SUM(DH8:DH32) -> 0 | ... DP33: =SUM(DP8:DP32) -> 0 | DR33: =SUM(DR8:DR32) -> 0 | DS33: =SUM(DS8:DS32) -> 0 | DT33: =SUM(DT8:DT32) -> 0 | DU33: =SUM(DU8:DU32) -> 0 | DV33: =SUM(DV8:DV32) -> 0 | DW33: =SUM(DW8:DW32) -> 0 | DX33: =SUM(DX8:DX32) -> 0 | DY33: =SUM(DY8:DY32) -> 0 | ... EG33: =SUM(EG8:EG32) -> 0 | EI33: =SUM(EI8:EI32) -> 0 | EJ33: =SUM(EJ8:EJ32) -> 0 | EK33: =SUM(EK8:EK32) -> 0 | EL33: =SUM(EL8:EL32) -> 0 | EM33: =SUM(EM8:EM32) -> 0 | EN33: =SUM(EN8:EN32) -> 0 | EO33: =SUM(EO8:EO32) -> 0 | EP33: =SUM(EP8:EP32) -> 0 | ... EX33: =SUM(EX8:EX32) -> 0 | EZ33: =SUM(EZ8:EZ32) -> 0 | FA33: =SUM(FA8:FA32) -> 0 | FB33: =SUM(FB8:FB32) -> 0 | FC33: =SUM(FC8:FC32) -> 0 | FD33: =SUM(FD8:FD32) -> 0 | FE33: =SUM(FE8:FE32) -> 0 | FF33: =SUM(FF8:FF32) -> 0 | FG33: =SUM(FG8:FG32) -> 0 | ... FO33: =SUM(FO8:FO32) -> 0 | FQ33: =SUM(FQ8:FQ32) -> 0 | FR33: =SUM(FR8:FR32) -> 0 | FS33: =SUM(FS8:FS32) -> 0 | FT33: =SUM(FT8:FT32) -> 0 | FU33: =SUM(FU8:FU32) -> 0 | FV33: =SUM(FV8:FV32) -> 0 | FW33: =SUM(FW8:FW32) -> 0 | FX33: =SUM(FX8:FX32) -> 0 | ... GF33: =SUM(GF8:GF32) -> 0 | GH33: =SUM(GH8:GH32) -> 0 | GI33: =SUM(GI8:GI32) -> 0 | GJ33: =SUM(GJ8:GJ32) -> 0 | GK33: =SUM(GK8:GK32) -> 0 | GL33: =SUM(GL8:GL32) -> 0 | GM33: =SUM(GM8:GM32) -> 0 | GN33: =SUM(GN8:GN32) -> 0 | GO33: =SUM(GO8:GO32) -> 0 | ... GW33: =SUM(GW8:GW32) -> 0 | GY33: =SUM(GY8:GY32) -> 0 | GZ33: =SUM(GZ8:GZ32) -> 0 | HA33: =SUM(HA8:HA32) -> 0 | HB33: =SUM(HB8:HB32) -> 0 | HC33: =SUM(HC8:HC32) -> 0 | HD33: =SUM(HD8:HD32) -> 0 | HE33: =SUM(HE8:HE32) -> 0 | HF33: =SUM(HF8:HF32) -> 0 | ... HN33: =SUM(HN8:HN32) -> 0 | HP33: =SUM(HP8:HP32) -> 0 | HQ33: =SUM(HQ8:HQ32) -> 0 | HR33: =SUM(HR8:HR32) -> 0 | HS33: =SUM(HS8:HS32) -> 0 | HT33: =SUM(HT8:HT32) -> 0 | HU33: =SUM(HU8:HU32) -> 0 | HV33: =SUM(HV8:HV32) -> 0 | HW33: =SUM(HW8:HW32) -> 0 | ... IE33: =SUM(IE8:IE32) -> 0 | IG33: =SUM(IG8:IG32) -> 0 | IH33: =SUM(IH8:IH32) -> 0 | II33: =SUM(II8:II32) -> 0 | IJ33: =SUM(IJ8:IJ32) -> 0 | IK33: =SUM(IK8:IK32) -> 0 | IL33: =SUM(IL8:IL32) -> 0 | IM33: =SUM(IM8:IM32) -> 0 | IN33: =SUM(IN8:IN32) -> 0 | ... IV33: =SUM(IV8:IV32) -> 0
A35: LIDERES INDIVIDUAL
A36: NOMBRE | B36: No | C36: VB | D36: CA | E36: H | F36: 2B | G36: 3B | H36: HR | I36: CI | J36: K | K36: BB | L36: BR | M36: GP | N36: SH | O36: SF | P36: INT | Q36: BAL | R36: AL | T36: AV | U36: SLG
A37: =IF(A8="","",A8) -> Luis Garcia | B37: =IF(B8="","",B8) -> 1 | C37: =C8+T8+AK8+BB8+BS8+CJ8+DA8+DR8+EI8+EZ8+FQ8+GH8+GY8+HP8+IG8 -> 7 | D37: =D8+U8+AL8+BC8+BT8+CK8+DB8+DS8+EJ8+FA8+FR8+GI8+GZ8+HQ8+IH8 -> 5 | E37: =E8+V8+AM8+BD8+BU8+CL8+DC8+DT8+EK8+FB8+FS8+GJ8+HA8+HR8+II8 -> 0 | F37: =F8+W8+AN8+BE8+BV8+CM8+DD8+DU8+EL8+FC8+FT8+GK8+HB8+HS8+IJ8 -> 0 | G37: =G8+X8+AO8+BF8+BW8+CN8+DE8+DV8+EM8+FD8+FU8+GL8+HC8+HT8+IK8 -> 0 | H37: =H8+Y8+AP8+BG8+BX8+CO8+DF8+DW8+EN8+FE8+FV8+GM8+HD8+HU8+IL8 -> 0 | I37: =I8+Z8+AQ8+BH8+BY8+CP8+DG8+DX8+EO8+FF8+FW8+GN8+HE8+HV8+IM8 -> 1 | J37: =J8+AA8+AR8+BI8+BZ8+CQ8+DH8+DY8+EP8+FG8+FX8+GO8+HF8+HW8+IN8 -> 2 | ... R37: =R8+AI8+AZ8+BQ8+CH8+CY8+DP8+EG8+EX8+FO8+GF8+GW8+HN8+IE8+IV8 -> 11 | T37: =IFERROR(E37/C37,0) -> 0 | U37: =IFERROR(Q37/C37,0) -> 0
A38: =IF(A9="","",A9) -> Luis Rodriguez | B38: =IF(B9="","",B9) -> 2 | C38: =C9+T9+AK9+BB9+BS9+CJ9+DA9+DR9+EI9+EZ9+FQ9+GH9+GY9+HP9+IG9 -> 4 | D38: =D9+U9+AL9+BC9+BT9+CK9+DB9+DS9+EJ9+FA9+FR9+GI9+GZ9+HQ9+IH9 -> 1 | E38: =E9+V9+AM9+BD9+BU9+CL9+DC9+DT9+EK9+FB9+FS9+GJ9+HA9+HR9+II9 -> 2 | F38: =F9+W9+AN9+BE9+BV9+CM9+DD9+DU9+EL9+FC9+FT9+GK9+HB9+HS9+IJ9 -> 0 | G38: =G9+X9+AO9+BF9+BW9+CN9+DE9+DV9+EM9+FD9+FU9+GL9+HC9+HT9+IK9 -> 0 | H38: =H9+Y9+AP9+BG9+BX9+CO9+DF9+DW9+EN9+FE9+FV9+GM9+HD9+HU9+IL9 -> 0 | I38: =I9+Z9+AQ9+BH9+BY9+CP9+DG9+DX9+EO9+FF9+FW9+GN9+HE9+HV9+IM9 -> 1 | J38: =J9+AA9+AR9+BI9+BZ9+CQ9+DH9+DY9+EP9+FG9+FX9+GO9+HF9+HW9+IN9 -> 2 | ... R38: =R9+AI9+AZ9+BQ9+CH9+CY9+DP9+EG9+EX9+FO9+GF9+GW9+HN9+IE9+IV9 -> 8 | T38: =IFERROR(E38/C38,0) -> 0.5 | U38: =IFERROR(Q38/C38,0) -> 0.5
A39: =IF(A10="","",A10) -> Luis Martinez | B39: =IF(B10="","",B10) -> 3 | C39: =C10+T10+AK10+BB10+BS10+CJ10+DA10+DR10+EI10+EZ10+FQ10+GH10+GY10+HP10+IG10 -> 10 | D39: =D10+U10+AL10+BC10+BT10+CK10+DB10+DS10+EJ10+FA10+FR10+GI10+GZ10+HQ10+IH10 -> 5 | E39: =E10+V10+AM10+BD10+BU10+CL10+DC10+DT10+EK10+FB10+FS10+GJ10+HA10+HR10+II10 -> 2 | F39: =F10+W10+AN10+BE10+BV10+CM10+DD10+DU10+EL10+FC10+FT10+GK10+HB10+HS10+IJ10 -> 0 | G39: =G10+X10+AO10+BF10+BW10+CN10+DE10+DV10+EM10+FD10+FU10+GL10+HC10+HT10+IK10 -> 0 | H39: =H10+Y10+AP10+BG10+BX10+CO10+DF10+DW10+EN10+FE10+FV10+GM10+HD10+HU10+IL10 -> 1 | I39: =I10+Z10+AQ10+BH10+BY10+CP10+DG10+DX10+EO10+FF10+FW10+GN10+HE10+HV10+IM10 -> 1 | J39: =J10+AA10+AR10+BI10+BZ10+CQ10+DH10+DY10+EP10+FG10+FX10+GO10+HF10+HW10+IN10 -> 2 | ... R39: =R10+AI10+AZ10+BQ10+CH10+CY10+DP10+EG10+EX10+FO10+GF10+GW10+HN10+IE10+IV10 -> 16 | T39: =IFERROR(E39/C39,0) -> 0.2 | U39: =IFERROR(Q39/C39,0) -> 0.5
A40: =IF(A11="","",A11) -> Luis Hernandez | B40: =IF(B11="","",B11) -> 4 | C40: =C11+T11+AK11+BB11+BS11+CJ11+DA11+DR11+EI11+EZ11+FQ11+GH11+GY11+HP11+IG11 -> 9 | D40: =D11+U11+AL11+BC11+BT11+CK11+DB11+DS11+EJ11+FA11+FR11+GI11+GZ11+HQ11+IH11 -> 5 | E40: =E11+V11+AM11+BD11+BU11+CL11+DC11+DT11+EK11+FB11+FS11+GJ11+HA11+HR11+II11 -> 2 | F40: =F11+W11+AN11+BE11+BV11+CM11+DD11+DU11+EL11+FC11+FT11+GK11+HB11+HS11+IJ11 -> 1 | G40: =G11+X11+AO11+BF11+BW11+CN11+DE11+DV11+EM11+FD11+FU11+GL11+HC11+HT11+IK11 -> 0 | H40: =H11+Y11+AP11+BG11+BX11+CO11+DF11+DW11+EN11+FE11+FV11+GM11+HD11+HU11+IL11 -> 0 | I40: =I11+Z11+AQ11+BH11+BY11+CP11+DG11+DX11+EO11+FF11+FW11+GN11+HE11+HV11+IM11 -> 2 | J40: =J11+AA11+AR11+BI11+BZ11+CQ11+DH11+DY11+EP11+FG11+FX11+GO11+HF11+HW11+IN11 -> 3 | ... R40: =R11+AI11+AZ11+BQ11+CH11+CY11+DP11+EG11+EX11+FO11+GF11+GW11+HN11+IE11+IV11 -> 13 | T40: =IFERROR(E40/C40,0) -> 0.22222222 | U40: =IFERROR(Q40/C40,0) -> 0.33333333
A41: =IF(A12="","",A12) -> Luis Lopez | B41: =IF(B12="","",B12) -> 5 | C41: =C12+T12+AK12+BB12+BS12+CJ12+DA12+DR12+EI12+EZ12+FQ12+GH12+GY12+HP12+IG12 -> 5 | D41: =D12+U12+AL12+BC12+BT12+CK12+DB12+DS12+EJ12+FA12+FR12+GI12+GZ12+HQ12+IH12 -> 3 | E41: =E12+V12+AM12+BD12+BU12+CL12+DC12+DT12+EK12+FB12+FS12+GJ12+HA12+HR12+II12 -> 1 | F41: =F12+W12+AN12+BE12+BV12+CM12+DD12+DU12+EL12+FC12+FT12+GK12+HB12+HS12+IJ12 -> 0 | G41: =G12+X12+AO12+BF12+BW12+CN12+DE12+DV12+EM12+FD12+FU12+GL12+HC12+HT12+IK12 -> 0 | H41: =H12+Y12+AP12+BG12+BX12+CO12+DF12+DW12+EN12+FE12+FV12+GM12+HD12+HU12+IL12 -> 0 | I41: =I12+Z12+AQ12+BH12+BY12+CP12+DG12+DX12+EO12+FF12+FW12+GN12+HE12+HV12+IM12 -> 2 | J41: =J12+AA12+AR12+BI12+BZ12+CQ12+DH12+DY12+EP12+FG12+FX12+GO12+HF12+HW12+IN12 -> 1 | ... R41: =R12+AI12+AZ12+BQ12+CH12+CY12+DP12+EG12+EX12+FO12+GF12+GW12+HN12+IE12+IV12 -> 8 | T41: =IFERROR(E41/C41,0) -> 0.2 | U41: =IFERROR(Q41/C41,0) -> 0.2
A42: =IF(A13="","",A13) -> Luis Gonzalez | B42: =IF(B13="","",B13) -> 6 | C42: =C13+T13+AK13+BB13+BS13+CJ13+DA13+DR13+EI13+EZ13+FQ13+GH13+GY13+HP13+IG13 -> 6 | D42: =D13+U13+AL13+BC13+BT13+CK13+DB13+DS13+EJ13+FA13+FR13+GI13+GZ13+HQ13+IH13 -> 4 | E42: =E13+V13+AM13+BD13+BU13+CL13+DC13+DT13+EK13+FB13+FS13+GJ13+HA13+HR13+II13 -> 5 | F42: =F13+W13+AN13+BE13+BV13+CM13+DD13+DU13+EL13+FC13+FT13+GK13+HB13+HS13+IJ13 -> 1 | G42: =G13+X13+AO13+BF13+BW13+CN13+DE13+DV13+EM13+FD13+FU13+GL13+HC13+HT13+IK13 -> 0 | H42: =H13+Y13+AP13+BG13+BX13+CO13+DF13+DW13+EN13+FE13+FV13+GM13+HD13+HU13+IL13 -> 0 | I42: =I13+Z13+AQ13+BH13+BY13+CP13+DG13+DX13+EO13+FF13+FW13+GN13+HE13+HV13+IM13 -> 3 | J42: =J13+AA13+AR13+BI13+BZ13+CQ13+DH13+DY13+EP13+FG13+FX13+GO13+HF13+HW13+IN13 -> 2 | ... R42: =R13+AI13+AZ13+BQ13+CH13+CY13+DP13+EG13+EX13+FO13+GF13+GW13+HN13+IE13+IV13 -> 13 | T42: =IFERROR(E42/C42,0) -> 0.83333333 | U42: =IFERROR(Q42/C42,0) -> 1
A43: =IF(A14="","",A14) -> Luis Perez | B43: =IF(B14="","",B14) -> 7 | C43: =C14+T14+AK14+BB14+BS14+CJ14+DA14+DR14+EI14+EZ14+FQ14+GH14+GY14+HP14+IG14 -> 9 | D43: =D14+U14+AL14+BC14+BT14+CK14+DB14+DS14+EJ14+FA14+FR14+GI14+GZ14+HQ14+IH14 -> 4 | E43: =E14+V14+AM14+BD14+BU14+CL14+DC14+DT14+EK14+FB14+FS14+GJ14+HA14+HR14+II14 -> 8 | F43: =F14+W14+AN14+BE14+BV14+CM14+DD14+DU14+EL14+FC14+FT14+GK14+HB14+HS14+IJ14 -> 0 | G43: =G14+X14+AO14+BF14+BW14+CN14+DE14+DV14+EM14+FD14+FU14+GL14+HC14+HT14+IK14 -> 0 | H43: =H14+Y14+AP14+BG14+BX14+CO14+DF14+DW14+EN14+FE14+FV14+GM14+HD14+HU14+IL14 -> 0 | I43: =I14+Z14+AQ14+BH14+BY14+CP14+DG14+DX14+EO14+FF14+FW14+GN14+HE14+HV14+IM14 -> 2 | J43: =J14+AA14+AR14+BI14+BZ14+CQ14+DH14+DY14+EP14+FG14+FX14+GO14+HF14+HW14+IN14 -> 1 | ... R43: =R14+AI14+AZ14+BQ14+CH14+CY14+DP14+EG14+EX14+FO14+GF14+GW14+HN14+IE14+IV14 -> 14 | T43: =IFERROR(E43/C43,0) -> 0.88888889 | U43: =IFERROR(Q43/C43,0) -> 0.88888889
A44: =IF(A15="","",A15) -> Luis Sanchez | B44: =IF(B15="","",B15) -> 8 | C44: =C15+T15+AK15+BB15+BS15+CJ15+DA15+DR15+EI15+EZ15+FQ15+GH15+GY15+HP15+IG15 -> 8 | D44: =D15+U15+AL15+BC15+BT15+CK15+DB15+DS15+EJ15+FA15+FR15+GI15+GZ15+HQ15+IH15 -> 8 | E44: =E15+V15+AM15+BD15+BU15+CL15+DC15+DT15+EK15+FB15+FS15+GJ15+HA15+HR15+II15 -> 6 | F44: =F15+W15+AN15+BE15+BV15+CM15+DD15+DU15+EL15+FC15+FT15+GK15+HB15+HS15+IJ15 -> 0 | G44: =G15+X15+AO15+BF15+BW15+CN15+DE15+DV15+EM15+FD15+FU15+GL15+HC15+HT15+IK15 -> 0 | H44: =H15+Y15+AP15+BG15+BX15+CO15+DF15+DW15+EN15+FE15+FV15+GM15+HD15+HU15+IL15 -> 0 | I44: =I15+Z15+AQ15+BH15+BY15+CP15+DG15+DX15+EO15+FF15+FW15+GN15+HE15+HV15+IM15 -> 6 | J44: =J15+AA15+AR15+BI15+BZ15+CQ15+DH15+DY15+EP15+FG15+FX15+GO15+HF15+HW15+IN15 -> 4 | ... R44: =R15+AI15+AZ15+BQ15+CH15+CY15+DP15+EG15+EX15+FO15+GF15+GW15+HN15+IE15+IV15 -> 14 | T44: =IFERROR(E44/C44,0) -> 0.75 | U44: =IFERROR(Q44/C44,0) -> 0.75
A45: =IF(A16="","",A16) -> Luis Ramirez | B45: =IF(B16="","",B16) -> 9 | C45: =C16+T16+AK16+BB16+BS16+CJ16+DA16+DR16+EI16+EZ16+FQ16+GH16+GY16+HP16+IG16 -> 5 | D45: =D16+U16+AL16+BC16+BT16+CK16+DB16+DS16+EJ16+FA16+FR16+GI16+GZ16+HQ16+IH16 -> 1 | E45: =E16+V16+AM16+BD16+BU16+CL16+DC16+DT16+EK16+FB16+FS16+GJ16+HA16+HR16+II16 -> 4 | F45: =F16+W16+AN16+BE16+BV16+CM16+DD16+DU16+EL16+FC16+FT16+GK16+HB16+HS16+IJ16 -> 0 | G45: =G16+X16+AO16+BF16+BW16+CN16+DE16+DV16+EM16+FD16+FU16+GL16+HC16+HT16+IK16 -> 0 | H45: =H16+Y16+AP16+BG16+BX16+CO16+DF16+DW16+EN16+FE16+FV16+GM16+HD16+HU16+IL16 -> 0 | I45: =I16+Z16+AQ16+BH16+BY16+CP16+DG16+DX16+EO16+FF16+FW16+GN16+HE16+HV16+IM16 -> 5 | J45: =J16+AA16+AR16+BI16+BZ16+CQ16+DH16+DY16+EP16+FG16+FX16+GO16+HF16+HW16+IN16 -> 3 | ... R45: =R16+AI16+AZ16+BQ16+CH16+CY16+DP16+EG16+EX16+FO16+GF16+GW16+HN16+IE16+IV16 -> 10 | T45: =IFERROR(E45/C45,0) -> 0.8 | U45: =IFERROR(Q45/C45,0) -> 0.8
A46: =IF(A17="","",A17) -> Luis Torres | B46: =IF(B17="","",B17) -> 10 | C46: =C17+T17+AK17+BB17+BS17+CJ17+DA17+DR17+EI17+EZ17+FQ17+GH17+GY17+HP17+IG17 -> 7 | D46: =D17+U17+AL17+BC17+BT17+CK17+DB17+DS17+EJ17+FA17+FR17+GI17+GZ17+HQ17+IH17 -> 6 | E46: =E17+V17+AM17+BD17+BU17+CL17+DC17+DT17+EK17+FB17+FS17+GJ17+HA17+HR17+II17 -> 3 | F46: =F17+W17+AN17+BE17+BV17+CM17+DD17+DU17+EL17+FC17+FT17+GK17+HB17+HS17+IJ17 -> 0 | G46: =G17+X17+AO17+BF17+BW17+CN17+DE17+DV17+EM17+FD17+FU17+GL17+HC17+HT17+IK17 -> 0 | H46: =H17+Y17+AP17+BG17+BX17+CO17+DF17+DW17+EN17+FE17+FV17+GM17+HD17+HU17+IL17 -> 0 | I46: =I17+Z17+AQ17+BH17+BY17+CP17+DG17+DX17+EO17+FF17+FW17+GN17+HE17+HV17+IM17 -> 5 | J46: =J17+AA17+AR17+BI17+BZ17+CQ17+DH17+DY17+EP17+FG17+FX17+GO17+HF17+HW17+IN17 -> 1 | ... R46: =R17+AI17+AZ17+BQ17+CH17+CY17+DP17+EG17+EX17+FO17+GF17+GW17+HN17+IE17+IV17 -> 13 | T46: =IFERROR(E46/C46,0) -> 0.42857143 | U46: =IFERROR(Q46/C46,0) -> 0.42857143
A47: =IF(A18="","",A18) -> Luis Flores | B47: =IF(B18="","",B18) -> 11 | C47: =C18+T18+AK18+BB18+BS18+CJ18+DA18+DR18+EI18+EZ18+FQ18+GH18+GY18+HP18+IG18 -> 7 | D47: =D18+U18+AL18+BC18+BT18+CK18+DB18+DS18+EJ18+FA18+FR18+GI18+GZ18+HQ18+IH18 -> 7 | E47: =E18+V18+AM18+BD18+BU18+CL18+DC18+DT18+EK18+FB18+FS18+GJ18+HA18+HR18+II18 -> 2 | F47: =F18+W18+AN18+BE18+BV18+CM18+DD18+DU18+EL18+FC18+FT18+GK18+HB18+HS18+IJ18 -> 0 | G47: =G18+X18+AO18+BF18+BW18+CN18+DE18+DV18+EM18+FD18+FU18+GL18+HC18+HT18+IK18 -> 0 | H47: =H18+Y18+AP18+BG18+BX18+CO18+DF18+DW18+EN18+FE18+FV18+GM18+HD18+HU18+IL18 -> 0 | I47: =I18+Z18+AQ18+BH18+BY18+CP18+DG18+DX18+EO18+FF18+FW18+GN18+HE18+HV18+IM18 -> 0 | J47: =J18+AA18+AR18+BI18+BZ18+CQ18+DH18+DY18+EP18+FG18+FX18+GO18+HF18+HW18+IN18 -> 4 | ... R47: =R18+AI18+AZ18+BQ18+CH18+CY18+DP18+EG18+EX18+FO18+GF18+GW18+HN18+IE18+IV18 -> 11 | T47: =IFERROR(E47/C47,0) -> 0.28571429 | U47: =IFERROR(Q47/C47,0) -> 0.28571429
A48: =IF(A19="","",A19) -> Luis Rivera | B48: =IF(B19="","",B19) -> 12 | C48: =C19+T19+AK19+BB19+BS19+CJ19+DA19+DR19+EI19+EZ19+FQ19+GH19+GY19+HP19+IG19 -> 6 | D48: =D19+U19+AL19+BC19+BT19+CK19+DB19+DS19+EJ19+FA19+FR19+GI19+GZ19+HQ19+IH19 -> 1 | E48: =E19+V19+AM19+BD19+BU19+CL19+DC19+DT19+EK19+FB19+FS19+GJ19+HA19+HR19+II19 -> 3 | F48: =F19+W19+AN19+BE19+BV19+CM19+DD19+DU19+EL19+FC19+FT19+GK19+HB19+HS19+IJ19 -> 0 | G48: =G19+X19+AO19+BF19+BW19+CN19+DE19+DV19+EM19+FD19+FU19+GL19+HC19+HT19+IK19 -> 0 | H48: =H19+Y19+AP19+BG19+BX19+CO19+DF19+DW19+EN19+FE19+FV19+GM19+HD19+HU19+IL19 -> 0 | I48: =I19+Z19+AQ19+BH19+BY19+CP19+DG19+DX19+EO19+FF19+FW19+GN19+HE19+HV19+IM19 -> 0 | J48: =J19+AA19+AR19+BI19+BZ19+CQ19+DH19+DY19+EP19+FG19+FX19+GO19+HF19+HW19+IN19 -> 4 | ... R48: =R19+AI19+AZ19+BQ19+CH19+CY19+DP19+EG19+EX19+FO19+GF19+GW19+HN19+IE19+IV19 -> 13 | T48: =IFERROR(E48/C48,0) -> 0.5 | U48: =IFERROR(Q48/C48,0) -> 0.5
... A61: =IF(A32="","",A32) -> Carlos Lopez | B61: =IF(B32="","",B32) -> 25 | C61: =C32+T32+AK32+BB32+BS32+CJ32+DA32+DR32+EI32+EZ32+FQ32+GH32+GY32+HP32+IG32 -> 5 | D61: =D32+U32+AL32+BC32+BT32+CK32+DB32+DS32+EJ32+FA32+FR32+GI32+GZ32+HQ32+IH32 -> 2 | E61: =E32+V32+AM32+BD32+BU32+CL32+DC32+DT32+EK32+FB32+FS32+GJ32+HA32+HR32+II32 -> 1 | F61: =F32+W32+AN32+BE32+BV32+CM32+DD32+DU32+EL32+FC32+FT32+GK32+HB32+HS32+IJ32 -> 0 | G61: =G32+X32+AO32+BF32+BW32+CN32+DE32+DV32+EM32+FD32+FU32+GL32+HC32+HT32+IK32 -> 0 | H61: =H32+Y32+AP32+BG32+BX32+CO32+DF32+DW32+EN32+FE32+FV32+GM32+HD32+HU32+IL32 -> 0 | I61: =I32+Z32+AQ32+BH32+BY32+CP32+DG32+DX32+EO32+FF32+FW32+GN32+HE32+HV32+IM32 -> 2 | J61: =J32+AA32+AR32+BI32+BZ32+CQ32+DH32+DY32+EP32+FG32+FX32+GO32+HF32+HW32+IN32 -> 2 | ... R61: =R32+AI32+AZ32+BQ32+CH32+CY32+DP32+EG32+EX32+FO32+GF32+GW32+HN32+IE32+IV32 -> 11 | T61: =IFERROR(E61/C61,0) -> 0.2 | U61: =IFERROR(Q61/C61,0) -> 0.2
A62: TOTALES : | C62: =SUM(C37:C61) -> 179 | D62: =SUM(D37:D61) -> 102 | E62: =SUM(E37:E61) -> 88 | F62: =SUM(F37:F61) -> 3 | G62: =SUM(G37:G61) -> 3 | H62: =SUM(H37:H61) -> 1 | I62: =SUM(I37:I61) -> 70 | J62: =SUM(J37:J61) -> 60 | ... R62: =SUM(R37:R61) -> 312 | T62: =IFERROR(E62/C62,0) -> 0.49162011 | U62: =IFERROR(Q62/C62,0) -> 0.55865922
A64: L A N Z A D O R E S
A65: NOMBRE | B65: No | C65: P? | D65: G/P/S | E65: INN | F65: CL | G65: K | H65: H | I65: P? | J65: G/P/S | K65: INN | L65: CL | M65: K | N65: H | O65: P? | P65: G/P/S | Q65: INN | R65: CL | S65: K | T65: H | U65: P? | V65: G/P/S | W65: INN | X65: CL | Y65: K | Z65: H | AA65: P? | AB65: G/P/S | AC65: INN | AD65: CL | AE65: K | AF65: H | AG65: P? | AH65: G/P/S | AI65: INN | AJ65: CL | AK65: K | AL65: H | AM65: P? | AN65: G/P/S | AO65: INN | AP65: CL | AQ65: K | AR65: H | AS65: P? | AT65: G/P/S | AU65: INN | AV65: CL | AW65: K | AX65: H | AY65: P? | AZ65: G/P/S | BA65: INN | BB65: CL | BC65: K | BD65: H | BE65: P? | BF65: G/P/S | BG65: INN | BH65: CL | BI65: K | BJ65: H | BK65: P? | BL65: G/P/S | BM65: INN | BN65: CL | BO65: K | BP65: H | BQ65: P? | BR65: G/P/S | BS65: INN | BT65: CL | BU65: K | BV65: H | BW65: P? | BX65: G/P/S | BY65: INN | BZ65: CL | CA65: K | CB65: H | CC65: P? | CD65: G/P/S | CE65: INN | CF65: CL | CG65: K | CH65: H | CI65: P? | CJ65: G/P/S | CK65: INN | CL65: CL | CM65: K | CN65: H | CP65: JJ | CQ65: JG | CR65: JP | CS65: OUTS | CT65: INN | CU65: CL | CV65: K | CW65: H | CX65: PCL | CY65: SV
A66: =IF(A8="","",A8) -> Luis Garcia | B66: =IF(B8="","",B8) -> 1 | C66: 0 | I66: 1 | J66: P | K66: 1 | L66: 4 | M66: 6 | N66: 0 | CP66: =C66+I66+O66+U66+AA66+AG66+AM66+AS66+AY66+BE66+BK66+BQ66+BW66+CC66+CI66 -> 1 | CQ66: =COUNTIF(D66,"G")+COUNTIF(J66,"G")+COUNTIF(P66,"G")+COUNTIF(V66,"G")+COUNTIF(AB66,"G")+COUNTIF(AH66,"G")+COUNTIF(AN66,"G")+COUNTIF(AT66,"G")+COUNTIF(AZ66,"G")+COUNTIF(BF66,"G")+COUNTIF(BL66,"G")+COUNTIF(BR66,"G")+COUNTIF(BX66,"G")+COUNTIF(CD66,"G")+COUNTIF(CJ66,"G") -> 0 | CR66: =COUNTIF(D66,"P")+COUNTIF(J66,"P")+COUNTIF(P66,"P")+COUNTIF(V66,"P")+COUNTIF(AB66,"P")+COUNTIF(AH66,"P")+COUNTIF(AN66,"P")+COUNTIF(AT66,"P")+COUNTIF(AZ66,"P")+COUNTIF(BF66,"P")+COUNTIF(BL66,"P")+COUNTIF(BR66,"P")+COUNTIF(BX66,"P")+COUNTIF(CD66,"P")+COUNTIF(CJ66,"P") -> 1 | CS66: =(INT(E66)*3+(E66-INT(E66))*10)+(INT(K66)*3+(K66-INT(K66))*10)+(INT(Q66)*3+(Q66-INT(Q66))*10)+(INT(W66)*3+(W66-INT(W66))*10)+(INT(AC66)*3+(AC66-INT(AC66))*10)+(INT(AI66)*3+(AI66-INT(AI66))*10)+(INT(AO66)*3+(AO66-INT(AO66))*10)+(INT(AU66)*3+(AU66-INT(AU66))*10)+(INT(BA66)*3+(BA66-INT(BA66))*10)+(INT(BG66)*3+(BG66-INT(BG66))*10)+(INT(BM66)*3+(BM66-INT(BM66))*10)+(INT(BS66)*3+(BS66-INT(BS66))*10)+(INT(BY66)*3+(BY66-INT(BY66))*10)+(INT(CE66)*3+(CE66-INT(CE66))*10)+(INT(CK66)*3+(CK66-INT(CK66))*10) -> 3 | CT66: =INT(CS66/3)+MOD(CS66,3)/10 -> 1 | CU66: =F66+L66+R66+X66+AD66+AJ66+AP66+AV66+BB66+BH66+BN66+BT66+BZ66+CF66+CL66 -> 4 | CV66: =G66+M66+S66+Y66+AE66+AK66+AQ66+AW66+BC66+BI66+BO66+BU66+CA66+CG66+CM66 -> 6 | CW66: =H66+N66+T66+Z66+AF66+AL66+AR66+AX66+BD66+BJ66+BP66+BV66+CB66+CH66+CN66 -> 0 | CX66: =IFERROR(CU66*27/CS66,0) -> 36 | CY66: =COUNTIF(D66,"S")+COUNTIF(J66,"S")+COUNTIF(P66,"S")+COUNTIF(V66,"S")+COUNTIF(AB66,"S")+COUNTIF(AH66,"S")+COUNTIF(AN66,"S")+COUNTIF(AT66,"S")+COUNTIF(AZ66,"S")+COUNTIF(BF66,"S")+COUNTIF(BL66,"S")+COUNTIF(BR66,"S")+COUNTIF(BX66,"S")+COUNTIF(CD66,"S")+COUNTIF(CJ66,"S") -> 0
A67: =IF(A9="","",A9) -> Luis Rodriguez | B67: =IF(B9="","",B9) -> 2 | C67: 1 | D67: P | E67: 3 | F67: 0 | G67: 5 | H67: 1 | I67: 0 | CP67: =C67+I67+O67+U67+AA67+AG67+AM67+AS67+AY67+BE67+BK67+BQ67+BW67+CC67+CI67 -> 1 | CQ67: =COUNTIF(D67,"G")+COUNTIF(J67,"G")+COUNTIF(P67,"G")+COUNTIF(V67,"G")+COUNTIF(AB67,"G")+COUNTIF(AH67,"G")+COUNTIF(AN67,"G")+COUNTIF(AT67,"G")+COUNTIF(AZ67,"G")+COUNTIF(BF67,"G")+COUNTIF(BL67,"G")+COUNTIF(BR67,"G")+COUNTIF(BX67,"G")+COUNTIF(CD67,"G")+COUNTIF(CJ67,"G") -> 0 | CR67: =COUNTIF(D67,"P")+COUNTIF(J67,"P")+COUNTIF(P67,"P")+COUNTIF(V67,"P")+COUNTIF(AB67,"P")+COUNTIF(AH67,"P")+COUNTIF(AN67,"P")+COUNTIF(AT67,"P")+COUNTIF(AZ67,"P")+COUNTIF(BF67,"P")+COUNTIF(BL67,"P")+COUNTIF(BR67,"P")+COUNTIF(BX67,"P")+COUNTIF(CD67,"P")+COUNTIF(CJ67,"P") -> 1 | CS67: =(INT(E67)*3+(E67-INT(E67))*10)+(INT(K67)*3+(K67-INT(K67))*10)+(INT(Q67)*3+(Q67-INT(Q67))*10)+(INT(W67)*3+(W67-INT(W67))*10)+(INT(AC67)*3+(AC67-INT(AC67))*10)+(INT(AI67)*3+(AI67-INT(AI67))*10)+(INT(AO67)*3+(AO67-INT(AO67))*10)+(INT(AU67)*3+(AU67-INT(AU67))*10)+(INT(BA67)*3+(BA67-INT(BA67))*10)+(INT(BG67)*3+(BG67-INT(BG67))*10)+(INT(BM67)*3+(BM67-INT(BM67))*10)+(INT(BS67)*3+(BS67-INT(BS67))*10)+(INT(BY67)*3+(BY67-INT(BY67))*10)+(INT(CE67)*3+(CE67-INT(CE67))*10)+(INT(CK67)*3+(CK67-INT(CK67))*10) -> 9 | CT67: =INT(CS67/3)+MOD(CS67,3)/10 -> 3 | CU67: =F67+L67+R67+X67+AD67+AJ67+AP67+AV67+BB67+BH67+BN67+BT67+BZ67+CF67+CL67 -> 0 | CV67: =G67+M67+S67+Y67+AE67+AK67+AQ67+AW67+BC67+BI67+BO67+BU67+CA67+CG67+CM67 -> 5 | CW67: =H67+N67+T67+Z67+AF67+AL67+AR67+AX67+BD67+BJ67+BP67+BV67+CB67+CH67+CN67 -> 1 | CX67: =IFERROR(CU67*27/CS67,0) -> 0 | CY67: =COUNTIF(D67,"S")+COUNTIF(J67,"S")+COUNTIF(P67,"S")+COUNTIF(V67,"S")+COUNTIF(AB67,"S")+COUNTIF(AH67,"S")+COUNTIF(AN67,"S")+COUNTIF(AT67,"S")+COUNTIF(AZ67,"S")+COUNTIF(BF67,"S")+COUNTIF(BL67,"S")+COUNTIF(BR67,"S")+COUNTIF(BX67,"S")+COUNTIF(CD67,"S")+COUNTIF(CJ67,"S") -> 0
A68: =IF(A10="","",A10) -> Luis Martinez | B68: =IF(B10="","",B10) -> 3 | C68: 0 | I68: 1 | J68: G | K68: 2.1 | L68: 0 | M68: 4 | N68: 3 | CP68: =C68+I68+O68+U68+AA68+AG68+AM68+AS68+AY68+BE68+BK68+BQ68+BW68+CC68+CI68 -> 1 | CQ68: =COUNTIF(D68,"G")+COUNTIF(J68,"G")+COUNTIF(P68,"G")+COUNTIF(V68,"G")+COUNTIF(AB68,"G")+COUNTIF(AH68,"G")+COUNTIF(AN68,"G")+COUNTIF(AT68,"G")+COUNTIF(AZ68,"G")+COUNTIF(BF68,"G")+COUNTIF(BL68,"G")+COUNTIF(BR68,"G")+COUNTIF(BX68,"G")+COUNTIF(CD68,"G")+COUNTIF(CJ68,"G") -> 1 | CR68: =COUNTIF(D68,"P")+COUNTIF(J68,"P")+COUNTIF(P68,"P")+COUNTIF(V68,"P")+COUNTIF(AB68,"P")+COUNTIF(AH68,"P")+COUNTIF(AN68,"P")+COUNTIF(AT68,"P")+COUNTIF(AZ68,"P")+COUNTIF(BF68,"P")+COUNTIF(BL68,"P")+COUNTIF(BR68,"P")+COUNTIF(BX68,"P")+COUNTIF(CD68,"P")+COUNTIF(CJ68,"P") -> 0 | CS68: =(INT(E68)*3+(E68-INT(E68))*10)+(INT(K68)*3+(K68-INT(K68))*10)+(INT(Q68)*3+(Q68-INT(Q68))*10)+(INT(W68)*3+(W68-INT(W68))*10)+(INT(AC68)*3+(AC68-INT(AC68))*10)+(INT(AI68)*3+(AI68-INT(AI68))*10)+(INT(AO68)*3+(AO68-INT(AO68))*10)+(INT(AU68)*3+(AU68-INT(AU68))*10)+(INT(BA68)*3+(BA68-INT(BA68))*10)+(INT(BG68)*3+(BG68-INT(BG68))*10)+(INT(BM68)*3+(BM68-INT(BM68))*10)+(INT(BS68)*3+(BS68-INT(BS68))*10)+(INT(BY68)*3+(BY68-INT(BY68))*10)+(INT(CE68)*3+(CE68-INT(CE68))*10)+(INT(CK68)*3+(CK68-INT(CK68))*10) -> 7 | CT68: =INT(CS68/3)+MOD(CS68,3)/10 -> 2.1 | CU68: =F68+L68+R68+X68+AD68+AJ68+AP68+AV68+BB68+BH68+BN68+BT68+BZ68+CF68+CL68 -> 0 | CV68: =G68+M68+S68+Y68+AE68+AK68+AQ68+AW68+BC68+BI68+BO68+BU68+CA68+CG68+CM68 -> 4 | CW68: =H68+N68+T68+Z68+AF68+AL68+AR68+AX68+BD68+BJ68+BP68+BV68+CB68+CH68+CN68 -> 3 | CX68: =IFERROR(CU68*27/CS68,0) -> 0 | CY68: =COUNTIF(D68,"S")+COUNTIF(J68,"S")+COUNTIF(P68,"S")+COUNTIF(V68,"S")+COUNTIF(AB68,"S")+COUNTIF(AH68,"S")+COUNTIF(AN68,"S")+COUNTIF(AT68,"S")+COUNTIF(AZ68,"S")+COUNTIF(BF68,"S")+COUNTIF(BL68,"S")+COUNTIF(BR68,"S")+COUNTIF(BX68,"S")+COUNTIF(CD68,"S")+COUNTIF(CJ68,"S") -> 0
...

Sheet equipo2
A1: CORPORACION CRIOLLITOS DE VENEZUELA
A2: LIGA DE BEISBOL MENOR JUAN GUILLERMO GUZMAN
B4: CATEGORIA : INFANTIL
A6: Equipo 2 | C6: O F E N S I V A I N D I V I D U A L
A7: NOMBRE | B7: No | C7: VB | D7: CA | E7: H | F7: 2B | G7: 3B | H7: HR | I7: CI | J7: K | K7: BB | L7: BR | M7: GP | N7: SH | O7: SF | P7: INT | Q7: BAL | R7: AL | T7: VB | U7: CA | V7: H | W7: 2B | X7: 3B | Y7: HR | Z7: CI | AA7: K | AB7: BB | AC7: BR | AD7: GP | AE7: SH | AF7: SF | AG7: INT | AH7: BAL | AI7: AL | AK7: VB | AL7: CA | AM7: H | AN7: 2B | AO7: 3B | AP7: HR | AQ7: CI | AR7: K | AS7: BB | AT7: BR | AU7: GP | AV7: SH | AW7: SF | AX7: INT | AY7: BAL | AZ7: AL | BB7: VB | BC7: CA | BD7: H | BE7: 2B | BF7: 3B | BG7: HR | BH7: CI | BI7: K | BJ7: BB | BK7: BR | BL7: GP | BM7: SH | BN7: SF | BO7: INT | BP7: BAL | BQ7: AL | BS7: VB | BT7: CA | BU7: H | BV7: 2B | BW7: 3B | BX7: HR | BY7: CI | BZ7: K | CA7: BB | CB7: BR | CC7: GP | CD7: SH | CE7: SF | CF7: INT | CG7: BAL | CH7: AL | CJ7: VB | CK7: CA | CL7: H | CM7: 2B | CN7: 3B | CO7: HR | CP7: CI | CQ7: K | CR7: BB | CS7: BR | CT7: GP | CU7: SH | CV7: SF | CW7: INT | CX7: BAL | CY7: AL | DA7: VB | DB7: CA | DC7: H | DD7: 2B | DE7: 3B | DF7: HR | DG7: CI | DH7: K | DI7: BB | DJ7: BR | DK7: GP | DL7: SH | DM7: SF | DN7: INT | DO7: BAL | DP7: AL | DR7: VB | DS7: CA | DT7: H | DU7: 2B | DV7: 3B | DW7: HR | DX7: CI | DY7: K | DZ7: BB | EA7: BR | EB7: GP | EC7: SH | ED7: SF | EE7: INT | EF7: BAL | EG7: AL | EI7: VB | EJ7: CA | EK7: H | EL7: 2B | EM7: 3B | EN7: HR | EO7: CI | EP7: K | EQ7: BB | ER7: BR | ES7: GP | ET7: SH | EU7: SF | EV7: INT | EW7: BAL | EX7: AL | EZ7: VB | FA7: CA | FB7: H | FC7: 2B | FD7: 3B | FE7: HR | FF7: CI | FG7: K | FH7: BB | FI7: BR | FJ7: GP | FK7: SH | FL7: SF | FM7: INT | FN7: BAL | FO7: AL | FQ7: VB | FR7: CA | FS7: H | FT7: 2B | FU7: 3B | FV7: HR | FW7: CI | FX7: K | FY7: BB | FZ7: BR | GA7: GP | GB7: SH | GC7: SF | GD7: INT | GE7: BAL | GF7: AL | GH7: VB | GI7: CA | GJ7: H | GK7: 2B | GL7: 3B | GM7: HR | GN7: CI | GO7: K | GP7: BB | GQ7: BR | GR7: GP | GS7: SH | GT7: SF | GU7: INT | GV7: BAL | GW7: AL | GY7: VB | GZ7: CA | HA7: H | HB7: 2B | HC7: 3B | HD7: HR | HE7: CI | HF7: K | HG7: BB | HH7: BR | HI7: GP | HJ7: SH | HK7: SF | HL7: INT | HM7: BAL | HN7: AL | HP7: VB | HQ7: CA | HR7: H | HS7: 2B | HT7: 3B | HU7: HR | HV7: CI | HW7: K | HX7: BB | HY7: BR | HZ7: GP | IA7: SH | IB7: SF | IC7: INT | ID7: BAL | IE7: AL | IG7: VB | IH7: CA | II7: H | IJ7: 2B | IK7: 3B | IL7: HR | IM7: CI | IN7: K | IO7: BB | IP7: BR | IQ7: GP | IR7: SH | IS7: SF | IT7: INT | IU7: BAL | IV7: AL
A8: Carlos Gonzalez | B8: 1 | C8: 4 | D8: 0 | E8: 1 | F8: 0 | G8: 0 | H8: 0 | I8: 0 | J8: 2 | K8: 1 | L8: 1 | M8: 0 | N8: 0 | O8: 1 | P8: 0 | Q8: =(E8-(F8+G8+H8))+(F8*2)+(G8*3)+(H8*4) -> 1 | R8: =C8+K8+M8+N8+O8+P8 -> 6 | T8: 3 | U8: 1 | V8: 3 | W8: 0 | X8: 0 | Y8: 0 | Z8: 1 | AA8: 1 | AB8: 1 | AC8: 1 | AD8: 0 | AE8: 1 | AF8: 1 | AG8: 0 | AH8: =(V8-(W8+X8+Y8))+(W8*2)+(X8*3)+(Y8*4) -> 3 | AI8: =T8+AB8+AD8+AE8+AF8+AG8 -> 6
A9: Carlos Perez | B9: 2 | C9: 3 | D9: 0 | E9: 1 | F9: 0 | G9: 0 | H9: 0 | I9: 0 | J9: 0 | K9: 0 | L9: 1 | M9: 1 | N9: 1 | O9: 1 | P9: 0 | Q9: =(E9-(F9+G9+H9))+(F9*2)+(G9*3)+(H9*4) -> 1 | R9: =C9+K9+M9+N9+O9+P9 -> 6 | T9: 4 | U9: 2 | V9: 2 | W9: 0 | X9: 0 | Y9: 1 | Z9: 3 | AA9: 2 | AB9: 1 | AC9: 1 | AD9: 1 | AE9: 1 | AF9: 0 | AG9: 0 | AH9: =(V9-(W9+X9+Y9))+(W9*2)+(X9*3)+(Y9*4) -> 5 | AI9: =T9+AB9+AD9+AE9+AF9+AG9 -> 7
A10: Carlos Sanchez | B10: 3 | C10: 5 | D10: 3 | E10: 0 | F10: 0 | G10: 0 | H10: 0 | I10: 0 | J10: 2 | K10: 1 | L10: 0 | M10: 1 | N10: 1 | O10: 1 | P10: 0 | Q10: =(E10-(F10+G10+H10))+(F10*2)+(G10*3)+(H10*4) -> 0 | R10: =C10+K10+M10+N10+O10+P10 -> 9 | T10: 2 | U10: 2 | V10: 1 | W10: 1 | X10: 0 | Y10: 0 | Z10: 2 | AA10: 2 | AB10: 2 | AC10: 0 | AD10: 0 | AE10: 1 | AF10: 1 | AG10: 0 | AH10: =(V10-(W10+X10+Y10))+(W10*2)+(X10*3)+(Y10*4) -> 2 | AI10: =T10+AB10+AD10+AE10+AF10+AG10 -> 6
A11: Carlos Ramirez | B11: 4 | C11: 3 | D11: 1 | E11: 0 | F11: 0 | G11: 0 | H11: 0 | I11: 1 | J11: 1 | K11: 2 | L11: 0 | M11: 0 | N11: 1 | O11: 1 | P11: 0 | Q11: =(E11-(F11+G11+H11))+(F11*2)+(G11*3)+(H11*4) -> 0 | R11: =C11+K11+M11+N11+O11+P11 -> 7 | T11: 4 | U11: 3 | V11: 3 | W11: 0 | X11: 0 | Y11: 1 | Z11: 4 | AA11: 1 | AB11: 2 | AC11: 0 | AD11: 0 | AE11: 0 | AF11: 1 | AG11: 0 | AH11: =(V11-(W11+X11+Y11))+(W11*2)+(X11*3)+(Y11*4) -> 6 | AI11: =T11+AB11+AD11+AE11+AF11+AG11 -> 7
A12: Carlos Torres | B12: 5 | C12: 5 | D12: 1 | E12: 3 | F12: 0 | G12: 0 | H12: 0 | I12: 4 | J12: 0 | K12: 0 | L12: 0 | M12: 1 | N12: 0 | O12: 0 | P12: 0 | Q12: =(E12-(F12+G12+H12))+(F12*2)+(G12*3)+(H12*4) -> 3 | R12: =C12+K12+M12+N12+O12+P12 -> 6 | T12: 5 | U12: 5 | V12: 3 | W12: 0 | X12: 1 | Y12: 0 | Z12: 0 | AA12: 1 | AB12: 0 | AC12: 0 | AD12: 0 | AE12: 0 | AF12: 1 | AG12: 0 | AH12: =(V12-(W12+X12+Y12))+(W12*2)+(X12*3)+(Y12*4) -> 5 | AI12: =T12+AB12+AD12+AE12+AF12+AG12 -> 6
A13: Carlos Flores | B13: 6 | C13: 4 | D13: 1 | E13: 0 | F13: 0 | G13: 0 | H13: 0 | I13: 1 | J13: 2 | K13: 2 | L13: 1 | M13: 1 | N13: 1 | O13: 1 | P13: 0 | Q13: =(E13-(F13+G13+H13))+(F13*2)+(G13*3)+(H13*4) -> 0 | R13: =C13+K13+M13+N13+O13+P13 -> 9 | T13: 5 | U13: 3 | V13: 0 | W13: 0 | X13: 0 | Y13: 0 | Z13: 1 | AA13: 0 | AB13: 0 | AC13: 0 | AD13: 0 | AE13: 1 | AF13: 1 | AG13: 0 | AH13: =(V13-(W13+X13+Y13))+(W13*2)+(X13*3)+(Y13*4) -> 0 | AI13: =T13+AB13+AD13+AE13+AF13+AG13 -> 7
A14: Carlos Rivera | B14: 7 | C14: 5 | D14: 4 | E14: 4 | F14: 0 | G14: 0 | H14: 1 | I14: 4 | J14: 0 | K14: 1 | L14: 1 | M14: 1 | N14: 0 | O14: 0 | P14: 0 | Q14: =(E14-(F14+G14+H14))+(F14*2)+(G14*3)+(H14*4) -> 7 | R14: =C14+K14+M14+N14+O14+P14 -> 7 | T14: 3 | U14: 2 | V14: 0 | W14: 0 | X14: 0 | Y14: 0 | Z14: 1 | AA14: 0 | AB14: 1 | AC14: 0 | AD14: 0 | AE14: 1 | AF14: 1 | AG14: 0 | AH14: =(V14-(W14+X14+Y14))+(W14*2)+(X14*3)+(Y14*4) -> 0 | AI14: =T14+AB14+AD14+AE14+AF14+AG14 -> 6
A15: Carlos Gomez | B15: 8 | C15: 5 | D15: 0 | E15: 4 | F15: 0 | G15: 0 | H15: 0 | I15: 4 | J15: 0 | K15: 0 | L15: 1 | M15: 1 | N15: 0 | O15: 1 | P15: 0 | Q15: =(E15-(F15+G15+H15))+(F15*2)+(G15*3)+(H15*4) -> 4 | R15: =C15+K15+M15+N15+O15+P15 -> 7 | T15: 2 | U15: 1 | V15: 1 | W15: 0 | X15: 0 | Y15: 0 | Z15: 1 | AA15: 0 | AB15: 1 | AC15: 0 | AD15: 0 | AE15: 1 | AF15: 0 | AG15: 0 | AH15: =(V15-(W15+X15+Y15))+(W15*2)+(X15*3)+(Y15*4) -> 1 | AI15: =T15+AB15+AD15+AE15+AF15+AG15 -> 4
A16: Carlos Diaz | B16: 9 | C16: 3 | D16: 3 | E16: 0 | F16: 0 | G16: 0 | H16: 0 | I16: 0 | J16: 2 | K16: 0 | L16: 0 | M16: 0 | N16: 0 | O16: 0 | P16: 0 | Q16: =(E16-(F16+G16+H16))+(F16*2)+(G16*3)+(H16*4) -> 0 | R16: =C16+K16+M16+N16+O16+P16 -> 3 | T16: 2 | U16: 2 | V16: 1 | W16: 0 | X16: 0 | Y16: 1 | Z16: 1 | AA16: 1 | AB16: 1 | AC16: 1 | AD16: 0 | AE16: 0 | AF16: 0 | AG16: 0 | AH16: =(V16-(W16+X16+Y16))+(W16*2)+(X16*3)+(Y16*4) -> 4 | AI16: =T16+AB16+AD16+AE16+AF16+AG16 -> 3
A17: Carlos Reyes | B17: 10 | C17: 5 | D17: 2 | E17: 3 | F17: 0 | G17: 0 | H17: 0 | I17: 4 | J17: 1 | K17: 2 | L17: 1 | M17: 1 | N17: 0 | O17: 1 | P17: 0 | Q17: =(E17-(F17+G17+H17))+(F17*2)+(G17*3)+(H17*4) -> 3 | R17: =C17+K17+M17+N17+O17+P17 -> 9 | T17: 2 | U17: 1 | V17: 1 | W17: 0 | X17: 0 | Y17: 0 | Z17: 1 | AA17: 0 | AB17: 0 | AC17: 0 | AD17: 1 | AE17: 1 | AF17: 1 | AG17: 0 | AH17: =(V17-(W17+X17+Y17))+(W17*2)+(X17*3)+(Y17*4) -> 1 | AI17: =T17+AB17+AD17+AE17+AF17+AG17 -> 5
A18: Carlos Morales | B18: 11 | C18: 2 | D18: 2 | E18: 1 | F18: 0 | G18: 0 | H18: 0 | I18: 2 | J18: 0 | K18: 0 | L18: 1 | M18: 0 | N18: 1 | O18: 1 | P18: 0 | Q18: =(E18-(F18+G18+H18))+(F18*2)+(G18*3)+(H18*4) -> 1 | R18: =C18+K18+M18+N18+O18+P18 -> 4 | T18: 3 | U18: 3 | V18: 3 | W18: 0 | X18: 0 | Y18: 0 | Z18: 0 | AA18: 1 | AB18: 0 | AC18: 1 | AD18: 0 | AE18: 1 | AF18: 0 | AG18: 0 | AH18: =(V18-(W18+X18+Y18))+(W18*2)+(X18*3)+(Y18*4) -> 3 | AI18: =T18+AB18+AD18+AE18+AF18+AG18 -> 4
A19: Carlos Cruz | B19: 12 | C19: 4 | D19: 1 | E19: 1 | F19: 1 | G19: 0 | H19: 0 | I19: 2 | J19: 2 | K19: 0 | L19: 0 | M19: 1 | N19: 1 | O19: 1 | P19: 0 | Q19: =(E19-(F19+G19+H19))+(F19*2)+(G19*3)+(H19*4) -> 2 | R19: =C19+K19+M19+N19+O19+P19 -> 7 | T19: 4 | U19: 2 | V19: 0 | W19: 0 | X19: 0 | Y19: 0 | Z19: 1 | AA19: 0 | AB19: 0 | AC19: 0 | AD19: 0 | AE19: 0 | AF19: 0 | AG19: 0 | AH19: =(V19-(W19+X19+Y19))+(W19*2)+(X19*3)+(Y19*4) -> 0 | AI19: =T19+AB19+AD19+AE19+AF19+AG19 -> 4
... A32: Jose Torres | B32: 25 | C32: 3 | D32: 2 | E32: 0 | F32: 0 | G32: 0 | H32: 0 | I32: 0 | J32: 2 | K32: 2 | L32: 0 | M32: 0 | N32: 1 | O32: 1 | P32: 0 | Q32: =(E32-(F32+G32+H32))+(F32*2)+(G32*3)+(H32*4) -> 0 | R32: =C32+K32+M32+N32+O32+P32 -> 7 | T32: 3 | U32: 0 | V32: 3 | W32: 0 | X32: 0 | Y32: 1 | Z32: 0 | AA32: 1 | AB32: 2 | AC32: 1 | AD32: 1 | AE32: 1 | AF32: 0 | AG32: 0 | AH32: =(V32-(W32+X32+Y32))+(W32*2)+(X32*3)+(Y32*4) -> 6 | AI32: =T32+AB32+AD32+AE32+AF32+AG32 -> 7
A33: TOTALES : | C33: =SUM(C8:C32) -> 102 | D33: =SUM(D8:D32) -> 53 | E33: =SUM(E8:E32) -> 41 | F33: =SUM(F8:F32) -> 5 | G33: =SUM(G8:G32) -> 0 | H33: =SUM(H8:H32) -> 1 | I33: =SUM(I8:I32) -> 39 | J33: =SUM(J8:J32) -> 26 | ... R33: =SUM(R8:R32) -> 175 | T33: =SUM(T8:T32) -> 82 | U33: =SUM(U8:U32) -> 43 | V33: =SUM(V8:V32) -> 44 | W33: =SUM(W8:W32) -> 2 | X33: =SUM(X8:X32) -> 2 | Y33: =SUM(Y8:Y32) -> 6 | Z33: =SUM(Z8:Z32) -> 34 | AA33: =SUM(AA8:AA32) -> 26 | ... AI33: =SUM(AI8:AI32) -> 143 | AK33: =SUM(AK8:AK32) -> 0 | AL33: =SUM(AL8:AL32) -> 0 | AM33: =SUM(AM8:AM32) -> 0 | AN33: =SUM(AN8:AN32) -> 0 | AO33: =SUM(AO8:AO32) -> 0 | AP33: =SUM(AP8:AP32) -> 0 | AQ33: =SUM(AQ8:AQ32) -> 0 | AR33: =SUM(AR8:AR32) -> 0 | ... AZ33: =SUM(AZ8:AZ32) -> 0 | BB33: =SUM(BB8:BB32) -> 0 | BC33: =SUM(BC8:BC32) -> 0 | BD33: =SUM(BD8:BD32) -> 0 | BE33: =SUM(BE8:BE32) -> 0 | BF33: =SUM(BF8:BF32) -> 0 | BG33: =SUM(BG8:BG32) -> 0 | BH33: =SUM(BH8:BH32) -> 0 | BI33: =SUM(BI8:BI32) -> 0 | ... BQ33: =SUM(BQ8:BQ32) -> 0 | BS33: =SUM(BS8:BS32) -> 0 | BT33: =SUM(BT8:BT32) -> 0 | BU33: =SUM(BU8:BU32) -> 0 | BV33: =SUM(BV8:BV32) -> 0 | BW33: =SUM(BW8:BW32) -> 0 | BX33: =SUM(BX8:BX32) -> 0 | BY33: =SUM(BY8:BY32) -> 0 | BZ33: =SUM(BZ8:BZ32) -> 0 | ... CH33: =SUM(CH8:CH32) -> 0 | CJ33: =SUM(CJ8:CJ32) -> 0 | CK33: =SUM(CK8:CK32) -> 0 | CL33: =SUM(CL8:CL32) -> 0 | CM33: =SUM(CM8:CM32) -> 0 | CN33: =SUM(CN8:CN32) -> 0 | CO33: =SUM(CO8:CO32) -> 0 | CP33: =SUM(CP8:CP32) -> 0 | CQ33: =SUM(CQ8:CQ32) -> 0 | ... CY33: =SUM(CY8:CY32) -> 0 | DA33: =SUM(DA8:DA32) -> 0 | DB33: =SUM(DB8:DB32) -> 0 | DC33: =SUM(DC8:DC32) -> 0 | DD33: =SUM(DD8:DD32) -> 0 | DE33: =SUM(DE8:DE32) -> 0 | DF33: =SUM(DF8:DF32) -> 0 | DG33: =SUM(DG8:DG32) -> 0 | DH33: =SUM(DH8:DH32) -> 0 | ... DP33: =SUM(DP8:DP32) -> 0 | DR33: =SUM(DR8:DR32) -> 0 | DS33: =SUM(DS8:DS32) -> 0 | DT33: =SUM(DT8:DT32) -> 0 | DU33: =SUM(DU8:DU32) -> 0 | DV33: =SUM(DV8:DV32) -> 0 | DW33: =SUM(DW8:DW32) -> 0 | DX33: =SUM(DX8:DX32) -> 0 | DY33: =SUM(DY8:DY32) -> 0 | ... EG33: =SUM(EG8:EG32) -> 0 | EI33: =SUM(EI8:EI32) -> 0 | EJ33: =SUM(EJ8:EJ32) -> 0 | EK33: =SUM(EK8:EK32) -> 0 | EL33: =SUM(EL8:EL32) -> 0 | EM33: =SUM(EM8:EM32) -> 0 | EN33: =SUM(EN8:EN32) -> 0 | EO33: =SUM(EO8:EO32) -> 0 | EP33: =SUM(EP8:EP32) -> 0 | ... EX33: =SUM(EX8:EX32) -> 0 | EZ33: =SUM(EZ8:EZ32) -> 0 | FA33: =SUM(FA8:FA32) -> 0 | FB33: =SUM(FB8:FB32) -> 0 | FC33: =SUM(FC8:FC32) -> 0 | FD33: =SUM(FD8:FD32) -> 0 | FE33: =SUM(FE8:FE32) -> 0 | FF33: =SUM(FF8:FF32) -> 0 | FG33: =SUM(FG8:FG32) -> 0 | ... FO33: =SUM(FO8:FO32) -> 0 | FQ33: =SUM(FQ8:FQ32) -> 0 | FR33: =SUM(FR8:FR32) -> 0 | FS33: =SUM(FS8:FS32) -> 0 | FT33: =SUM(FT8:FT32) -> 0 | FU33: =SUM(FU8:FU32) -> 0 | FV33: =SUM(FV8:FV32) -> 0 | FW33: =SUM(FW8:FW32) -> 0 | FX33: =SUM(FX8:FX32) -> 0 | ... GF33: =SUM(GF8:GF32) -> 0 | GH33: =SUM(GH8:GH32) -> 0 | GI33: =SUM(GI8:GI32) -> 0 | GJ33: =SUM(GJ8:GJ32) -> 0 | GK33: =SUM(GK8:GK32) -> 0 | GL33: =SUM(GL8:GL32) -> 0 | GM33: =SUM(GM8:GM32) -> 0 | GN33: =SUM(GN8:GN32) -> 0 | GO33: =SUM(GO8:GO32) -> 0 | ... GW33: =SUM(GW8:GW32) -> 0 | GY33: =SUM(GY8:GY32) -> 0 | GZ33: =SUM(GZ8:GZ32) -> 0 | HA33: =SUM(HA8:HA32) -> 0 | HB33: =SUM(HB8:HB32) -> 0 | HC33: =SUM(HC8:HC32) -> 0 | HD33: =SUM(HD8:HD32) -> 0 | HE33: =SUM(HE8:HE32) -> 0 | HF33: =SUM(HF8:HF32) -> 0 | ... HN33: =SUM(HN8:HN32) -> 0 | HP33: =SUM(HP8:HP32) -> 0 | HQ33: =SUM(HQ8:HQ32) -> 0 | HR33: =SUM(HR8:HR32) -> 0 | HS33: =SUM(HS8:HS32) -> 0 | HT33: =SUM(HT8:HT32) -> 0 | HU33: =SUM(HU8:HU32) -> 0 | HV33: =SUM(HV8:HV32) -> 0 | HW33: =SUM(HW8:HW32) -> 0 | ... IE33: =SUM(IE8:IE32) -> 0 | IG33: =SUM(IG8:IG32) -> 0 | IH33: =SUM(IH8:IH32) -> 0 | II33: =SUM(II8:II32) -> 0 | IJ33: =SUM(IJ8:IJ32) -> 0 | IK33: =SUM(IK8:IK32) -> 0 | IL33: =SUM(IL8:IL32) -> 0 | IM33: =SUM(IM8:IM32) -> 0 | IN33: =SUM(IN8:IN32) -> 0 | ... IV33: =SUM(IV8:IV32) -> 0
A35: LIDERES INDIVIDUAL
A36: NOMBRE | B36: No | C36: VB | D36: CA | E36: H | F36: 2B | G36: 3B | H36: HR | I36: CI | J36: K | K36: BB | L36: BR | M36: GP | N36: SH | O36: SF | P36: INT | Q36: BAL | R36: AL | T36: AV | U36: SLG
A37: =IF(A8="","",A8) -> Carlos Gonzalez | B37: =IF(B8="","",B8) -> 1 | C37: =C8+T8+AK8+BB8+BS8+CJ8+DA8+DR8+EI8+EZ8+FQ8+GH8+GY8+HP8+IG8 -> 7 | D37: =D8+U8+AL8+BC8+BT8+CK8+DB8+DS8+EJ8+FA8+FR8+GI8+GZ8+HQ8+IH8 -> 1 | E37: =E8+V8+AM8+BD8+BU8+CL8+DC8+DT8+EK8+FB8+FS8+GJ8+HA8+HR8+II8 -> 4 | F37: =F8+W8+AN8+BE8+BV8+CM8+DD8+DU8+EL8+FC8+FT8+GK8+HB8+HS8+IJ8 -> 0 | G37: =G8+X8+AO8+BF8+BW8+CN8+DE8+DV8+EM8+FD8+FU8+GL8+HC8+HT8+IK8 -> 0 | H37: =H8+Y8+AP8+BG8+BX8+CO8+DF8+DW8+EN8+FE8+FV8+GM8+HD8+HU8+IL8 -> 0 | I37: =I8+Z8+AQ8+BH8+BY8+CP8+DG8+DX8+EO8+FF8+FW8+GN8+HE8+HV8+IM8 -> 1 | J37: =J8+AA8+AR8+BI8+BZ8+CQ8+DH8+DY8+EP8+FG8+FX8+GO8+HF8+HW8+IN8 -> 3 | ... R37: =R8+AI8+AZ8+BQ8+CH8+CY8+DP8+EG8+EX8+FO8+GF8+GW8+HN8+IE8+IV8 -> 12 | T37: =IFERROR(E37/C37,0) -> 0.57142857 | U37: =IFERROR(Q37/C37,0) -> 0.57142857
A38: =IF(A9="","",A9) -> Carlos Perez | B38: =IF(B9="","",B9) -> 2 | C38: =C9+T9+AK9+BB9+BS9+CJ9+DA9+DR9+EI9+EZ9+FQ9+GH9+GY9+HP9+IG9 -> 7 | D38: =D9+U9+AL9+BC9+BT9+CK9+DB9+DS9+EJ9+FA9+FR9+GI9+GZ9+HQ9+IH9 -> 2 | E38: =E9+V9+AM9+BD9+BU9+CL9+DC9+DT9+EK9+FB9+FS9+GJ9+HA9+HR9+II9 -> 3 | F38: =F9+W9+AN9+BE9+BV9+CM9+DD9+DU9+EL9+FC9+FT9+GK9+HB9+HS9+IJ9 -> 0 | G38: =G9+X9+AO9+BF9+BW9+CN9+DE9+DV9+EM9+FD9+FU9+GL9+HC9+HT9+IK9 -> 0 | H38: =H9+Y9+AP9+BG9+BX9+CO9+DF9+DW9+EN9+FE9+FV9+GM9+HD9+HU9+IL9 -> 1 | I38: =I9+Z9+AQ9+BH9+BY9+CP9+DG9+DX9+EO9+FF9+FW9+GN9+HE9+HV9+IM9 -> 3 | J38: =J9+AA9+AR9+BI9+BZ9+CQ9+DH9+DY9+EP9+FG9+FX9+GO9+HF9+HW9+IN9 -> 2 | ... R38: =R9+AI9+AZ9+BQ9+CH9+CY9+DP9+EG9+EX9+FO9+GF9+GW9+HN9+IE9+IV9 -> 13 | T38: =IFERROR(E38/C38,0) -> 0.42857143 | U38: =IFERROR(Q38/C38,0) -> 0.85714286
A39: =IF(A10="","",A10) -> Carlos Sanchez | B39: =IF(B10="","",B10) -> 3 | C39: =C10+T10+AK10+BB10+BS10+CJ10+DA10+DR10+EI10+EZ10+FQ10+GH10+GY10+HP10+IG10 -> 7 | D39: =D10+U10+AL10+BC10+BT10+CK10+DB10+DS10+EJ10+FA10+FR10+GI10+GZ10+HQ10+IH10 -> 5 | E39: =E10+V10+AM10+BD10+BU10+CL10+DC10+DT10+EK10+FB10+FS10+GJ10+HA10+HR10+II10 -> 1 | F39: =F10+W10+AN10+BE10+BV10+CM10+DD10+DU10+EL10+FC10+FT10+GK10+HB10+HS10+IJ10 -> 1 | G39: =G10+X10+AO10+BF10+BW10+CN10+DE10+DV10+EM10+FD10+FU10+GL10+HC10+HT10+IK10 -> 0 | H39: =H10+Y10+AP10+BG10+BX10+CO10+DF10+DW10+EN10+FE10+FV10+GM10+HD10+HU10+IL10 -> 0 | I39: =I10+Z10+AQ10+BH10+BY10+CP10+DG10+DX10+EO10+FF10+FW10+GN10+HE10+HV10+IM10 -> 2 | J39: =J10+AA10+AR10+BI10+BZ10+CQ10+DH10+DY10+EP10+FG10+FX10+GO10+HF10+HW10+IN10 -> 4 | ... R39: =R10+AI10+AZ10+BQ10+CH10+CY10+DP10+EG10+EX10+FO10+GF10+GW10+HN10+IE10+IV10 -> 15 | T39: =IFERROR(E39/C39,0) -> 0.14285714 | U39: =IFERROR(Q39/C39,0) -> 0.28571429
A40: =IF(A11="","",A11) -> Carlos Ramirez | B40: =IF(B11="","",B11) -> 4 | C40: =C11+T11+AK11+BB11+BS11+CJ11+DA11+DR11+EI11+EZ11+FQ11+GH11+GY11+HP11+IG11 -> 7 | D40: =D11+U11+AL11+BC11+BT11+CK11+DB11+DS11+EJ11+FA11+FR11+GI11+GZ11+HQ11+IH11 -> 4 | E40: =E11+V11+AM11+BD11+BU11+CL11+DC11+DT11+EK11+FB11+FS11+GJ11+HA11+HR11+II11 -> 3 | F40: =F11+W11+AN11+BE11+BV11+CM11+DD11+DU11+EL11+FC11+FT11+GK11+HB11+HS11+IJ11 -> 0 | G40: =G11+X11+AO11+BF11+BW11+CN11+DE11+DV11+EM11+FD11+FU11+GL11+HC11+HT11+IK11 -> 0 | H40: =H11+Y11+AP11+BG11+BX11+CO11+DF11+DW11+EN11+FE11+FV11+GM11+HD11+HU11+IL11 -> 1 | I40: =I11+Z11+AQ11+BH11+BY11+CP11+DG11+DX11+EO11+FF11+FW11+GN11+HE11+HV11+IM11 -> 5 | J40: =J11+AA11+AR11+BI11+BZ11+CQ11+DH11+DY11+EP11+FG11+FX11+GO11+HF11+HW11+IN11 -> 2 | ... R40: =R11+AI11+AZ11+BQ11+CH11+CY11+DP11+EG11+EX11+FO11+GF11+GW11+HN11+IE11+IV11 -> 14 | T40: =IFERROR(E40/C40,0) -> 0.42857143 | U40: =IFERROR(Q40/C40,0) -> 0.85714286
A41: =IF(A12="","",A12) -> Carlos Torres | B41: =IF(B12="","",B12) -> 5 | C41: =C12+T12+AK12+BB12+BS12+CJ12+DA12+DR12+EI12+EZ12+FQ12+GH12+GY12+HP12+IG12 -> 10 | D41: =D12+U12+AL12+BC12+BT12+CK12+DB12+DS12+EJ12+FA12+FR12+GI12+GZ12+HQ12+IH12 -> 6 | E41: =E12+V12+AM12+BD12+BU12+CL12+DC12+DT12+EK12+FB12+FS12+GJ12+HA12+HR12+II12 -> 6 | F41: =F12+W12+AN12+BE12+BV12+CM12+DD12+DU12+EL12+FC12+FT12+GK12+HB12+HS12+IJ12 -> 0 | G41: =G12+X12+AO12+BF12+BW12+CN12+DE12+DV12+EM12+FD12+FU12+GL12+HC12+HT12+IK12 -> 1 | H41: =H12+Y12+AP12+BG12+BX12+CO12+DF12+DW12+EN12+FE12+FV12+GM12+HD12+HU12+IL12 -> 0 | I41: =I12+Z12+AQ12+BH12+BY12+CP12+DG12+DX12+EO12+FF12+FW12+GN12+HE12+HV12+IM12 -> 4 | J41: =J12+AA12+AR12+BI12+BZ12+CQ12+DH12+DY12+EP12+FG12+FX12+GO12+HF12+HW12+IN12 -> 1 | ... R41: =R12+AI12+AZ12+BQ12+CH12+CY12+DP12+EG12+EX12+FO12+GF12+GW12+HN12+IE12+IV12 -> 12 | T41: =IFERROR(E41/C41,0) -> 0.6 | U41: =IFERROR(Q41/C41,0) -> 0.8
A42: =IF(A13="","",A13) -> Carlos Flores | B42: =IF(B13="","",B13) -> 6 | C42: =C13+T13+AK13+BB13+BS13+CJ13+DA13+DR13+EI13+EZ13+FQ13+GH13+GY13+HP13+IG13 -> 9 | D42: =D13+U13+AL13+BC13+BT13+CK13+DB13+DS13+EJ13+FA13+FR13+GI13+GZ13+HQ13+IH13 -> 4 | E42: =E13+V13+AM13+BD13+BU13+CL13+DC13+DT13+EK13+FB13+FS13+GJ13+HA13+HR13+II13 -> 0 | F42: =F13+W13+AN13+BE13+BV13+CM13+DD13+DU13+EL13+FC13+FT13+GK13+HB13+HS13+IJ13 -> 0 | G42: =G13+X13+AO13+BF13+BW13+CN13+DE13+DV13+EM13+FD13+FU13+GL13+HC13+HT13+IK13 -> 0 | H42: =H13+Y13+AP13+BG13+BX13+CO13+DF13+DW13+EN13+FE13+FV13+GM13+HD13+HU13+IL13 -> 0 | I42: =I13+Z13+AQ13+BH13+BY13+CP13+DG13+DX13+EO13+FF13+FW13+GN13+HE13+HV13+IM13 -> 2 | J42: =J13+AA13+AR13+BI13+BZ13+CQ13+DH13+DY13+EP13+FG13+FX13+GO13+HF13+HW13+IN13 -> 2 | ... R42: =R13+AI13+AZ13+BQ13+CH13+CY13+DP13+EG13+EX13+FO13+GF13+GW13+HN13+IE13+IV13 -> 16 | T42: =IFERROR(E42/C42,0) -> 0 | U42: =IFERROR(Q42/C42,0) -> 0
A43: =IF(A14="","",A14) -> Carlos Rivera | B43: =IF(B14="","",B14) -> 7 | C43: =C14+T14+AK14+BB14+BS14+CJ14+DA14+DR14+EI14+EZ14+FQ14+GH14+GY14+HP14+IG14 -> 8 | D43: =D14+U14+AL14+BC14+BT14+CK14+DB14+DS14+EJ14+FA14+FR14+GI14+GZ14+HQ14+IH14 -> 6 | E43: =E14+V14+AM14+BD14+BU14+CL14+DC14+DT14+EK14+FB14+FS14+GJ14+HA14+HR14+II14 -> 4 | F43: =F14+W14+AN14+BE14+BV14+CM14+DD14+DU14+EL14+FC14+FT14+GK14+HB14+HS14+IJ14 -> 0 | G43: =G14+X14+AO14+BF14+BW14+CN14+DE14+DV14+EM14+FD14+FU14+GL14+HC14+HT14+IK14 -> 0 | H43: =H14+Y14+AP14+BG14+BX14+CO14+DF14+DW14+EN14+FE14+FV14+GM14+HD14+HU14+IL14 -> 1 | I43: =I14+Z14+AQ14+BH14+BY14+CP14+DG14+DX14+EO14+FF14+FW14+GN14+HE14+HV14+IM14 -> 5 | J43: =J14+AA14+AR14+BI14+BZ14+CQ14+DH14+DY14+EP14+FG14+FX14+GO14+HF14+HW14+IN14 -> 0 | ... R43: =R14+AI14+AZ14+BQ14+CH14+CY14+DP14+EG14+EX14+FO14+GF14+GW14+HN14+IE14+IV14 -> 13 | T43: =IFERROR(E43/C43,0) -> 0.5 | U43: =IFERROR(Q43/C43,0) -> 0.875
A44: =IF(A15="","",A15) -> Carlos Gomez | B44: =IF(B15="","",B15) -> 8 | C44: =C15+T15+AK15+BB15+BS15+CJ15+DA15+DR15+EI15+EZ15+FQ15+GH15+GY15+HP15+IG15 -> 7 | D44: =D15+U15+AL15+BC15+BT15+CK15+DB15+DS15+EJ15+FA15+FR15+GI15+GZ15+HQ15+IH15 -> 1 | E44: =E15+V15+AM15+BD15+BU15+CL15+DC15+DT15+EK15+FB15+FS15+GJ15+HA15+HR15+II15 -> 5 | F44: =F15+W15+AN15+BE15+BV15+CM15+DD15+DU15+EL15+FC15+FT15+GK15+HB15+HS15+IJ15 -> 0 | G44: =G15+X15+AO15+BF15+BW15+CN15+DE15+DV15+EM15+FD15+FU15+GL15+HC15+HT15+IK15 -> 0 | H44: =H15+Y15+AP15+BG15+BX15+CO15+DF15+DW15+EN15+FE15+FV15+GM15+HD15+HU15+IL15 -> 0 | I44: =I15+Z15+AQ15+BH15+BY15+CP15+DG15+DX15+EO15+FF15+FW15+GN15+HE15+HV15+IM15 -> 5 | J44: =J15+AA15+AR15+BI15+BZ15+CQ15+DH15+DY15+EP15+FG15+FX15+GO15+HF15+HW15+IN15 -> 0 | ... R44: =R15+AI15+AZ15+BQ15+CH15+CY15+DP15+EG15+EX15+FO15+GF15+GW15+HN15+IE15+IV15 -> 11 | T44: =IFERROR(E44/C44,0) -> 0.71428571 | U44: =IFERROR(Q44/C44,0) -> 0.71428571
A45: =IF(A16="","",A16) -> Carlos Diaz | B45: =IF(B16="","",B16) -> 9 | C45: =C16+T16+AK16+BB16+BS16+CJ16+DA16+DR16+EI16+EZ16+FQ16+GH16+GY16+HP16+IG16 -> 5 | D45: =D16+U16+AL16+BC16+BT16+CK16+DB16+DS16+EJ16+FA16+FR16+GI16+GZ16+HQ16+IH16 -> 5 | E45: =E16+V16+AM16+BD16+BU16+CL16+DC16+DT16+EK16+FB16+FS16+GJ16+HA16+HR16+II16 -> 1 | F45: =F16+W16+AN16+BE16+BV16+CM16+DD16+DU16+EL16+FC16+FT16+GK16+HB16+HS16+IJ16 -> 0 | G45: =G16+X16+AO16+BF16+BW16+CN16+DE16+DV16+EM16+FD16+FU16+GL16+HC16+HT16+IK16 -> 0 | H45: =H16+Y16+AP16+BG16+BX16+CO16+DF16+DW16+EN16+FE16+FV16+GM16+HD16+HU16+IL16 -> 1 | I45: =I16+Z16+AQ16+BH16+BY16+CP16+DG16+DX16+EO16+FF16+FW16+GN16+HE16+HV16+IM16 -> 1 | J45: =J16+AA16+AR16+BI16+BZ16+CQ16+DH16+DY16+EP16+FG16+FX16+GO16+HF16+HW16+IN16 -> 3 | ... R45: =R16+AI16+AZ16+BQ16+CH16+CY16+DP16+EG16+EX16+FO16+GF16+GW16+HN16+IE16+IV16 -> 6 | T45: =IFERROR(E45/C45,0) -> 0.2 | U45: =IFERROR(Q45/C45,0) -> 0.8
A46: =IF(A17="","",A17) -> Carlos Reyes | B46: =IF(B17="","",B17) -> 10 | C46: =C17+T17+AK17+BB17+BS17+CJ17+DA17+DR17+EI17+EZ17+FQ17+GH17+GY17+HP17+IG17 -> 7 | D46: =D17+U17+AL17+BC17+BT17+CK17+DB17+DS17+EJ17+FA17+FR17+GI17+GZ17+HQ17+IH17 -> 3 | E46: =E17+V17+AM17+BD17+BU17+CL17+DC17+DT17+EK17+FB17+FS17+GJ17+HA17+HR17+II17 -> 4 | F46: =F17+W17+AN17+BE17+BV17+CM17+DD17+DU17+EL17+FC17+FT17+GK17+HB17+HS17+IJ17 -> 0 | G46: =G17+X17+AO17+BF17+BW17+CN17+DE17+DV17+EM17+FD17+FU17+GL17+HC17+HT17+IK17 -> 0 | H46: =H17+Y17+AP17+BG17+BX17+CO17+DF17+DW17+EN17+FE17+FV17+GM17+HD17+HU17+IL17 -> 0 | I46: =I17+Z17+AQ17+BH17+BY17+CP17+DG17+DX17+EO17+FF17+FW17+GN17+HE17+HV17+IM17 -> 5 | J46: =J17+AA17+AR17+BI17+BZ17+CQ17+DH17+DY17+EP17+FG17+FX17+GO17+HF17+HW17+IN17 -> 1 | ... R46: =R17+AI17+AZ17+BQ17+CH17+CY17+DP17+EG17+EX17+FO17+GF17+GW17+HN17+IE17+IV17 -> 14 | T46: =IFERROR(E46/C46,0) -> 0.57142857 | U46: =IFERROR(Q46/C46,0) -> 0.57142857
A47: =IF(A18="","",A18) -> Carlos Morales | B47: =IF(B18="","",B18) -> 11 | C47: =C18+T18+AK18+BB18+BS18+CJ18+DA18+DR18+EI18+EZ18+FQ18+GH18+GY18+HP18+IG18 -> 5 | D47: =D18+U18+AL18+BC18+BT18+CK18+DB18+DS18+EJ18+FA18+FR18+GI18+GZ18+HQ18+IH18 -> 5 | E47: =E18+V18+AM18+BD18+BU18+CL18+DC18+DT18+EK18+FB18+FS18+GJ18+HA18+HR18+II18 -> 4 | F47: =F18+W18+AN18+BE18+BV18+CM18+DD18+DU18+EL18+FC18+FT18+GK18+HB18+HS18+IJ18 -> 0 | G47: =G18+X18+AO18+BF18+BW18+CN18+DE18+DV18+EM18+FD18+FU18+GL18+HC18+HT18+IK18 -> 0 | H47: =H18+Y18+AP18+BG18+BX18+CO18+DF18+DW18+EN18+FE18+FV18+GM18+HD18+HU18+IL18 -> 0 | I47: =I18+Z18+AQ18+BH18+BY18+CP18+DG18+DX18+EO18+FF18+FW18+GN18+HE18+HV18+IM18 -> 2 | J47: =J18+AA18+AR18+BI18+BZ18+CQ18+DH18+DY18+EP18+FG18+FX18+GO18+HF18+HW18+IN18 -> 1 | ... R47: =R18+AI18+AZ18+BQ18+CH18+CY18+DP18+EG18+EX18+FO18+GF18+GW18+HN18+IE18+IV18 -> 8 | T47: =IFERROR(E47/C47,0) -> 0.8 | U47: =IFERROR(Q47/C47,0) -> 0.8
A48: =IF(A19="","",A19) -> Carlos Cruz | B48: =IF(B19="","",B19) -> 12 | C48: =C19+T19+AK19+BB19+BS19+CJ19+DA19+DR19+EI19+EZ19+FQ19+GH19+GY19+HP19+IG19 -> 8 | D48: =D19+U19+AL19+BC19+BT19+CK19+DB19+DS19+EJ19+FA19+FR19+GI19+GZ19+HQ19+IH19 -> 3 | E48: =E19+V19+AM19+BD19+BU19+CL19+DC19+DT19+EK19+FB19+FS19+GJ19+HA19+HR19+II19 -> 1 | F48: =F19+W19+AN19+BE19+BV19+CM19+DD19+DU19+EL19+FC19+FT19+GK19+HB19+HS19+IJ19 -> 1 | G48: =G19+X19+AO19+BF19+BW19+CN19+DE19+DV19+EM19+FD19+FU19+GL19+HC19+HT19+IK19 -> 0 | H48: =H19+Y19+AP19+BG19+BX19+CO19+DF19+DW19+EN19+FE19+FV19+GM19+HD19+HU19+IL19 -> 0 | I48: =I19+Z19+AQ19+BH19+BY19+CP19+DG19+DX19+EO19+FF19+FW19+GN19+HE19+HV19+IM19 -> 3 | J48: =J19+AA19+AR19+BI19+BZ19+CQ19+DH19+DY19+EP19+FG19+FX19+GO19+HF19+HW19+IN19 -> 2 | ... R48: =R19+AI19+AZ19+BQ19+CH19+CY19+DP19+EG19+EX19+FO19+GF19+GW19+HN19+IE19+IV19 -> 11 | T48: =IFERROR(E48/C48,0) -> 0.125 | U48: =IFERROR(Q48/C48,0) -> 0.25
... A61: =IF(A32="","",A32) -> Jose Torres | B61: =IF(B32="","",B32) -> 25 | C61: =C32+T32+AK32+BB32+BS32+CJ32+DA32+DR32+EI32+EZ32+FQ32+GH32+GY32+HP32+IG32 -> 6 | D61: =D32+U32+AL32+BC32+BT32+CK32+DB32+DS32+EJ32+FA32+FR32+GI32+GZ32+HQ32+IH32 -> 2 | E61: =E32+V32+AM32+BD32+BU32+CL32+DC32+DT32+EK32+FB32+FS32+GJ32+HA32+HR32+II32 -> 3 | F61: =F32+W32+AN32+BE32+BV32+CM32+DD32+DU32+EL32+FC32+FT32+GK32+HB32+HS32+IJ32 -> 0 | G61: =G32+X32+AO32+BF32+BW32+CN32+DE32+DV32+EM32+FD32+FU32+GL32+HC32+HT32+IK32 -> 0 | H61: =H32+Y32+AP32+BG32+BX32+CO32+DF32+DW32+EN32+FE32+FV32+GM32+HD32+HU32+IL32 -> 1 | I61: =I32+Z32+AQ32+BH32+BY32+CP32+DG32+DX32+EO32+FF32+FW32+GN32+HE32+HV32+IM32 -> 0 | J61: =J32+AA32+AR32+BI32+BZ32+CQ32+DH32+DY32+EP32+FG32+FX32+GO32+HF32+HW32+IN32 -> 3 | ... R61: =R32+AI32+AZ32+BQ32+CH32+CY32+DP32+EG32+EX32+FO32+GF32+GW32+HN32+IE32+IV32 -> 14 | T61: =IFERROR(E61/C61,0) -> 0.5 | U61: =IFERROR(Q61/C61,0) -> 1
A62: TOTALES : | C62: =SUM(C37:C61) -> 184 | D62: =SUM(D37:D61) -> 96 | E62: =SUM(E37:E61) -> 85 | F62: =SUM(F37:F61) -> 7 | G62: =SUM(G37:G61) -> 2 | H62: =SUM(H37:H61) -> 7 | I62: =SUM(I37:I61) -> 73 | J62: =SUM(J37:J61) -> 52 | ... R62: =SUM(R37:R61) -> 318 | T62: =IFERROR(E62/C62,0) -> 0.46195652 | U62: =IFERROR(Q62/C62,0) -> 0.63586957
A64: L A N Z A D O R E S
A65: NOMBRE | B65: No | C65: P? | D65: G/P/S | E65: INN | F65: CL | G65: K | H65: H | I65: P? | J65: G/P/S | K65: INN | L65: CL | M65: K | N65: H | O65: P? | P65: G/P/S | Q65: INN | R65: CL | S65: K | T65: H | U65: P? | V65: G/P/S | W65: INN | X65: CL | Y65: K | Z65: H | AA65: P? | AB65: G/P/S | AC65: INN | AD65: CL | AE65: K | AF65: H | AG65: P? | AH65: G/P/S | AI65: INN | AJ65: CL | AK65: K | AL65: H | AM65: P? | AN65: G/P/S | AO65: INN | AP65: CL | AQ65: K | AR65: H | AS65: P? | AT65: G/P/S | AU65: INN | AV65: CL | AW65: K | AX65: H | AY65: P? | AZ65: G/P/S | BA65: INN | BB65: CL | BC65: K | BD65: H | BE65: P? | BF65: G/P/S | BG65: INN | BH65: CL | BI65: K | BJ65: H | BK65: P? | BL65: G/P/S | BM65: INN | BN65: CL | BO65: K | BP65: H | BQ65: P? | BR65: G/P/S | BS65: INN | BT65: CL | BU65: K | BV65: H | BW65: P? | BX65: G/P/S | BY65: INN | BZ65: CL | CA65: K | CB65: H | CC65: P? | CD65: G/P/S | CE65: INN | CF65: CL | CG65: K | CH65: H | CI65: P? | CJ65: G/P/S | CK65: INN | CL65: CL | CM65: K | CN65: H | CP65: JJ | CQ65: JG | CR65: JP | CS65: OUTS | CT65: INN | CU65: CL | CV65: K | CW65: H | CX65: PCL | CY65: SV
A66: =IF(A8="","",A8) -> Carlos Gonzalez | B66: =IF(B8="","",B8) -> 1 | C66: 1 | D66: G | E66: 2.1 | F66: 4 | G66: 4 | H66: 3 | I66: 1 | J66: G | K66: 2.1 | L66: 0 | M66: 1 | N66: 0 | CP66: =C66+I66+O66+U66+AA66+AG66+AM66+AS66+AY66+BE66+BK66+BQ66+BW66+CC66+CI66 -> 2 | CQ66: =COUNTIF(D66,"G")+COUNTIF(J66,"G")+COUNTIF(P66,"G")+COUNTIF(V66,"G")+COUNTIF(AB66,"G")+COUNTIF(AH66,"G")+COUNTIF(AN66,"G")+COUNTIF(AT66,"G")+COUNTIF(AZ66,"G")+COUNTIF(BF66,"G")+COUNTIF(BL66,"G")+COUNTIF(BR66,"G")+COUNTIF(BX66,"G")+COUNTIF(CD66,"G")+COUNTIF(CJ66,"G") -> 2 | CR66: =COUNTIF(D66,"P")+COUNTIF(J66,"P")+COUNTIF(P66,"P")+COUNTIF(V66,"P")+COUNTIF(AB66,"P")+COUNTIF(AH66,"P")+COUNTIF(AN66,"P")+COUNTIF(AT66,"P")+COUNTIF(AZ66,"P")+COUNTIF(BF66,"P")+COUNTIF(BL66,"P")+COUNTIF(BR66,"P")+COUNTIF(BX66,"P")+COUNTIF(CD66,"P")+COUNTIF(CJ66,"P") -> 0 | CS66: =(INT(E66)*3+(E66-INT(E66))*10)+(INT(K66)*3+(K66-INT(K66))*10)+(INT(Q66)*3+(Q66-INT(Q66))*10)+(INT(W66)*3+(W66-INT(W66))*10)+(INT(AC66)*3+(AC66-INT(AC66))*10)+(INT(AI66)*3+(AI66-INT(AI66))*10)+(INT(AO66)*3+(AO66-INT(AO66))*10)+(INT(AU66)*3+(AU66-INT(AU66))*10)+(INT(BA66)*3+(BA66-INT(BA66))*10)+(INT(BG66)*3+(BG66-INT(BG66))*10)+(INT(BM66)*3+(BM66-INT(BM66))*10)+(INT(BS66)*3+(BS66-INT(BS66))*10)+(INT(BY66)*3+(BY66-INT(BY66))*10)+(INT(CE66)*3+(CE66-INT(CE66))*10)+(INT(CK66)*3+(CK66-INT(CK66))*10) -> 14 | CT66: =INT(CS66/3)+MOD(CS66,3)/10 -> 4.2 | CU66: =F66+L66+R66+X66+AD66+AJ66+AP66+AV66+BB66+BH66+BN66+BT66+BZ66+CF66+CL66 -> 4 | CV66: =G66+M66+S66+Y66+AE66+AK66+AQ66+AW66+BC66+BI66+BO66+BU66+CA66+CG66+CM66 -> 5 | CW66: =H66+N66+T66+Z66+AF66+AL66+AR66+AX66+BD66+BJ66+BP66+BV66+CB66+CH66+CN66 -> 3 | CX66: =IFERROR(CU66*27/CS66,0) -> 7.7142857 | CY66: =COUNTIF(D66,"S")+COUNTIF(J66,"S")+COUNTIF(P66,"S")+COUNTIF(V66,"S")+COUNTIF(AB66,"S")+COUNTIF(AH66,"S")+COUNTIF(AN66,"S")+COUNTIF(AT66,"S")+COUNTIF(AZ66,"S")+COUNTIF(BF66,"S")+COUNTIF(BL66,"S")+COUNTIF(BR66,"S")+COUNTIF(BX66,"S")+COUNTIF(CD66,"S")+COUNTIF(CJ66,"S") -> 0
