Workbook

Sheet equipo1
A1: CORPORACION CRIOLLITOS DE VENEZUELA
A2: LIGA DE BEISBOL MENOR JUAN GUILLERMO GUZMAN
B4: CATEGORIA : INFANTIL
A6: equipo1 | C6: O F E N S I V A I N D I V I D U A L
A7: NOMBRE | B7: No | C7: VB | D7: CA | E7: H | F7: 2B | G7: 3B | H7: HR | I7: CI | J7: K | K7: BB | L7: BR | M7: GP | N7: SH | O7: SF | P7: INT | Q7: BAL | R7: AL | T7: VB | U7: CA | V7: H | W7: 2B | X7: 3B | Y7: HR | Z7: CI | AA7: K | AB7: BB | AC7: BR | AD7: GP | AE7: SH | AF7: SF | AG7: INT | AH7: BAL | AI7: AL | AK7: VB | AL7: CA | AM7: H | AN7: 2B | AO7: 3B | AP7: HR | AQ7: CI | AR7: K | AS7: BB | AT7: BR | AU7: GP | AV7: SH | AW7: SF | AX7: INT | AY7: BAL | AZ7: AL | BB7: VB | BC7: CA | BD7: H | BE7: 2B | BF7: 3B | BG7: HR | BH7: CI | BI7: K | BJ7: BB | BK7: BR | BL7: GP | BM7: SH | BN7: SF | BO7: INT | BP7: BAL | BQ7: AL | BS7: VB | BT7: CA | BU7: H | BV7: 2B | BW7: 3B | BX7: HR | BY7: CI | BZ7: K | CA7: BB | CB7: BR | CC7: GP | CD7: SH | CE7: SF | CF7: INT | CG7: BAL | CH7: AL | CJ7: VB | CK7: CA | CL7: H | CM7: 2B | CN7: 3B | CO7: HR | CP7: CI | CQ7: K | CR7: BB | CS7: BR | CT7: GP | CU7: SH | CV7: SF | CW7: INT | CX7: BAL | CY7: AL | DA7: VB | DB7: CA | DC7: H | DD7: 2B | DE7: 3B | DF7: HR | DG7: CI | DH7: K | DI7: BB | DJ7: BR | DK7: GP | DL7: SH | DM7: SF | DN7: INT | DO7: BAL | DP7: AL | DR7: VB | DS7: CA | DT7: H | DU7: 2B | DV7: 3B | DW7: HR | DX7: CI | DY7: K | DZ7: BB | EA7: BR | EB7: GP | EC7: SH | ED7: SF | EE7: INT | EF7: BAL | EG7: AL | EI7: VB | EJ7: CA | EK7: H | EL7: 2B | EM7: 3B | EN7: HR | EO7: CI | EP7: K | EQ7: BB | ER7: BR | ES7: GP | ET7: SH | EU7: SF | EV7: INT | EW7: BAL | EX7: AL | EZ7: VB | FA7: CA | FB7: H | FC7: 2B | FD7: 3B | FE7: HR | FF7: CI | FG7: K | FH7: BB | FI7: BR | FJ7: GP | FK7: SH | FL7: SF | FM7: INT | FN7: BAL | FO7: AL | FQ7: VB | FR7: CA | FS7: H | FT7: 2B | FU7: 3B | FV7: HR | FW7: CI | FX7: K | FY7: BB | FZ7: BR | GA7: GP | GB7: SH | GC7: SF | GD7: INT | GE7: BAL | GF7: AL | GH7: VB | GI7: CA | GJ7: H | GK7: 2B | GL7: 3B | GM7: HR | GN7: CI | GO7: K | GP7: BB | GQ7: BR | GR7: GP | GS7: SH | GT7: SF | GU7: INT | GV7: BAL | GW7: AL | GY7: VB | GZ7: CA | HA7: H | HB7: 2B | HC7: 3B | HD7: HR | HE7: CI | HF7: K | HG7: BB | HH7: BR | HI7: GP | HJ7: SH | HK7: SF | HL7: INT | HM7: BAL | HN7: AL | HP7: VB | HQ7: CA | HR7: H | HS7: 2B | HT7: 3B | HU7: HR | HV7: CI | HW7: K | HX7: BB | HY7: BR | HZ7: GP | IA7: SH | IB7: SF | IC7: INT | ID7: BAL | IE7: AL | IG7: VB | IH7: CA | II7: H | IJ7: 2B | IK7: 3B | IL7: HR | IM7: CI | IN7: K | IO7: BB | IP7: BR | IQ7: GP | IR7: SH | IS7: SF | IT7: INT | IU7: BAL | IV7: AL
A8: JESUS HERNANDEZ | B8: 5 | C8: 4 | D8: 1 | E8: 1 | H8: 1 | I8: 2 | L8: 1 | Q8: =(E8-(F8+G8+H8))+(F8*2)+(G8*3)+(H8*4) | R8: =C8+K8+M8+N8+O8+P8 | T8: 4 | V8: 1 | AH8: =(V8-(W8+X8+Y8))+(W8*2)+(X8*3)+(Y8*4) | AI8: =T8+AB8+AD8+AE8+AF8+AG8 | AK8: 4 | AM8: 4 | AY8: =(AM8-(AN8+AO8+AP8))+(AN8*2)+(AO8*3)+(AP8*4) | AZ8: =AK8+AS8+AU8+AV8+AW8+AX8 | BB8: 2 | BD8: 0 | BP8: =(BD8-(BE8+BF8+BG8))+(BE8*2)+(BF8*3)+(BG8*4) | BQ8: =BB8+BJ8+BL8+BM8+BN8+BO8 | BS8: 1 | BU8: 1 | CG8: =(BU8-(BV8+BW8+BX8))+(BV8*2)+(BW8*3)+(BX8*4) | CH8: =BS8+CA8+CC8+CD8+CE8+CF8 | CJ8: 5 | CL8: 0 | CX8: =(CL8-(CM8+CN8+CO8))+(CM8*2)+(CN8*3)+(CO8*4) | CY8: =CJ8+CR8+CT8+CU8+CV8+CW8 | DA8: 4 | DC8: 1 | DO8: =(DC8-(DD8+DE8+DF8))+(DD8*2)+(DE8*3)+(DF8*4) | DP8: =DA8+DI8+DK8+DL8+DM8+DN8 | DR8: 5 | DT8: 0 | EF8: =(DT8-(DU8+DV8+DW8))+(DU8*2)+(DV8*3)+(DW8*4) | EG8: =DR8+DZ8+EB8+EC8+ED8+EE8 | EI8: 3 | EK8: 0 | EW8: =(EK8-(EL8+EM8+EN8))+(EL8*2)+(EM8*3)+(EN8*4) | EX8: =EI8+EQ8+ES8+ET8+EU8+EV8 | EZ8: 5 | FB8: 5 | FN8: =(FB8-(FC8+FD8+FE8))+(FC8*2)+(FD8*3)+(FE8*4) | FO8: =EZ8+FH8+FJ8+FK8+FL8+FM8 | FQ8: 2 | FR8: 1 | FS8: 1 | GE8: =(FS8-(FT8+FU8+FV8))+(FT8*2)+(FU8*3)+(FV8*4) | GF8: =FQ8+FY8+GA8+GB8+GC8+GD8 | GH8: 2 | GJ8: 0 | GV8: =(GJ8-(GK8+GL8+GM8))+(GK8*2)+(GL8*3)+(GM8*4) | GW8: =GH8+GP8+GR8+GS8+GT8+GU8 | GY8: 3 | HA8: 1 | HM8: =(HA8-(HB8+HC8+HD8))+(HB8*2)+(HC8*3)+(HD8*4) | HN8: =GY8+HG8+HI8+HJ8+HK8+HL8 | HP8: 2 | HR8: 1 | ID8: =(HR8-(HS8+HT8+HU8))+(HS8*2)+(HT8*3)+(HU8*4) | IE8: =HP8+HX8+HZ8+IA8+IB8+IC8 | IG8: 5 | II8: 0 | IU8: =(II8-(IJ8+IK8+IL8))+(IJ8*2)+(IK8*3)+(IL8*4) | IV8: =IG8+IO8+IQ8+IR8+IS8+IT8
A9: JOSEPH MENDOZA | B9: 6 | C9: 3 | D9: 1 | E9: 1 | F9: 1 | K9: 2 | Q9: =(E9-(F9+G9+H9))+(F9*2)+(G9*3)+(H9*4) | R9: =C9+K9+M9+N9+O9+P9 | AH9: =(V9-(W9+X9+Y9))+(W9*2)+(X9*3)+(Y9*4) | AI9: =T9+AB9+AD9+AE9+AF9+AG9 | AY9: =(AM9-(AN9+AO9+AP9))+(AN9*2)+(AO9*3)+(AP9*4) | AZ9: =AK9+AS9+AU9+AV9+AW9+AX9 | BP9: =(BD9-(BE9+BF9+BG9))+(BE9*2)+(BF9*3)+(BG9*4) | BQ9: =BB9+BJ9+BL9+BM9+BN9+BO9 | CG9: =(BU9-(BV9+BW9+BX9))+(BV9*2)+(BW9*3)+(BX9*4) | CH9: =BS9+CA9+CC9+CD9+CE9+CF9 | CX9: =(CL9-(CM9+CN9+CO9))+(CM9*2)+(CN9*3)+(CO9*4) | CY9: =CJ9+CR9+CT9+CU9+CV9+CW9 | DO9: =(DC9-(DD9+DE9+DF9))+(DD9*2)+(DE9*3)+(DF9*4) | DP9: =DA9+DI9+DK9+DL9+DM9+DN9 | EF9: =(DT9-(DU9+DV9+DW9))+(DU9*2)+(DV9*3)+(DW9*4) | EG9: =DR9+DZ9+EB9+EC9+ED9+EE9 | EW9: =(EK9-(EL9+EM9+EN9))+(EL9*2)+(EM9*3)+(EN9*4) | EX9: =EI9+EQ9+ES9+ET9+EU9+EV9 | FN9: =(FB9-(FC9+FD9+FE9))+(FC9*2)+(FD9*3)+(FE9*4) | FO9: =EZ9+FH9+FJ9+FK9+FL9+FM9 | GE9: =(FS9-(FT9+FU9+FV9))+(FT9*2)+(FU9*3)+(FV9*4) | GF9: =FQ9+FY9+GA9+GB9+GC9+GD9 | GV9: =(GJ9-(GK9+GL9+GM9))+(GK9*2)+(GL9*3)+(GM9*4) | GW9: =GH9+GP9+GR9+GS9+GT9+GU9 | HM9: =(HA9-(HB9+HC9+HD9))+(HB9*2)+(HC9*3)+(HD9*4) | HN9: =GY9+HG9+HI9+HJ9+HK9+HL9 | ID9: =(HR9-(HS9+HT9+HU9))+(HS9*2)+(HT9*3)+(HU9*4) | IE9: =HP9+HX9+HZ9+IA9+IB9+IC9 | IU9: =(II9-(IJ9+IK9+IL9))+(IJ9*2)+(IK9*3)+(IL9*4) | IV9: =IG9+IO9+IQ9+IR9+IS9+IT9
A10: ABRAHAN RODRIGUZ | B10: 2 | C10: 4 | E10: 1 | Q10: =(E10-(F10+G10+H10))+(F10*2)+(G10*3)+(H10*4) | R10: =C10+K10+M10+N10+O10+P10 | AH10: =(V10-(W10+X10+Y10))+(W10*2)+(X10*3)+(Y10*4) | AI10: =T10+AB10+AD10+AE10+AF10+AG10 | AY10: =(AM10-(AN10+AO10+AP10))+(AN10*2)+(AO10*3)+(AP10*4) | AZ10: =AK10+AS10+AU10+AV10+AW10+AX10 | BP10: =(BD10-(BE10+BF10+BG10))+(BE10*2)+(BF10*3)+(BG10*4) | BQ10: =BB10+BJ10+BL10+BM10+BN10+BO10 | CG10: =(BU10-(BV10+BW10+BX10))+(BV10*2)+(BW10*3)+(BX10*4) | CH10: =BS10+CA10+CC10+CD10+CE10+CF10 | CX10: =(CL10-(CM10+CN10+CO10))+(CM10*2)+(CN10*3)+(CO10*4) | CY10: =CJ10+CR10+CT10+CU10+CV10+CW10 | DO10: =(DC10-(DD10+DE10+DF10))+(DD10*2)+(DE10*3)+(DF10*4) | DP10: =DA10+DI10+DK10+DL10+DM10+DN10 | EF10: =(DT10-(DU10+DV10+DW10))+(DU10*2)+(DV10*3)+(DW10*4) | EG10: =DR10+DZ10+EB10+EC10+ED10+EE10 | EW10: =(EK10-(EL10+EM10+EN10))+(EL10*2)+(EM10*3)+(EN10*4) | EX10: =EI10+EQ10+ES10+ET10+EU10+EV10 | FN10: =(FB10-(FC10+FD10+FE10))+(FC10*2)+(FD10*3)+(FE10*4) | FO10: =EZ10+FH10+FJ10+FK10+FL10+FM10 | GE10: =(FS10-(FT10+FU10+FV10))+(FT10*2)+(FU10*3)+(FV10*4) | GF10: =FQ10+FY10+GA10+GB10+GC10+GD10 | GV10: =(GJ10-(GK10+GL10+GM10))+(GK10*2)+(GL10*3)+(GM10*4) | GW10: =GH10+GP10+GR10+GS10+GT10+GU10 | HM10: =(HA10-(HB10+HC10+HD10))+(HB10*2)+(HC10*3)+(HD10*4) | HN10: =GY10+HG10+HI10+HJ10+HK10+HL10 | ID10: =(HR10-(HS10+HT10+HU10))+(HS10*2)+(HT10*3)+(HU10*4) | IE10: =HP10+HX10+HZ10+IA10+IB10+IC10 | IU10: =(II10-(IJ10+IK10+IL10))+(IJ10*2)+(IK10*3)+(IL10*4) | IV10: =IG10+IO10+IQ10+IR10+IS10+IT10
A11: ALEXANDER HERNANDEZ | D11: 1 | I11: 1 | K11: 3 | L11: 3 | Q11: =(E11-(F11+G11+H11))+(F11*2)+(G11*3)+(H11*4) | R11: =C11+K11+M11+N11+O11+P11 | AH11: =(V11-(W11+X11+Y11))+(W11*2)+(X11*3)+(Y11*4) | AI11: =T11+AB11+AD11+AE11+AF11+AG11 | AY11: =(AM11-(AN11+AO11+AP11))+(AN11*2)+(AO11*3)+(AP11*4) | AZ11: =AK11+AS11+AU11+AV11+AW11+AX11 | BP11: =(BD11-(BE11+BF11+BG11))+(BE11*2)+(BF11*3)+(BG11*4) | BQ11: =BB11+BJ11+BL11+BM11+BN11+BO11 | CG11: =(BU11-(BV11+BW11+BX11))+(BV11*2)+(BW11*3)+(BX11*4) | CH11: =BS11+CA11+CC11+CD11+CE11+CF11 | CX11: =(CL11-(CM11+CN11+CO11))+(CM11*2)+(CN11*3)+(CO11*4) | CY11: =CJ11+CR11+CT11+CU11+CV11+CW11 | DO11: =(DC11-(DD11+DE11+DF11))+(DD11*2)+(DE11*3)+(DF11*4) | DP11: =DA11+DI11+DK11+DL11+DM11+DN11 | EF11: =(DT11-(DU11+DV11+DW11))+(DU11*2)+(DV11*3)+(DW11*4) | EG11: =DR11+DZ11+EB11+EC11+ED11+EE11 | EW11: =(EK11-(EL11+EM11+EN11))+(EL11*2)+(EM11*3)+(EN11*4) | EX11: =EI11+EQ11+ES11+ET11+EU11+EV11 | FN11: =(FB11-(FC11+FD11+FE11))+(FC11*2)+(FD11*3)+(FE11*4) | FO11: =EZ11+FH11+FJ11+FK11+FL11+FM11 | GE11: =(FS11-(FT11+FU11+FV11))+(FT11*2)+(FU11*3)+(FV11*4) | GF11: =FQ11+FY11+GA11+GB11+GC11+GD11 | GV11: =(GJ11-(GK11+GL11+GM11))+(GK11*2)+(GL11*3)+(GM11*4) | GW11: =GH11+GP11+GR11+GS11+GT11+GU11 | HM11: =(HA11-(HB11+HC11+HD11))+(HB11*2)+(HC11*3)+(HD11*4) | HN11: =GY11+HG11+HI11+HJ11+HK11+HL11 | ID11: =(HR11-(HS11+HT11+HU11))+(HS11*2)+(HT11*3)+(HU11*4) | IE11: =HP11+HX11+HZ11+IA11+IB11+IC11 | IU11: =(II11-(IJ11+IK11+IL11))+(IJ11*2)+(IK11*3)+(IL11*4) | IV11: =IG11+IO11+IQ11+IR11+IS11+IT11
A12: DANIEL LIENDO | C12: 1 | Q12: =(E12-(F12+G12+H12))+(F12*2)+(G12*3)+(H12*4) | R12: =C12+K12+M12+N12+O12+P12 | AH12: =(V12-(W12+X12+Y12))+(W12*2)+(X12*3)+(Y12*4) | AI12: =T12+AB12+AD12+AE12+AF12+AG12 | AY12: =(AM12-(AN12+AO12+AP12))+(AN12*2)+(AO12*3)+(AP12*4) | AZ12: =AK12+AS12+AU12+AV12+AW12+AX12 | BP12: =(BD12-(BE12+BF12+BG12))+(BE12*2)+(BF12*3)+(BG12*4) | BQ12: =BB12+BJ12+BL12+BM12+BN12+BO12 | CG12: =(BU12-(BV12+BW12+BX12))+(BV12*2)+(BW12*3)+(BX12*4) | CH12: =BS12+CA12+CC12+CD12+CE12+CF12 | CX12: =(CL12-(CM12+CN12+CO12))+(CM12*2)+(CN12*3)+(CO12*4) | CY12: =CJ12+CR12+CT12+CU12+CV12+CW12 | DO12: =(DC12-(DD12+DE12+DF12))+(DD12*2)+(DE12*3)+(DF12*4) | DP12: =DA12+DI12+DK12+DL12+DM12+DN12 | EF12: =(DT12-(DU12+DV12+DW12))+(DU12*2)+(DV12*3)+(DW12*4) | EG12: =DR12+DZ12+EB12+EC12+ED12+EE12 | EW12: =(EK12-(EL12+EM12+EN12))+(EL12*2)+(EM12*3)+(EN12*4) | EX12: =EI12+EQ12+ES12+ET12+EU12+EV12 | FN12: =(FB12-(FC12+FD12+FE12))+(FC12*2)+(FD12*3)+(FE12*4) | FO12: =EZ12+FH12+FJ12+FK12+FL12+FM12 | GE12: =(FS12-(FT12+FU12+FV12))+(FT12*2)+(FU12*3)+(FV12*4) | GF12: =FQ12+FY12+GA12+GB12+GC12+GD12 | GV12: =(GJ12-(GK12+GL12+GM12))+(GK12*2)+(GL12*3)+(GM12*4) | GW12: =GH12+GP12+GR12+GS12+GT12+GU12 | HM12: =(HA12-(HB12+HC12+HD12))+(HB12*2)+(HC12*3)+(HD12*4) | HN12: =GY12+HG12+HI12+HJ12+HK12+HL12 | ID12: =(HR12-(HS12+HT12+HU12))+(HS12*2)+(HT12*3)+(HU12*4) | IE12: =HP12+HX12+HZ12+IA12+IB12+IC12 | IU12: =(II12-(IJ12+IK12+IL12))+(IJ12*2)+(IK12*3)+(IL12*4) | IV12: =IG12+IO12+IQ12+IR12+IS12+IT12
A13: SEBASTIAN MUJICA | C13: 2 | J13: 1 | Q13: =(E13-(F13+G13+H13))+(F13*2)+(G13*3)+(H13*4) | R13: =C13+K13+M13+N13+O13+P13 | AH13: =(V13-(W13+X13+Y13))+(W13*2)+(X13*3)+(Y13*4) | AI13: =T13+AB13+AD13+AE13+AF13+AG13 | AY13: =(AM13-(AN13+AO13+AP13))+(AN13*2)+(AO13*3)+(AP13*4) | AZ13: =AK13+AS13+AU13+AV13+AW13+AX13 | BP13: =(BD13-(BE13+BF13+BG13))+(BE13*2)+(BF13*3)+(BG13*4) | BQ13: =BB13+BJ13+BL13+BM13+BN13+BO13 | CG13: =(BU13-(BV13+BW13+BX13))+(BV13*2)+(BW13*3)+(BX13*4) | CH13: =BS13+CA13+CC13+CD13+CE13+CF13 | CX13: =(CL13-(CM13+CN13+CO13))+(CM13*2)+(CN13*3)+(CO13*4) | CY13: =CJ13+CR13+CT13+CU13+CV13+CW13 | DO13: =(DC13-(DD13+DE13+DF13))+(DD13*2)+(DE13*3)+(DF13*4) | DP13: =DA13+DI13+DK13+DL13+DM13+DN13 | EF13: =(DT13-(DU13+DV13+DW13))+(DU13*2)+(DV13*3)+(DW13*4) | EG13: =DR13+DZ13+EB13+EC13+ED13+EE13 | EW13: =(EK13-(EL13+EM13+EN13))+(EL13*2)+(EM13*3)+(EN13*4) | EX13: =EI13+EQ13+ES13+ET13+EU13+EV13 | FN13: =(FB13-(FC13+FD13+FE13))+(FC13*2)+(FD13*3)+(FE13*4) | FO13: =EZ13+FH13+FJ13+FK13+FL13+FM13 | GE13: =(FS13-(FT13+FU13+FV13))+(FT13*2)+(FU13*3)+(FV13*4) | GF13: =FQ13+FY13+GA13+GB13+GC13+GD13 | GV13: =(GJ13-(GK13+GL13+GM13))+(GK13*2)+(GL13*3)+(GM13*4) | GW13: =GH13+GP13+GR13+GS13+GT13+GU13 | HM13: =(HA13-(HB13+HC13+HD13))+(HB13*2)+(HC13*3)+(HD13*4) | HN13: =GY13+HG13+HI13+HJ13+HK13+HL13 | ID13: =(HR13-(HS13+HT13+HU13))+(HS13*2)+(HT13*3)+(HU13*4) | IE13: =HP13+HX13+HZ13+IA13+IB13+IC13 | IU13: =(II13-(IJ13+IK13+IL13))+(IJ13*2)+(IK13*3)+(IL13*4) | IV13: =IG13+IO13+IQ13+IR13+IS13+IT13
A14: ANGEL RODRIGUEZ | C14: 3 | D14: 2 | E14: 2 | I14: 1 | J14: 1 | L14: 1 | Q14: =(E14-(F14+G14+H14))+(F14*2)+(G14*3)+(H14*4) | R14: =C14+K14+M14+N14+O14+P14 | AH14: =(V14-(W14+X14+Y14))+(W14*2)+(X14*3)+(Y14*4) | AI14: =T14+AB14+AD14+AE14+AF14+AG14 | AY14: =(AM14-(AN14+AO14+AP14))+(AN14*2)+(AO14*3)+(AP14*4) | AZ14: =AK14+AS14+AU14+AV14+AW14+AX14 | BP14: =(BD14-(BE14+BF14+BG14))+(BE14*2)+(BF14*3)+(BG14*4) | BQ14: =BB14+BJ14+BL14+BM14+BN14+BO14 | CG14: =(BU14-(BV14+BW14+BX14))+(BV14*2)+(BW14*3)+(BX14*4) | CH14: =BS14+CA14+CC14+CD14+CE14+CF14 | CX14: =(CL14-(CM14+CN14+CO14))+(CM14*2)+(CN14*3)+(CO14*4) | CY14: =CJ14+CR14+CT14+CU14+CV14+CW14 | DO14: =(DC14-(DD14+DE14+DF14))+(DD14*2)+(DE14*3)+(DF14*4) | DP14: =DA14+DI14+DK14+DL14+DM14+DN14 | EF14: =(DT14-(DU14+DV14+DW14))+(DU14*2)+(DV14*3)+(DW14*4) | EG14: =DR14+DZ14+EB14+EC14+ED14+EE14 | EW14: =(EK14-(EL14+EM14+EN14))+(EL14*2)+(EM14*3)+(EN14*4) | EX14: =EI14+EQ14+ES14+ET14+EU14+EV14 | FN14: =(FB14-(FC14+FD14+FE14))+(FC14*2)+(FD14*3)+(FE14*4) | FO14: =EZ14+FH14+FJ14+FK14+FL14+FM14 | GE14: =(FS14-(FT14+FU14+FV14))+(FT14*2)+(FU14*3)+(FV14*4) | GF14: =FQ14+FY14+GA14+GB14+GC14+GD14 | GV14: =(GJ14-(GK14+GL14+GM14))+(GK14*2)+(GL14*3)+(GM14*4) | GW14: =GH14+GP14+GR14+GS14+GT14+GU14 | HM14: =(HA14-(HB14+HC14+HD14))+(HB14*2)+(HC14*3)+(HD14*4) | HN14: =GY14+HG14+HI14+HJ14+HK14+HL14 | ID14: =(HR14-(HS14+HT14+HU14))+(HS14*2)+(HT14*3)+(HU14*4) | IE14: =HP14+HX14+HZ14+IA14+IB14+IC14 | IU14: =(II14-(IJ14+IK14+IL14))+(IJ14*2)+(IK14*3)+(IL14*4) | IV14: =IG14+IO14+IQ14+IR14+IS14+IT14
A15: FRANCISCO MONASTERIO | C15: 3 | D15: 1 | E15: 2 | G15: 1 | Q15: =(E15-(F15+G15+H15))+(F15*2)+(G15*3)+(H15*4) | R15: =C15+K15+M15+N15+O15+P15 | AH15: =(V15-(W15+X15+Y15))+(W15*2)+(X15*3)+(Y15*4) | AI15: =T15+AB15+AD15+AE15+AF15+AG15 | AY15: =(AM15-(AN15+AO15+AP15))+(AN15*2)+(AO15*3)+(AP15*4) | AZ15: =AK15+AS15+AU15+AV15+AW15+AX15 | BP15: =(BD15-(BE15+BF15+BG15))+(BE15*2)+(BF15*3)+(BG15*4) | BQ15: =BB15+BJ15+BL15+BM15+BN15+BO15 | CG15: =(BU15-(BV15+BW15+BX15))+(BV15*2)+(BW15*3)+(BX15*4) | CH15: =BS15+CA15+CC15+CD15+CE15+CF15 | CX15: =(CL15-(CM15+CN15+CO15))+(CM15*2)+(CN15*3)+(CO15*4) | CY15: =CJ15+CR15+CT15+CU15+CV15+CW15 | DO15: =(DC15-(DD15+DE15+DF15))+(DD15*2)+(DE15*3)+(DF15*4) | DP15: =DA15+DI15+DK15+DL15+DM15+DN15 | EF15: =(DT15-(DU15+DV15+DW15))+(DU15*2)+(DV15*3)+(DW15*4) | EG15: =DR15+DZ15+EB15+EC15+ED15+EE15 | EW15: =(EK15-(EL15+EM15+EN15))+(EL15*2)+(EM15*3)+(EN15*4) | EX15: =EI15+EQ15+ES15+ET15+EU15+EV15 | FN15: =(FB15-(FC15+FD15+FE15))+(FC15*2)+(FD15*3)+(FE15*4) | FO15: =EZ15+FH15+FJ15+FK15+FL15+FM15 | GE15: =(FS15-(FT15+FU15+FV15))+(FT15*2)+(FU15*3)+(FV15*4) | GF15: =FQ15+FY15+GA15+GB15+GC15+GD15 | GV15: =(GJ15-(GK15+GL15+GM15))+(GK15*2)+(GL15*3)+(GM15*4) | GW15: =GH15+GP15+GR15+GS15+GT15+GU15 | HM15: =(HA15-(HB15+HC15+HD15))+(HB15*2)+(HC15*3)+(HD15*4) | HN15: =GY15+HG15+HI15+HJ15+HK15+HL15 | ID15: =(HR15-(HS15+HT15+HU15))+(HS15*2)+(HT15*3)+(HU15*4) | IE15: =HP15+HX15+HZ15+IA15+IB15+IC15 | IU15: =(II15-(IJ15+IK15+IL15))+(IJ15*2)+(IK15*3)+(IL15*4) | IV15: =IG15+IO15+IQ15+IR15+IS15+IT15
A16: MARCOS MORALES | C16: 3 | D16: 2 | E16: 2 | F16: 1 | I16: 2 | J16: 1 | L16: 3 | Q16: =(E16-(F16+G16+H16))+(F16*2)+(G16*3)+(H16*4) | R16: =C16+K16+M16+N16+O16+P16 | AH16: =(V16-(W16+X16+Y16))+(W16*2)+(X16*3)+(Y16*4) | AI16: =T16+AB16+AD16+AE16+AF16+AG16 | AY16: =(AM16-(AN16+AO16+AP16))+(AN16*2)+(AO16*3)+(AP16*4) | AZ16: =AK16+AS16+AU16+AV16+AW16+AX16 | BP16: =(BD16-(BE16+BF16+BG16))+(BE16*2)+(BF16*3)+(BG16*4) | BQ16: =BB16+BJ16+BL16+BM16+BN16+BO16 | CG16: =(BU16-(BV16+BW16+BX16))+(BV16*2)+(BW16*3)+(BX16*4) | CH16: =BS16+CA16+CC16+CD16+CE16+CF16 | CX16: =(CL16-(CM16+CN16+CO16))+(CM16*2)+(CN16*3)+(CO16*4) | CY16: =CJ16+CR16+CT16+CU16+CV16+CW16 | DO16: =(DC16-(DD16+DE16+DF16))+(DD16*2)+(DE16*3)+(DF16*4) | DP16: =DA16+DI16+DK16+DL16+DM16+DN16 | EF16: =(DT16-(DU16+DV16+DW16))+(DU16*2)+(DV16*3)+(DW16*4) | EG16: =DR16+DZ16+EB16+EC16+ED16+EE16 | EW16: =(EK16-(EL16+EM16+EN16))+(EL16*2)+(EM16*3)+(EN16*4) | EX16: =EI16+EQ16+ES16+ET16+EU16+EV16 | FN16: =(FB16-(FC16+FD16+FE16))+(FC16*2)+(FD16*3)+(FE16*4) | FO16: =EZ16+FH16+FJ16+FK16+FL16+FM16 | GE16: =(FS16-(FT16+FU16+FV16))+(FT16*2)+(FU16*3)+(FV16*4) | GF16: =FQ16+FY16+GA16+GB16+GC16+GD16 | GV16: =(GJ16-(GK16+GL16+GM16))+(GK16*2)+(GL16*3)+(GM16*4) | GW16: =GH16+GP16+GR16+GS16+GT16+GU16 | HM16: =(HA16-(HB16+HC16+HD16))+(HB16*2)+(HC16*3)+(HD16*4) | HN16: =GY16+HG16+HI16+HJ16+HK16+HL16 | ID16: =(HR16-(HS16+HT16+HU16))+(HS16*2)+(HT16*3)+(HU16*4) | IE16: =HP16+HX16+HZ16+IA16+IB16+IC16 | IU16: =(II16-(IJ16+IK16+IL16))+(IJ16*2)+(IK16*3)+(IL16*4) | IV16: =IG16+IO16+IQ16+IR16+IS16+IT16
A17: ADRIAN MURILLO | C17: 2 | D17: 1 | J17: 1 | K17: 1 | L17: 1 | Q17: =(E17-(F17+G17+H17))+(F17*2)+(G17*3)+(H17*4) | R17: =C17+K17+M17+N17+O17+P17 | AH17: =(V17-(W17+X17+Y17))+(W17*2)+(X17*3)+(Y17*4) | AI17: =T17+AB17+AD17+AE17+AF17+AG17 | AY17: =(AM17-(AN17+AO17+AP17))+(AN17*2)+(AO17*3)+(AP17*4) | AZ17: =AK17+AS17+AU17+AV17+AW17+AX17 | BP17: =(BD17-(BE17+BF17+BG17))+(BE17*2)+(BF17*3)+(BG17*4) | BQ17: =BB17+BJ17+BL17+BM17+BN17+BO17 | CG17: =(BU17-(BV17+BW17+BX17))+(BV17*2)+(BW17*3)+(BX17*4) | CH17: =BS17+CA17+CC17+CD17+CE17+CF17 | CX17: =(CL17-(CM17+CN17+CO17))+(CM17*2)+(CN17*3)+(CO17*4) | CY17: =CJ17+CR17+CT17+CU17+CV17+CW17 | DO17: =(DC17-(DD17+DE17+DF17))+(DD17*2)+(DE17*3)+(DF17*4) | DP17: =DA17+DI17+DK17+DL17+DM17+DN17 | EF17: =(DT17-(DU17+DV17+DW17))+(DU17*2)+(DV17*3)+(DW17*4) | EG17: =DR17+DZ17+EB17+EC17+ED17+EE17 | EW17: =(EK17-(EL17+EM17+EN17))+(EL17*2)+(EM17*3)+(EN17*4) | EX17: =EI17+EQ17+ES17+ET17+EU17+EV17 | FN17: =(FB17-(FC17+FD17+FE17))+(FC17*2)+(FD17*3)+(FE17*4) | FO17: =EZ17+FH17+FJ17+FK17+FL17+FM17 | GE17: =(FS17-(FT17+FU17+FV17))+(FT17*2)+(FU17*3)+(FV17*4) | GF17: =FQ17+FY17+GA17+GB17+GC17+GD17 | GV17: =(GJ17-(GK17+GL17+GM17))+(GK17*2)+(GL17*3)+(GM17*4) | GW17: =GH17+GP17+GR17+GS17+GT17+GU17 | HM17: =(HA17-(HB17+HC17+HD17))+(HB17*2)+(HC17*3)+(HD17*4) | HN17: =GY17+HG17+HI17+HJ17+HK17+HL17 | ID17: =(HR17-(HS17+HT17+HU17))+(HS17*2)+(HT17*3)+(HU17*4) | IE17: =HP17+HX17+HZ17+IA17+IB17+IC17 | IU17: =(II17-(IJ17+IK17+IL17))+(IJ17*2)+(IK17*3)+(IL17*4) | IV17: =IG17+IO17+IQ17+IR17+IS17+IT17
A18: DARGREYBER RODRIGUEZ | Q18: =(E18-(F18+G18+H18))+(F18*2)+(G18*3)+(H18*4) | R18: =C18+K18+M18+N18+O18+P18 | AH18: =(V18-(W18+X18+Y18))+(W18*2)+(X18*3)+(Y18*4) | AI18: =T18+AB18+AD18+AE18+AF18+AG18 | AY18: =(AM18-(AN18+AO18+AP18))+(AN18*2)+(AO18*3)+(AP18*4) | AZ18: =AK18+AS18+AU18+AV18+AW18+AX18 | BP18: =(BD18-(BE18+BF18+BG18))+(BE18*2)+(BF18*3)+(BG18*4) | BQ18: =BB18+BJ18+BL18+BM18+BN18+BO18 | CG18: =(BU18-(BV18+BW18+BX18))+(BV18*2)+(BW18*3)+(BX18*4) | CH18: =BS18+CA18+CC18+CD18+CE18+CF18 | CX18: =(CL18-(CM18+CN18+CO18))+(CM18*2)+(CN18*3)+(CO18*4) | CY18: =CJ18+CR18+CT18+CU18+CV18+CW18 | DO18: =(DC18-(DD18+DE18+DF18))+(DD18*2)+(DE18*3)+(DF18*4) | DP18: =DA18+DI18+DK18+DL18+DM18+DN18 | EF18: =(DT18-(DU18+DV18+DW18))+(DU18*2)+(DV18*3)+(DW18*4) | EG18: =DR18+DZ18+EB18+EC18+ED18+EE18 | EW18: =(EK18-(EL18+EM18+EN18))+(EL18*2)+(EM18*3)+(EN18*4) | EX18: =EI18+EQ18+ES18+ET18+EU18+EV18 | FN18: =(FB18-(FC18+FD18+FE18))+(FC18*2)+(FD18*3)+(FE18*4) | FO18: =EZ18+FH18+FJ18+FK18+FL18+FM18 | GE18: =(FS18-(FT18+FU18+FV18))+(FT18*2)+(FU18*3)+(FV18*4) | GF18: =FQ18+FY18+GA18+GB18+GC18+GD18 | GV18: =(GJ18-(GK18+GL18+GM18))+(GK18*2)+(GL18*3)+(GM18*4) | GW18: =GH18+GP18+GR18+GS18+GT18+GU18 | HM18: =(HA18-(HB18+HC18+HD18))+(HB18*2)+(HC18*3)+(HD18*4) | HN18: =GY18+HG18+HI18+HJ18+HK18+HL18 | ID18: =(HR18-(HS18+HT18+HU18))+(HS18*2)+(HT18*3)+(HU18*4) | IE18: =HP18+HX18+HZ18+IA18+IB18+IC18 | IU18: =(II18-(IJ18+IK18+IL18))+(IJ18*2)+(IK18*3)+(IL18*4) | IV18: =IG18+IO18+IQ18+IR18+IS18+IT18
A19: JENSE FLORES | Q19: =(E19-(F19+G19+H19))+(F19*2)+(G19*3)+(H19*4) | R19: =C19+K19+M19+N19+O19+P19 | AH19: =(V19-(W19+X19+Y19))+(W19*2)+(X19*3)+(Y19*4) | AI19: =T19+AB19+AD19+AE19+AF19+AG19 | AY19: =(AM19-(AN19+AO19+AP19))+(AN19*2)+(AO19*3)+(AP19*4) | AZ19: =AK19+AS19+AU19+AV19+AW19+AX19 | BP19: =(BD19-(BE19+BF19+BG19))+(BE19*2)+(BF19*3)+(BG19*4) | BQ19: =BB19+BJ19+BL19+BM19+BN19+BO19 | CG19: =(BU19-(BV19+BW19+BX19))+(BV19*2)+(BW19*3)+(BX19*4) | CH19: =BS19+CA19+CC19+CD19+CE19+CF19 | CX19: =(CL19-(CM19+CN19+CO19))+(CM19*2)+(CN19*3)+(CO19*4) | CY19: =CJ19+CR19+CT19+CU19+CV19+CW19 | DO19: =(DC19-(DD19+DE19+DF19))+(DD19*2)+(DE19*3)+(DF19*4) | DP19: =DA19+DI19+DK19+DL19+DM19+DN19 | EF19: =(DT19-(DU19+DV19+DW19))+(DU19*2)+(DV19*3)+(DW19*4) | EG19: =DR19+DZ19+EB19+EC19+ED19+EE19 | EW19: =(EK19-(EL19+EM19+EN19))+(EL19*2)+(EM19*3)+(EN19*4) | EX19: =EI19+EQ19+ES19+ET19+EU19+EV19 | FN19: =(FB19-(FC19+FD19+FE19))+(FC19*2)+(FD19*3)+(FE19*4) | FO19: =EZ19+FH19+FJ19+FK19+FL19+FM19 | GE19: =(FS19-(FT19+FU19+FV19))+(FT19*2)+(FU19*3)+(FV19*4) | GF19: =FQ19+FY19+GA19+GB19+GC19+GD19 | GV19: =(GJ19-(GK19+GL19+GM19))+(GK19*2)+(GL19*3)+(GM19*4) | GW19: =GH19+GP19+GR19+GS19+GT19+GU19 | HM19: =(HA19-(HB19+HC19+HD19))+(HB19*2)+(HC19*3)+(HD19*4) | HN19: =GY19+HG19+HI19+HJ19+HK19+HL19 | ID19: =(HR19-(HS19+HT19+HU19))+(HS19*2)+(HT19*3)+(HU19*4) | IE19: =HP19+HX19+HZ19+IA19+IB19+IC19 | IU19: =(II19-(IJ19+IK19+IL19))+(IJ19*2)+(IK19*3)+(IL19*4) | IV19: =IG19+IO19+IQ19+IR19+IS19+IT19
Q20: =(E20-(F20+G20+H20))+(F20*2)+(G20*3)+(H20*4) | R20: =C20+K20+M20+N20+O20+P20 | AH20: =(V20-(W20+X20+Y20))+(W20*2)+(X20*3)+(Y20*4) | AI20: =T20+AB20+AD20+AE20+AF20+AG20 | AY20: =(AM20-(AN20+AO20+AP20))+(AN20*2)+(AO20*3)+(AP20*4) | AZ20: =AK20+AS20+AU20+AV20+AW20+AX20 | BP20: =(BD20-(BE20+BF20+BG20))+(BE20*2)+(BF20*3)+(BG20*4) | BQ20: =BB20+BJ20+BL20+BM20+BN20+BO20 | CG20: =(BU20-(BV20+BW20+BX20))+(BV20*2)+(BW20*3)+(BX20*4) | CH20: =BS20+CA20+CC20+CD20+CE20+CF20 | CX20: =(CL20-(CM20+CN20+CO20))+(CM20*2)+(CN20*3)+(CO20*4) | CY20: =CJ20+CR20+CT20+CU20+CV20+CW20 | DO20: =(DC20-(DD20+DE20+DF20))+(DD20*2)+(DE20*3)+(DF20*4) | DP20: =DA20+DI20+DK20+DL20+DM20+DN20 | EF20: =(DT20-(DU20+DV20+DW20))+(DU20*2)+(DV20*3)+(DW20*4) | EG20: =DR20+DZ20+EB20+EC20+ED20+EE20 | EW20: =(EK20-(EL20+EM20+EN20))+(EL20*2)+(EM20*3)+(EN20*4) | EX20: =EI20+EQ20+ES20+ET20+EU20+EV20 | FN20: =(FB20-(FC20+FD20+FE20))+(FC20*2)+(FD20*3)+(FE20*4) | FO20: =EZ20+FH20+FJ20+FK20+FL20+FM20 | GE20: =(FS20-(FT20+FU20+FV20))+(FT20*2)+(FU20*3)+(FV20*4) | GF20: =FQ20+FY20+GA20+GB20+GC20+GD20 | GV20: =(GJ20-(GK20+GL20+GM20))+(GK20*2)+(GL20*3)+(GM20*4) | GW20: =GH20+GP20+GR20+GS20+GT20+GU20 | HM20: =(HA20-(HB20+HC20+HD20))+(HB20*2)+(HC20*3)+(HD20*4) | HN20: =GY20+HG20+HI20+HJ20+HK20+HL20 | ID20: =(HR20-(HS20+HT20+HU20))+(HS20*2)+(HT20*3)+(HU20*4) | IE20: =HP20+HX20+HZ20+IA20+IB20+IC20 | IU20: =(II20-(IJ20+IK20+IL20))+(IJ20*2)+(IK20*3)+(IL20*4) | IV20: =IG20+IO20+IQ20+IR20+IS20+IT20
Q21: =(E21-(F21+G21+H21))+(F21*2)+(G21*3)+(H21*4) | R21: =C21+K21+M21+N21+O21+P21 | AH21: =(V21-(W21+X21+Y21))+(W21*2)+(X21*3)+(Y21*4) | AI21: =T21+AB21+AD21+AE21+AF21+AG21 | AY21: =(AM21-(AN21+AO21+AP21))+(AN21*2)+(AO21*3)+(AP21*4) | AZ21: =AK21+AS21+AU21+AV21+AW21+AX21 | BP21: =(BD21-(BE21+BF21+BG21))+(BE21*2)+(BF21*3)+(BG21*4) | BQ21: =BB21+BJ21+BL21+BM21+BN21+BO21 | CG21: =(BU21-(BV21+BW21+BX21))+(BV21*2)+(BW21*3)+(BX21*4) | CH21: =BS21+CA21+CC21+CD21+CE21+CF21 | CX21: =(CL21-(CM21+CN21+CO21))+(CM21*2)+(CN21*3)+(CO21*4) | CY21: =CJ21+CR21+CT21+CU21+CV21+CW21 | DO21: =(DC21-(DD21+DE21+DF21))+(DD21*2)+(DE21*3)+(DF21*4) | DP21: =DA21+DI21+DK21+DL21+DM21+DN21 | EF21: =(DT21-(DU21+DV21+DW21))+(DU21*2)+(DV21*3)+(DW21*4) | EG21: =DR21+DZ21+EB21+EC21+ED21+EE21 | EW21: =(EK21-(EL21+EM21+EN21))+(EL21*2)+(EM21*3)+(EN21*4) | EX21: =EI21+EQ21+ES21+ET21+EU21+EV21 | FN21: =(FB21-(FC21+FD21+FE21))+(FC21*2)+(FD21*3)+(FE21*4) | FO21: =EZ21+FH21+FJ21+FK21+FL21+FM21 | GE21: =(FS21-(FT21+FU21+FV21))+(FT21*2)+(FU21*3)+(FV21*4) | GF21: =FQ21+FY21+GA21+GB21+GC21+GD21 | GV21: =(GJ21-(GK21+GL21+GM21))+(GK21*2)+(GL21*3)+(GM21*4) | GW21: =GH21+GP21+GR21+GS21+GT21+GU21 | HM21: =(HA21-(HB21+HC21+HD21))+(HB21*2)+(HC21*3)+(HD21*4) | HN21: =GY21+HG21+HI21+HJ21+HK21+HL21 | ID21: =(HR21-(HS21+HT21+HU21))+(HS21*2)+(HT21*3)+(HU21*4) | IE21: =HP21+HX21+HZ21+IA21+IB21+IC21 | IU21: =(II21-(IJ21+IK21+IL21))+(IJ21*2)+(IK21*3)+(IL21*4) | IV21: =IG21+IO21+IQ21+IR21+IS21+IT21
Q22: =(E22-(F22+G22+H22))+(F22*2)+(G22*3)+(H22*4) | R22: =C22+K22+M22+N22+O22+P22 | AH22: =(V22-(W22+X22+Y22))+(W22*2)+(X22*3)+(Y22*4) | AI22: =T22+AB22+AD22+AE22+AF22+AG22 | AY22: =(AM22-(AN22+AO22+AP22))+(AN22*2)+(AO22*3)+(AP22*4) | AZ22: =AK22+AS22+AU22+AV22+AW22+AX22 | BP22: =(BD22-(BE22+BF22+BG22))+(BE22*2)+(BF22*3)+(BG22*4) | BQ22: =BB22+BJ22+BL22+BM22+BN22+BO22 | CG22: =(BU22-(BV22+BW22+BX22))+(BV22*2)+(BW22*3)+(BX22*4) | CH22: =BS22+CA22+CC22+CD22+CE22+CF22 | CX22: =(CL22-(CM22+CN22+CO22))+(CM22*2)+(CN22*3)+(CO22*4) | CY22: =CJ22+CR22+CT22+CU22+CV22+CW22 | DO22: =(DC22-(DD22+DE22+DF22))+(DD22*2)+(DE22*3)+(DF22*4) | DP22: =DA22+DI22+DK22+DL22+DM22+DN22 | EF22: =(DT22-(DU22+DV22+DW22))+(DU22*2)+(DV22*3)+(DW22*4) | EG22: =DR22+DZ22+EB22+EC22+ED22+EE22 | EW22: =(EK22-(EL22+EM22+EN22))+(EL22*2)+(EM22*3)+(EN22*4) | EX22: =EI22+EQ22+ES22+ET22+EU22+EV22 | FN22: =(FB22-(FC22+FD22+FE22))+(FC22*2)+(FD22*3)+(FE22*4) | FO22: =EZ22+FH22+FJ22+FK22+FL22+FM22 | GE22: =(FS22-(FT22+FU22+FV22))+(FT22*2)+(FU22*3)+(FV22*4) | GF22: =FQ22+FY22+GA22+GB22+GC22+GD22 | GV22: =(GJ22-(GK22+GL22+GM22))+(GK22*2)+(GL22*3)+(GM22*4) | GW22: =GH22+GP22+GR22+GS22+GT22+GU22 | HM22: =(HA22-(HB22+HC22+HD22))+(HB22*2)+(HC22*3)+(HD22*4) | HN22: =GY22+HG22+HI22+HJ22+HK22+HL22 | ID22: =(HR22-(HS22+HT22+HU22))+(HS22*2)+(HT22*3)+(HU22*4) | IE22: =HP22+HX22+HZ22+IA22+IB22+IC22 | IU22: =(II22-(IJ22+IK22+IL22))+(IJ22*2)+(IK22*3)+(IL22*4) | IV22: =IG22+IO22+IQ22+IR22+IS22+IT22
Q23: =(E23-(F23+G23+H23))+(F23*2)+(G23*3)+(H23*4) | R23: =C23+K23+M23+N23+O23+P23 | AH23: =(V23-(W23+X23+Y23))+(W23*2)+(X23*3)+(Y23*4) | AI23: =T23+AB23+AD23+AE23+AF23+AG23 | AY23: =(AM23-(AN23+AO23+AP23))+(AN23*2)+(AO23*3)+(AP23*4) | AZ23: =AK23+AS23+AU23+AV23+AW23+AX23 | BP23: =(BD23-(BE23+BF23+BG23))+(BE23*2)+(BF23*3)+(BG23*4) | BQ23: =BB23+BJ23+BL23+BM23+BN23+BO23 | CG23: =(BU23-(BV23+BW23+BX23))+(BV23*2)+(BW23*3)+(BX23*4) | CH23: =BS23+CA23+CC23+CD23+CE23+CF23 | CX23: =(CL23-(CM23+CN23+CO23))+(CM23*2)+(CN23*3)+(CO23*4) | CY23: =CJ23+CR23+CT23+CU23+CV23+CW23 | DO23: =(DC23-(DD23+DE23+DF23))+(DD23*2)+(DE23*3)+(DF23*4) | DP23: =DA23+DI23+DK23+DL23+DM23+DN23 | EF23: =(DT23-(DU23+DV23+DW23))+(DU23*2)+(DV23*3)+(DW23*4) | EG23: =DR23+DZ23+EB23+EC23+ED23+EE23 | EW23: =(EK23-(EL23+EM23+EN23))+(EL23*2)+(EM23*3)+(EN23*4) | EX23: =EI23+EQ23+ES23+ET23+EU23+EV23 | FN23: =(FB23-(FC23+FD23+FE23))+(FC23*2)+(FD23*3)+(FE23*4) | FO23: =EZ23+FH23+FJ23+FK23+FL23+FM23 | GE23: =(FS23-(FT23+FU23+FV23))+(FT23*2)+(FU23*3)+(FV23*4) | GF23: =FQ23+FY23+GA23+GB23+GC23+GD23 | GV23: =(GJ23-(GK23+GL23+GM23))+(GK23*2)+(GL23*3)+(GM23*4) | GW23: =GH23+GP23+GR23+GS23+GT23+GU23 | HM23: =(HA23-(HB23+HC23+HD23))+(HB23*2)+(HC23*3)+(HD23*4) | HN23: =GY23+HG23+HI23+HJ23+HK23+HL23 | ID23: =(HR23-(HS23+HT23+HU23))+(HS23*2)+(HT23*3)+(HU23*4) | IE23: =HP23+HX23+HZ23+IA23+IB23+IC23 | IU23: =(II23-(IJ23+IK23+IL23))+(IJ23*2)+(IK23*3)+(IL23*4) | IV23: =IG23+IO23+IQ23+IR23+IS23+IT23
Q24: =(E24-(F24+G24+H24))+(F24*2)+(G24*3)+(H24*4) | R24: =C24+K24+M24+N24+O24+P24 | AH24: =(V24-(W24+X24+Y24))+(W24*2)+(X24*3)+(Y24*4) | AI24: =T24+AB24+AD24+AE24+AF24+AG24 | AY24: =(AM24-(AN24+AO24+AP24))+(AN24*2)+(AO24*3)+(AP24*4) | AZ24: =AK24+AS24+AU24+AV24+AW24+AX24 | BP24: =(BD24-(BE24+BF24+BG24))+(BE24*2)+(BF24*3)+(BG24*4) | BQ24: =BB24+BJ24+BL24+BM24+BN24+BO24 | CG24: =(BU24-(BV24+BW24+BX24))+(BV24*2)+(BW24*3)+(BX24*4) | CH24: =BS24+CA24+CC24+CD24+CE24+CF24 | CX24: =(CL24-(CM24+CN24+CO24))+(CM24*2)+(CN24*3)+(CO24*4) | CY24: =CJ24+CR24+CT24+CU24+CV24+CW24 | DO24: =(DC24-(DD24+DE24+DF24))+(DD24*2)+(DE24*3)+(DF24*4) | DP24: =DA24+DI24+DK24+DL24+DM24+DN24 | EF24: =(DT24-(DU24+DV24+DW24))+(DU24*2)+(DV24*3)+(DW24*4) | EG24: =DR24+DZ24+EB24+EC24+ED24+EE24 | EW24: =(EK24-(EL24+EM24+EN24))+(EL24*2)+(EM24*3)+(EN24*4) | EX24: =EI24+EQ24+ES24+ET24+EU24+EV24 | FN24: =(FB24-(FC24+FD24+FE24))+(FC24*2)+(FD24*3)+(FE24*4) | FO24: =EZ24+FH24+FJ24+FK24+FL24+FM24 | GE24: =(FS24-(FT24+FU24+FV24))+(FT24*2)+(FU24*3)+(FV24*4) | GF24: =FQ24+FY24+GA24+GB24+GC24+GD24 | GV24: =(GJ24-(GK24+GL24+GM24))+(GK24*2)+(GL24*3)+(GM24*4) | GW24: =GH24+GP24+GR24+GS24+GT24+GU24 | HM24: =(HA24-(HB24+HC24+HD24))+(HB24*2)+(HC24*3)+(HD24*4) | HN24: =GY24+HG24+HI24+HJ24+HK24+HL24 | ID24: =(HR24-(HS24+HT24+HU24))+(HS24*2)+(HT24*3)+(HU24*4) | IE24: =HP24+HX24+HZ24+IA24+IB24+IC24 | IU24: =(II24-(IJ24+IK24+IL24))+(IJ24*2)+(IK24*3)+(IL24*4) | IV24: =IG24+IO24+IQ24+IR24+IS24+IT24
Q25: =(E25-(F25+G25+H25))+(F25*2)+(G25*3)+(H25*4) | R25: =C25+K25+M25+N25+O25+P25 | AH25: =(V25-(W25+X25+Y25))+(W25*2)+(X25*3)+(Y25*4) | AI25: =T25+AB25+AD25+AE25+AF25+AG25 | AY25: =(AM25-(AN25+AO25+AP25))+(AN25*2)+(AO25*3)+(AP25*4) | AZ25: =AK25+AS25+AU25+AV25+AW25+AX25 | BP25: =(BD25-(BE25+BF25+BG25))+(BE25*2)+(BF25*3)+(BG25*4) | BQ25: =BB25+BJ25+BL25+BM25+BN25+BO25 | CG25: =(BU25-(BV25+BW25+BX25))+(BV25*2)+(BW25*3)+(BX25*4) | CH25: =BS25+CA25+CC25+CD25+CE25+CF25 | CX25: =(CL25-(CM25+CN25+CO25))+(CM25*2)+(CN25*3)+(CO25*4) | CY25: =CJ25+CR25+CT25+CU25+CV25+CW25 | DO25: =(DC25-(DD25+DE25+DF25))+(DD25*2)+(DE25*3)+(DF25*4) | DP25: =DA25+DI25+DK25+DL25+DM25+DN25 | EF25: =(DT25-(DU25+DV25+DW25))+(DU25*2)+(DV25*3)+(DW25*4) | EG25: =DR25+DZ25+EB25+EC25+ED25+EE25 | EW25: =(EK25-(EL25+EM25+EN25))+(EL25*2)+(EM25*3)+(EN25*4) | EX25: =EI25+EQ25+ES25+ET25+EU25+EV25 | FN25: =(FB25-(FC25+FD25+FE25))+(FC25*2)+(FD25*3)+(FE25*4) | FO25: =EZ25+FH25+FJ25+FK25+FL25+FM25 | GE25: =(FS25-(FT25+FU25+FV25))+(FT25*2)+(FU25*3)+(FV25*4) | GF25: =FQ25+FY25+GA25+GB25+GC25+GD25 | GV25: =(GJ25-(GK25+GL25+GM25))+(GK25*2)+(GL25*3)+(GM25*4) | GW25: =GH25+GP25+GR25+GS25+GT25+GU25 | HM25: =(HA25-(HB25+HC25+HD25))+(HB25*2)+(HC25*3)+(HD25*4) | HN25: =GY25+HG25+HI25+HJ25+HK25+HL25 | ID25: =(HR25-(HS25+HT25+HU25))+(HS25*2)+(HT25*3)+(HU25*4) | IE25: =HP25+HX25+HZ25+IA25+IB25+IC25 | IU25: =(II25-(IJ25+IK25+IL25))+(IJ25*2)+(IK25*3)+(IL25*4) | IV25: =IG25+IO25+IQ25+IR25+IS25+IT25
Q26: =(E26-(F26+G26+H26))+(F26*2)+(G26*3)+(H26*4) | R26: =C26+K26+M26+N26+O26+P26 | AH26: =(V26-(W26+X26+Y26))+(W26*2)+(X26*3)+(Y26*4) | AI26: =T26+AB26+AD26+AE26+AF26+AG26 | AY26: =(AM26-(AN26+AO26+AP26))+(AN26*2)+(AO26*3)+(AP26*4) | AZ26: =AK26+AS26+AU26+AV26+AW26+AX26 | BP26: =(BD26-(BE26+BF26+BG26))+(BE26*2)+(BF26*3)+(BG26*4) | BQ26: =BB26+BJ26+BL26+BM26+BN26+BO26 | CG26: =(BU26-(BV26+BW26+BX26))+(BV26*2)+(BW26*3)+(BX26*4) | CH26: =BS26+CA26+CC26+CD26+CE26+CF26 | CX26: =(CL26-(CM26+CN26+CO26))+(CM26*2)+(CN26*3)+(CO26*4) | CY26: =CJ26+CR26+CT26+CU26+CV26+CW26 | DO26: =(DC26-(DD26+DE26+DF26))+(DD26*2)+(DE26*3)+(DF26*4) | DP26: =DA26+DI26+DK26+DL26+DM26+DN26 | EF26: =(DT26-(DU26+DV26+DW26))+(DU26*2)+(DV26*3)+(DW26*4) | EG26: =DR26+DZ26+EB26+EC26+ED26+EE26 | EW26: =(EK26-(EL26+EM26+EN26))+(EL26*2)+(EM26*3)+(EN26*4) | EX26: =EI26+EQ26+ES26+ET26+EU26+EV26 | FN26: =(FB26-(FC26+FD26+FE26))+(FC26*2)+(FD26*3)+(FE26*4) | FO26: =EZ26+FH26+FJ26+FK26+FL26+FM26 | GE26: =(FS26-(FT26+FU26+FV26))+(FT26*2)+(FU26*3)+(FV26*4) | GF26: =FQ26+FY26+GA26+GB26+GC26+GD26 | GV26: =(GJ26-(GK26+GL26+GM26))+(GK26*2)+(GL26*3)+(GM26*4) | GW26: =GH26+GP26+GR26+GS26+GT26+GU26 | HM26: =(HA26-(HB26+HC26+HD26))+(HB26*2)+(HC26*3)+(HD26*4) | HN26: =GY26+HG26+HI26+HJ26+HK26+HL26 | ID26: =(HR26-(HS26+HT26+HU26))+(HS26*2)+(HT26*3)+(HU26*4) | IE26: =HP26+HX26+HZ26+IA26+IB26+IC26 | IU26: =(II26-(IJ26+IK26+IL26))+(IJ26*2)+(IK26*3)+(IL26*4) | IV26: =IG26+IO26+IQ26+IR26+IS26+IT26
Q27: =(E27-(F27+G27+H27))+(F27*2)+(G27*3)+(H27*4) | R27: =C27+K27+M27+N27+O27+P27 | AH27: =(V27-(W27+X27+Y27))+(W27*2)+(X27*3)+(Y27*4) | AI27: =T27+AB27+AD27+AE27+AF27+AG27 | AY27: =(AM27-(AN27+AO27+AP27))+(AN27*2)+(AO27*3)+(AP27*4) | AZ27: =AK27+AS27+AU27+AV27+AW27+AX27 | BP27: =(BD27-(BE27+BF27+BG27))+(BE27*2)+(BF27*3)+(BG27*4) | BQ27: =BB27+BJ27+BL27+BM27+BN27+BO27 | CG27: =(BU27-(BV27+BW27+BX27))+(BV27*2)+(BW27*3)+(BX27*4) | CH27: =BS27+CA27+CC27+CD27+CE27+CF27 | CX27: =(CL27-(CM27+CN27+CO27))+(CM27*2)+(CN27*3)+(CO27*4) | CY27: =CJ27+CR27+CT27+CU27+CV27+CW27 | DO27: =(DC27-(DD27+DE27+DF27))+(DD27*2)+(DE27*3)+(DF27*4) | DP27: =DA27+DI27+DK27+DL27+DM27+DN27 | EF27: =(DT27-(DU27+DV27+DW27))+(DU27*2)+(DV27*3)+(DW27*4) | EG27: =DR27+DZ27+EB27+EC27+ED27+EE27 | EW27: =(EK27-(EL27+EM27+EN27))+(EL27*2)+(EM27*3)+(EN27*4) | EX27: =EI27+EQ27+ES27+ET27+EU27+EV27 | FN27: =(FB27-(FC27+FD27+FE27))+(FC27*2)+(FD27*3)+(FE27*4) | FO27: =EZ27+FH27+FJ27+FK27+FL27+FM27 | GE27: =(FS27-(FT27+FU27+FV27))+(FT27*2)+(FU27*3)+(FV27*4) | GF27: =FQ27+FY27+GA27+GB27+GC27+GD27 | GV27: =(GJ27-(GK27+GL27+GM27))+(GK27*2)+(GL27*3)+(GM27*4) | GW27: =GH27+GP27+GR27+GS27+GT27+GU27 | HM27: =(HA27-(HB27+HC27+HD27))+(HB27*2)+(HC27*3)+(HD27*4) | HN27: =GY27+HG27+HI27+HJ27+HK27+HL27 | ID27: =(HR27-(HS27+HT27+HU27))+(HS27*2)+(HT27*3)+(HU27*4) | IE27: =HP27+HX27+HZ27+IA27+IB27+IC27 | IU27: =(II27-(IJ27+IK27+IL27))+(IJ27*2)+(IK27*3)+(IL27*4) | IV27: =IG27+IO27+IQ27+IR27+IS27+IT27
Q28: =(E28-(F28+G28+H28))+(F28*2)+(G28*3)+(H28*4) | R28: =C28+K28+M28+N28+O28+P28 | AH28: =(V28-(W28+X28+Y28))+(W28*2)+(X28*3)+(Y28*4) | AI28: =T28+AB28+AD28+AE28+AF28+AG28 | AY28: =(AM28-(AN28+AO28+AP28))+(AN28*2)+(AO28*3)+(AP28*4) | AZ28: =AK28+AS28+AU28+AV28+AW28+AX28 | BP28: =(BD28-(BE28+BF28+BG28))+(BE28*2)+(BF28*3)+(BG28*4) | BQ28: =BB28+BJ28+BL28+BM28+BN28+BO28 | CG28: =(BU28-(BV28+BW28+BX28))+(BV28*2)+(BW28*3)+(BX28*4) | CH28: =BS28+CA28+CC28+CD28+CE28+CF28 | CX28: =(CL28-(CM28+CN28+CO28))+(CM28*2)+(CN28*3)+(CO28*4) | CY28: =CJ28+CR28+CT28+CU28+CV28+CW28 | DO28: =(DC28-(DD28+DE28+DF28))+(DD28*2)+(DE28*3)+(DF28*4) | DP28: =DA28+DI28+DK28+DL28+DM28+DN28 | EF28: =(DT28-(DU28+DV28+DW28))+(DU28*2)+(DV28*3)+(DW28*4) | EG28: =DR28+DZ28+EB28+EC28+ED28+EE28 | EW28: =(EK28-(EL28+EM28+EN28))+(EL28*2)+(EM28*3)+(EN28*4) | EX28: =EI28+EQ28+ES28+ET28+EU28+EV28 | FN28: =(FB28-(FC28+FD28+FE28))+(FC28*2)+(FD28*3)+(FE28*4) | FO28: =EZ28+FH28+FJ28+FK28+FL28+FM28 | GE28: =(FS28-(FT28+FU28+FV28))+(FT28*2)+(FU28*3)+(FV28*4) | GF28: =FQ28+FY28+GA28+GB28+GC28+GD28 | GV28: =(GJ28-(GK28+GL28+GM28))+(GK28*2)+(GL28*3)+(GM28*4) | GW28: =GH28+GP28+GR28+GS28+GT28+GU28 | HM28: =(HA28-(HB28+HC28+HD28))+(HB28*2)+(HC28*3)+(HD28*4) | HN28: =GY28+HG28+HI28+HJ28+HK28+HL28 | ID28: =(HR28-(HS28+HT28+HU28))+(HS28*2)+(HT28*3)+(HU28*4) | IE28: =HP28+HX28+HZ28+IA28+IB28+IC28 | IU28: =(II28-(IJ28+IK28+IL28))+(IJ28*2)+(IK28*3)+(IL28*4) | IV28: =IG28+IO28+IQ28+IR28+IS28+IT28
Q29: =(E29-(F29+G29+H29))+(F29*2)+(G29*3)+(H29*4) | R29: =C29+K29+M29+N29+O29+P29 | AH29: =(V29-(W29+X29+Y29))+(W29*2)+(X29*3)+(Y29*4) | AI29: =T29+AB29+AD29+AE29+AF29+AG29 | AY29: =(AM29-(AN29+AO29+AP29))+(AN29*2)+(AO29*3)+(AP29*4) | AZ29: =AK29+AS29+AU29+AV29+AW29+AX29 | BP29: =(BD29-(BE29+BF29+BG29))+(BE29*2)+(BF29*3)+(BG29*4) | BQ29: =BB29+BJ29+BL29+BM29+BN29+BO29 | CG29: =(BU29-(BV29+BW29+BX29))+(BV29*2)+(BW29*3)+(BX29*4) | CH29: =BS29+CA29+CC29+CD29+CE29+CF29 | CX29: =(CL29-(CM29+CN29+CO29))+(CM29*2)+(CN29*3)+(CO29*4) | CY29: =CJ29+CR29+CT29+CU29+CV29+CW29 | DO29: =(DC29-(DD29+DE29+DF29))+(DD29*2)+(DE29*3)+(DF29*4) | DP29: =DA29+DI29+DK29+DL29+DM29+DN29 | EF29: =(DT29-(DU29+DV29+DW29))+(DU29*2)+(DV29*3)+(DW29*4) | EG29: =DR29+DZ29+EB29+EC29+ED29+EE29 | EW29: =(EK29-(EL29+EM29+EN29))+(EL29*2)+(EM29*3)+(EN29*4) | EX29: =EI29+EQ29+ES29+ET29+EU29+EV29 | FN29: =(FB29-(FC29+FD29+FE29))+(FC29*2)+(FD29*3)+(FE29*4) | FO29: =EZ29+FH29+FJ29+FK29+FL29+FM29 | GE29: =(FS29-(FT29+FU29+FV29))+(FT29*2)+(FU29*3)+(FV29*4) | GF29: =FQ29+FY29+GA29+GB29+GC29+GD29 | GV29: =(GJ29-(GK29+GL29+GM29))+(GK29*2)+(GL29*3)+(GM29*4) | GW29: =GH29+GP29+GR29+GS29+GT29+GU29 | HM29: =(HA29-(HB29+HC29+HD29))+(HB29*2)+(HC29*3)+(HD29*4) | HN29: =GY29+HG29+HI29+HJ29+HK29+HL29 | ID29: =(HR29-(HS29+HT29+HU29))+(HS29*2)+(HT29*3)+(HU29*4) | IE29: =HP29+HX29+HZ29+IA29+IB29+IC29 | IU29: =(II29-(IJ29+IK29+IL29))+(IJ29*2)+(IK29*3)+(IL29*4) | IV29: =IG29+IO29+IQ29+IR29+IS29+IT29
Q30: =(E30-(F30+G30+H30))+(F30*2)+(G30*3)+(H30*4) | R30: =C30+K30+M30+N30+O30+P30 | AH30: =(V30-(W30+X30+Y30))+(W30*2)+(X30*3)+(Y30*4) | AI30: =T30+AB30+AD30+AE30+AF30+AG30 | AY30: =(AM30-(AN30+AO30+AP30))+(AN30*2)+(AO30*3)+(AP30*4) | AZ30: =AK30+AS30+AU30+AV30+AW30+AX30 | BP30: =(BD30-(BE30+BF30+BG30))+(BE30*2)+(BF30*3)+(BG30*4) | BQ30: =BB30+BJ30+BL30+BM30+BN30+BO30 | CG30: =(BU30-(BV30+BW30+BX30))+(BV30*2)+(BW30*3)+(BX30*4) | CH30: =BS30+CA30+CC30+CD30+CE30+CF30 | CX30: =(CL30-(CM30+CN30+CO30))+(CM30*2)+(CN30*3)+(CO30*4) | CY30: =CJ30+CR30+CT30+CU30+CV30+CW30 | DO30: =(DC30-(DD30+DE30+DF30))+(DD30*2)+(DE30*3)+(DF30*4) | DP30: =DA30+DI30+DK30+DL30+DM30+DN30 | EF30: =(DT30-(DU30+DV30+DW30))+(DU30*2)+(DV30*3)+(DW30*4) | EG30: =DR30+DZ30+EB30+EC30+ED30+EE30 | EW30: =(EK30-(EL30+EM30+EN30))+(EL30*2)+(EM30*3)+(EN30*4) | EX30: =EI30+EQ30+ES30+ET30+EU30+EV30 | FN30: =(FB30-(FC30+FD30+FE30))+(FC30*2)+(FD30*3)+(FE30*4) | FO30: =EZ30+FH30+FJ30+FK30+FL30+FM30 | GE30: =(FS30-(FT30+FU30+FV30))+(FT30*2)+(FU30*3)+(FV30*4) | GF30: =FQ30+FY30+GA30+GB30+GC30+GD30 | GV30: =(GJ30-(GK30+GL30+GM30))+(GK30*2)+(GL30*3)+(GM30*4) | GW30: =GH30+GP30+GR30+GS30+GT30+GU30 | HM30: =(HA30-(HB30+HC30+HD30))+(HB30*2)+(HC30*3)+(HD30*4) | HN30: =GY30+HG30+HI30+HJ30+HK30+HL30 | ID30: =(HR30-(HS30+HT30+HU30))+(HS30*2)+(HT30*3)+(HU30*4) | IE30: =HP30+HX30+HZ30+IA30+IB30+IC30 | IU30: =(II30-(IJ30+IK30+IL30))+(IJ30*2)+(IK30*3)+(IL30*4) | IV30: =IG30+IO30+IQ30+IR30+IS30+IT30
Q31: =(E31-(F31+G31+H31))+(F31*2)+(G31*3)+(H31*4) | R31: =C31+K31+M31+N31+O31+P31 | AH31: =(V31-(W31+X31+Y31))+(W31*2)+(X31*3)+(Y31*4) | AI31: =T31+AB31+AD31+AE31+AF31+AG31 | AY31: =(AM31-(AN31+AO31+AP31))+(AN31*2)+(AO31*3)+(AP31*4) | AZ31: =AK31+AS31+AU31+AV31+AW31+AX31 | BP31: =(BD31-(BE31+BF31+BG31))+(BE31*2)+(BF31*3)+(BG31*4) | BQ31: =BB31+BJ31+BL31+BM31+BN31+BO31 | CG31: =(BU31-(BV31+BW31+BX31))+(BV31*2)+(BW31*3)+(BX31*4) | CH31: =BS31+CA31+CC31+CD31+CE31+CF31 | CX31: =(CL31-(CM31+CN31+CO31))+(CM31*2)+(CN31*3)+(CO31*4) | CY31: =CJ31+CR31+CT31+CU31+CV31+CW31 | DO31: =(DC31-(DD31+DE31+DF31))+(DD31*2)+(DE31*3)+(DF31*4) | DP31: =DA31+DI31+DK31+DL31+DM31+DN31 | EF31: =(DT31-(DU31+DV31+DW31))+(DU31*2)+(DV31*3)+(DW31*4) | EG31: =DR31+DZ31+EB31+EC31+ED31+EE31 | EW31: =(EK31-(EL31+EM31+EN31))+(EL31*2)+(EM31*3)+(EN31*4) | EX31: =EI31+EQ31+ES31+ET31+EU31+EV31 | FN31: =(FB31-(FC31+FD31+FE31))+(FC31*2)+(FD31*3)+(FE31*4) | FO31: =EZ31+FH31+FJ31+FK31+FL31+FM31 | GE31: =(FS31-(FT31+FU31+FV31))+(FT31*2)+(FU31*3)+(FV31*4) | GF31: =FQ31+FY31+GA31+GB31+GC31+GD31 | GV31: =(GJ31-(GK31+GL31+GM31))+(GK31*2)+(GL31*3)+(GM31*4) | GW31: =GH31+GP31+GR31+GS31+GT31+GU31 | HM31: =(HA31-(HB31+HC31+HD31))+(HB31*2)+(HC31*3)+(HD31*4) | HN31: =GY31+HG31+HI31+HJ31+HK31+HL31 | ID31: =(HR31-(HS31+HT31+HU31))+(HS31*2)+(HT31*3)+(HU31*4) | IE31: =HP31+HX31+HZ31+IA31+IB31+IC31 | IU31: =(II31-(IJ31+IK31+IL31))+(IJ31*2)+(IK31*3)+(IL31*4) | IV31: =IG31+IO31+IQ31+IR31+IS31+IT31
Q32: =(E32-(F32+G32+H32))+(F32*2)+(G32*3)+(H32*4) | R32: =C32+K32+M32+N32+O32+P32 | AH32: =(V32-(W32+X32+Y32))+(W32*2)+(X32*3)+(Y32*4) | AI32: =T32+AB32+AD32+AE32+AF32+AG32 | AY32: =(AM32-(AN32+AO32+AP32))+(AN32*2)+(AO32*3)+(AP32*4) | AZ32: =AK32+AS32+AU32+AV32+AW32+AX32 | BP32: =(BD32-(BE32+BF32+BG32))+(BE32*2)+(BF32*3)+(BG32*4) | BQ32: =BB32+BJ32+BL32+BM32+BN32+BO32 | CG32: =(BU32-(BV32+BW32+BX32))+(BV32*2)+(BW32*3)+(BX32*4) | CH32: =BS32+CA32+CC32+CD32+CE32+CF32 | CX32: =(CL32-(CM32+CN32+CO32))+(CM32*2)+(CN32*3)+(CO32*4) | CY32: =CJ32+CR32+CT32+CU32+CV32+CW32 | DO32: =(DC32-(DD32+DE32+DF32))+(DD32*2)+(DE32*3)+(DF32*4) | DP32: =DA32+DI32+DK32+DL32+DM32+DN32 | EF32: =(DT32-(DU32+DV32+DW32))+(DU32*2)+(DV32*3)+(DW32*4) | EG32: =DR32+DZ32+EB32+EC32+ED32+EE32 | EW32: =(EK32-(EL32+EM32+EN32))+(EL32*2)+(EM32*3)+(EN32*4) | EX32: =EI32+EQ32+ES32+ET32+EU32+EV32 | FN32: =(FB32-(FC32+FD32+FE32))+(FC32*2)+(FD32*3)+(FE32*4) | FO32: =EZ32+FH32+FJ32+FK32+FL32+FM32 | GE32: =(FS32-(FT32+FU32+FV32))+(FT32*2)+(FU32*3)+(FV32*4) | GF32: =FQ32+FY32+GA32+GB32+GC32+GD32 | GV32: =(GJ32-(GK32+GL32+GM32))+(GK32*2)+(GL32*3)+(GM32*4) | GW32: =GH32+GP32+GR32+GS32+GT32+GU32 | HM32: =(HA32-(HB32+HC32+HD32))+(HB32*2)+(HC32*3)+(HD32*4) | HN32: =GY32+HG32+HI32+HJ32+HK32+HL32 | ID32: =(HR32-(HS32+HT32+HU32))+(HS32*2)+(HT32*3)+(HU32*4) | IE32: =HP32+HX32+HZ32+IA32+IB32+IC32 | IU32: =(II32-(IJ32+IK32+IL32))+(IJ32*2)+(IK32*3)+(IL32*4) | IV32: =IG32+IO32+IQ32+IR32+IS32+IT32
A33: TOTALES : | C33: =SUM(C8:C32) | D33: =SUM(D8:D32) | E33: =SUM(E8:E32) | F33: =SUM(F8:F32) | G33: =SUM(G8:G32) | H33: =SUM(H8:H32) | I33: =SUM(I8:I32) | J33: =SUM(J8:J32) | ... R33: =SUM(R8:R32) | T33: =SUM(T8:T32) | U33: =SUM(U8:U32) | V33: =SUM(V8:V32) | W33: =SUM(W8:W32) | X33: =SUM(X8:X32) | Y33: =SUM(Y8:Y32) | Z33: =SUM(Z8:Z32) | AA33: =SUM(AA8:AA32) | ... AI33: =SUM(AI8:AI32) | AK33: =SUM(AK8:AK32) | AL33: =SUM(AL8:AL32) | AM33: =SUM(AM8:AM32) | AN33: =SUM(AN8:AN32) | AO33: =SUM(AO8:AO32) | AP33: =SUM(AP8:AP32) | AQ33: =SUM(AQ8:AQ32) | AR33: =SUM(AR8:AR32) | ... AZ33: =SUM(AZ8:AZ32) | BB33: =SUM(BB8:BB32) | BC33: =SUM(BC8:BC32) | BD33: =SUM(BD8:BD32) | BE33: =SUM(BE8:BE32) | BF33: =SUM(BF8:BF32) | BG33: =SUM(BG8:BG32) | BH33: =SUM(BH8:BH32) | BI33: =SUM(BI8:BI32) | ... BQ33: =SUM(BQ8:BQ32) | BS33: =SUM(BS8:BS32) | BT33: =SUM(BT8:BT32) | BU33: =SUM(BU8:BU32) | BV33: =SUM(BV8:BV32) | BW33: =SUM(BW8:BW32) | BX33: =SUM(BX8:BX32) | BY33: =SUM(BY8:BY32) | BZ33: =SUM(BZ8:BZ32) | ... CH33: =SUM(CH8:CH32) | CJ33: =SUM(CJ8:CJ32) | CK33: =SUM(CK8:CK32) | CL33: =SUM(CL8:CL32) | CM33: =SUM(CM8:CM32) | CN33: =SUM(CN8:CN32) | CO33: =SUM(CO8:CO32) | CP33: =SUM(CP8:CP32) | CQ33: =SUM(CQ8:CQ32) | ... CY33: =SUM(CY8:CY32) | DA33: =SUM(DA8:DA32) | DB33: =SUM(DB8:DB32) | DC33: =SUM(DC8:DC32) | DD33: =SUM(DD8:DD32) | DE33: =SUM(DE8:DE32) | DF33: =SUM(DF8:DF32) | DG33: =SUM(DG8:DG32) | DH33: =SUM(DH8:DH32) | ... DP33: =SUM(DP8:DP32) | DR33: =SUM(DR8:DR32) | DS33: =SUM(DS8:DS32) | DT33: =SUM(DT8:DT32) | DU33: =SUM(DU8:DU32) | DV33: =SUM(DV8:DV32) | DW33: =SUM(DW8:DW32) | DX33: =SUM(DX8:DX32) | DY33: =SUM(DY8:DY32) | ... EG33: =SUM(EG8:EG32) | EI33: =SUM(EI8:EI32) | EJ33: =SUM(EJ8:EJ32) | EK33: =SUM(EK8:EK32) | EL33: =SUM(EL8:EL32) | EM33: =SUM(EM8:EM32) | EN33: =SUM(EN8:EN32) | EO33: =SUM(EO8:EO32) | EP33: =SUM(EP8:EP32) | ... EX33: =SUM(EX8:EX32) | EZ33: =SUM(EZ8:EZ32) | FA33: =SUM(FA8:FA32) | FB33: =SUM(FB8:FB32) | FC33: =SUM(FC8:FC32) | FD33: =SUM(FD8:FD32) | FE33: =SUM(FE8:FE32) | FF33: =SUM(FF8:FF32) | FG33: =SUM(FG8:FG32) | ... FO33: =SUM(FO8:FO32) | FQ33: =SUM(FQ8:FQ32) | FR33: =SUM(FR8:FR32) | FS33: =SUM(FS8:FS32) | FT33: =SUM(FT8:FT32) | FU33: =SUM(FU8:FU32) | FV33: =SUM(FV8:FV32) | FW33: =SUM(FW8:FW32) | FX33: =SUM(FX8:FX32) | ... GF33: =SUM(GF8:GF32) | GH33: =SUM(GH8:GH32) | GI33: =SUM(GI8:GI32) | GJ33: =SUM(GJ8:GJ32) | GK33: =SUM(GK8:GK32) | GL33: =SUM(GL8:GL32) | GM33: =SUM(GM8:GM32) | GN33: =SUM(GN8:GN32) | GO33: =SUM(GO8:GO32) | ... GW33: =SUM(GW8:GW32) | GY33: =SUM(GY8:GY32) | GZ33: =SUM(GZ8:GZ32) | HA33: =SUM(HA8:HA32) | HB33: =SUM(HB8:HB32) | HC33: =SUM(HC8:HC32) | HD33: =SUM(HD8:HD32) | HE33: =SUM(HE8:HE32) | HF33: =SUM(HF8:HF32) | ... HN33: =SUM(HN8:HN32) | HP33: =SUM(HP8:HP32) | HQ33: =SUM(HQ8:HQ32) | HR33: =SUM(HR8:HR32) | HS33: =SUM(HS8:HS32) | HT33: =SUM(HT8:HT32) | HU33: =SUM(HU8:HU32) | HV33: =SUM(HV8:HV32) | HW33: =SUM(HW8:HW32) | ... IE33: =SUM(IE8:IE32) | IG33: =SUM(IG8:IG32) | IH33: =SUM(IH8:IH32) | II33: =SUM(II8:II32) | IJ33: =SUM(IJ8:IJ32) | IK33: =SUM(IK8:IK32) | IL33: =SUM(IL8:IL32) | IM33: =SUM(IM8:IM32) | IN33: =SUM(IN8:IN32) | ... IV33: =SUM(IV8:IV32)
A35: LIDERES INDIVIDUAL
A36: NOMBRE | B36: No | C36: VB | D36: CA | E36: H | F36: 2B | G36: 3B | H36: HR | I36: CI | J36: K | K36: BB | L36: BR | M36: GP | N36: SH | O36: SF | P36: INT | Q36: BAL | R36: AL | T36: AV | U36: SLG
A37: =IF(A8="","",A8) | B37: =IF(B8="","",B8) | C37: =C8+T8+AK8+BB8+BS8+CJ8+DA8+DR8+EI8+EZ8+FQ8+GH8+GY8+HP8+IG8 | D37: =D8+U8+AL8+BC8+BT8+CK8+DB8+DS8+EJ8+FA8+FR8+GI8+GZ8+HQ8+IH8 | E37: =E8+V8+AM8+BD8+BU8+CL8+DC8+DT8+EK8+FB8+FS8+GJ8+HA8+HR8+II8 | F37: =F8+W8+AN8+BE8+BV8+CM8+DD8+DU8+EL8+FC8+FT8+GK8+HB8+HS8+IJ8 | G37: =G8+X8+AO8+BF8+BW8+CN8+DE8+DV8+EM8+FD8+FU8+GL8+HC8+HT8+IK8 | H37: =H8+Y8+AP8+BG8+BX8+CO8+DF8+DW8+EN8+FE8+FV8+GM8+HD8+HU8+IL8 | I37: =I8+Z8+AQ8+BH8+BY8+CP8+DG8+DX8+EO8+FF8+FW8+GN8+HE8+HV8+IM8 | J37: =J8+AA8+AR8+BI8+BZ8+CQ8+DH8+DY8+EP8+FG8+FX8+GO8+HF8+HW8+IN8 | ... R37: =R8+AI8+AZ8+BQ8+CH8+CY8+DP8+EG8+EX8+FO8+GF8+GW8+HN8+IE8+IV8 | T37: =IFERROR(E37/C37,0) | U37: =IFERROR(Q37/C37,0)
A38: =IF(A9="","",A9) | B38: =IF(B9="","",B9) | C38: =C9+T9+AK9+BB9+BS9+CJ9+DA9+DR9+EI9+EZ9+FQ9+GH9+GY9+HP9+IG9 | D38: =D9+U9+AL9+BC9+BT9+CK9+DB9+DS9+EJ9+FA9+FR9+GI9+GZ9+HQ9+IH9 | E38: =E9+V9+AM9+BD9+BU9+CL9+DC9+DT9+EK9+FB9+FS9+GJ9+HA9+HR9+II9 | F38: =F9+W9+AN9+BE9+BV9+CM9+DD9+DU9+EL9+FC9+FT9+GK9+HB9+HS9+IJ9 | G38: =G9+X9+AO9+BF9+BW9+CN9+DE9+DV9+EM9+FD9+FU9+GL9+HC9+HT9+IK9 | H38: =H9+Y9+AP9+BG9+BX9+CO9+DF9+DW9+EN9+FE9+FV9+GM9+HD9+HU9+IL9 | I38: =I9+Z9+AQ9+BH9+BY9+CP9+DG9+DX9+EO9+FF9+FW9+GN9+HE9+HV9+IM9 | J38: =J9+AA9+AR9+BI9+BZ9+CQ9+DH9+DY9+EP9+FG9+FX9+GO9+HF9+HW9+IN9 | ... R38: =R9+AI9+AZ9+BQ9+CH9+CY9+DP9+EG9+EX9+FO9+GF9+GW9+HN9+IE9+IV9 | T38: =IFERROR(E38/C38,0) | U38: =IFERROR(Q38/C38,0)
A39: =IF(A10="","",A10) | B39: =IF(B10="","",B10) | C39: =C10+T10+AK10+BB10+BS10+CJ10+DA10+DR10+EI10+EZ10+FQ10+GH10+GY10+HP10+IG10 | D39: =D10+U10+AL10+BC10+BT10+CK10+DB10+DS10+EJ10+FA10+FR10+GI10+GZ10+HQ10+IH10 | E39: =E10+V10+AM10+BD10+BU10+CL10+DC10+DT10+EK10+FB10+FS10+GJ10+HA10+HR10+II10 | F39: =F10+W10+AN10+BE10+BV10+CM10+DD10+DU10+EL10+FC10+FT10+GK10+HB10+HS10+IJ10 | G39: =G10+X10+AO10+BF10+BW10+CN10+DE10+DV10+EM10+FD10+FU10+GL10+HC10+HT10+IK10 | H39: =H10+Y10+AP10+BG10+BX10+CO10+DF10+DW10+EN10+FE10+FV10+GM10+HD10+HU10+IL10 | I39: =I10+Z10+AQ10+BH10+BY10+CP10+DG10+DX10+EO10+FF10+FW10+GN10+HE10+HV10+IM10 | J39: =J10+AA10+AR10+BI10+BZ10+CQ10+DH10+DY10+EP10+FG10+FX10+GO10+HF10+HW10+IN10 | ... R39: =R10+AI10+AZ10+BQ10+CH10+CY10+DP10+EG10+EX10+FO10+GF10+GW10+HN10+IE10+IV10 | T39: =IFERROR(E39/C39,0) | U39: =IFERROR(Q39/C39,0)
A40: =IF(A11="","",A11) | B40: =IF(B11="","",B11) | C40: =C11+T11+AK11+BB11+BS11+CJ11+DA11+DR11+EI11+EZ11+FQ11+GH11+GY11+HP11+IG11 | D40: =D11+U11+AL11+BC11+BT11+CK11+DB11+DS11+EJ11+FA11+FR11+GI11+GZ11+HQ11+IH11 | E40: =E11+V11+AM11+BD11+BU11+CL11+DC11+DT11+EK11+FB11+FS11+GJ11+HA11+HR11+II11 | F40: =F11+W11+AN11+BE11+BV11+CM11+DD11+DU11+EL11+FC11+FT11+GK11+HB11+HS11+IJ11 | G40: =G11+X11+AO11+BF11+BW11+CN11+DE11+DV11+EM11+FD11+FU11+GL11+HC11+HT11+IK11 | H40: =H11+Y11+AP11+BG11+BX11+CO11+DF11+DW11+EN11+FE11+FV11+GM11+HD11+HU11+IL11 | I40: =I11+Z11+AQ11+BH11+BY11+CP11+DG11+DX11+EO11+FF11+FW11+GN11+HE11+HV11+IM11 | J40: =J11+AA11+AR11+BI11+BZ11+CQ11+DH11+DY11+EP11+FG11+FX11+GO11+HF11+HW11+IN11 | ... R40: =R11+AI11+AZ11+BQ11+CH11+CY11+DP11+EG11+EX11+FO11+GF11+GW11+HN11+IE11+IV11 | T40: =IFERROR(E40/C40,0) | U40: =IFERROR(Q40/C40,0)
A41: =IF(A12="","",A12) | B41: =IF(B12="","",B12) | C41: =C12+T12+AK12+BB12+BS12+CJ12+DA12+DR12+EI12+EZ12+FQ12+GH12+GY12+HP12+IG12 | D41: =D12+U12+AL12+BC12+BT12+CK12+DB12+DS12+EJ12+FA12+FR12+GI12+GZ12+HQ12+IH12 | E41: =E12+V12+AM12+BD12+BU12+CL12+DC12+DT12+EK12+FB12+FS12+GJ12+HA12+HR12+II12 | F41: =F12+W12+AN12+BE12+BV12+CM12+DD12+DU12+EL12+FC12+FT12+GK12+HB12+HS12+IJ12 | G41: =G12+X12+AO12+BF12+BW12+CN12+DE12+DV12+EM12+FD12+FU12+GL12+HC12+HT12+IK12 | H41: =H12+Y12+AP12+BG12+BX12+CO12+DF12+DW12+EN12+FE12+FV12+GM12+HD12+HU12+IL12 | I41: =I12+Z12+AQ12+BH12+BY12+CP12+DG12+DX12+EO12+FF12+FW12+GN12+HE12+HV12+IM12 | J41: =J12+AA12+AR12+BI12+BZ12+CQ12+DH12+DY12+EP12+FG12+FX12+GO12+HF12+HW12+IN12 | ... R41: =R12+AI12+AZ12+BQ12+CH12+CY12+DP12+EG12+EX12+FO12+GF12+GW12+HN12+IE12+IV12 | T41: =IFERROR(E41/C41,0) | U41: =IFERROR(Q41/C41,0)
A42: =IF(A13="","",A13) | B42: =IF(B13="","",B13) | C42: =C13+T13+AK13+BB13+BS13+CJ13+DA13+DR13+EI13+EZ13+FQ13+GH13+GY13+HP13+IG13 | D42: =D13+U13+AL13+BC13+BT13+CK13+DB13+DS13+EJ13+FA13+FR13+GI13+GZ13+HQ13+IH13 | E42: =E13+V13+AM13+BD13+BU13+CL13+DC13+DT13+EK13+FB13+FS13+GJ13+HA13+HR13+II13 | F42: =F13+W13+AN13+BE13+BV13+CM13+DD13+DU13+EL13+FC13+FT13+GK13+HB13+HS13+IJ13 | G42: =G13+X13+AO13+BF13+BW13+CN13+DE13+DV13+EM13+FD13+FU13+GL13+HC13+HT13+IK13 | H42: =H13+Y13+AP13+BG13+BX13+CO13+DF13+DW13+EN13+FE13+FV13+GM13+HD13+HU13+IL13 | I42: =I13+Z13+AQ13+BH13+BY13+CP13+DG13+DX13+EO13+FF13+FW13+GN13+HE13+HV13+IM13 | J42: =J13+AA13+AR13+BI13+BZ13+CQ13+DH13+DY13+EP13+FG13+FX13+GO13+HF13+HW13+IN13 | ... R42: =R13+AI13+AZ13+BQ13+CH13+CY13+DP13+EG13+EX13+FO13+GF13+GW13+HN13+IE13+IV13 | T42: =IFERROR(E42/C42,0) | U42: =IFERROR(Q42/C42,0)
A43: =IF(A14="","",A14) | B43: =IF(B14="","",B14) | C43: =C14+T14+AK14+BB14+BS14+CJ14+DA14+DR14+EI14+EZ14+FQ14+GH14+GY14+HP14+IG14 | D43: =D14+U14+AL14+BC14+BT14+CK14+DB14+DS14+EJ14+FA14+FR14+GI14+GZ14+HQ14+IH14 | E43: =E14+V14+AM14+BD14+BU14+CL14+DC14+DT14+EK14+FB14+FS14+GJ14+HA14+HR14+II14 | F43: =F14+W14+AN14+BE14+BV14+CM14+DD14+DU14+EL14+FC14+FT14+GK14+HB14+HS14+IJ14 | G43: =G14+X14+AO14+BF14+BW14+CN14+DE14+DV14+EM14+FD14+FU14+GL14+HC14+HT14+IK14 | H43: =H14+Y14+AP14+BG14+BX14+CO14+DF14+DW14+EN14+FE14+FV14+GM14+HD14+HU14+IL14 | I43: =I14+Z14+AQ14+BH14+BY14+CP14+DG14+DX14+EO14+FF14+FW14+GN14+HE14+HV14+IM14 | J43: =J14+AA14+AR14+BI14+BZ14+CQ14+DH14+DY14+EP14+FG14+FX14+GO14+HF14+HW14+IN14 | ... R43: =R14+AI14+AZ14+BQ14+CH14+CY14+DP14+EG14+EX14+FO14+GF14+GW14+HN14+IE14+IV14 | T43: =IFERROR(E43/C43,0) | U43: =IFERROR(Q43/C43,0)
...

Sheet equipo2
A1: CORPORACION CRIOLLITOS DE VENEZUELA
A2: LIGA DE BEISBOL MENOR JUAN GUILLERMO GUZMAN
B4: CATEGORIA : INFANTIL
A6: equipo2 | C6: O F E N S I V A I N D I V I D U A L
A7: NOMBRE | B7: No | C7: VB | D7: CA | E7: H | F7: 2B | G7: 3B | H7: HR | I7: CI | J7: K | K7: BB | L7: BR | M7: GP | N7: SH | O7: SF | P7: INT | Q7: BAL | R7: AL | T7: VB | U7: CA | V7: H | W7: 2B | X7: 3B | Y7: HR | Z7: CI | AA7: K | AB7: BB | AC7: BR | AD7: GP | AE7: SH | AF7: SF | AG7: INT | AH7: BAL | AI7: AL | AK7: VB | AL7: CA | AM7: H | AN7: 2B | AO7: 3B | AP7: HR | AQ7: CI | AR7: K | AS7: BB | AT7: BR | AU7: GP | AV7: SH | AW7: SF | AX7: INT | AY7: BAL | AZ7: AL | BB7: VB | BC7: CA | BD7: H | BE7: 2B | BF7: 3B | BG7: HR | BH7: CI | BI7: K | BJ7: BB | BK7: BR | BL7: GP | BM7: SH | BN7: SF | BO7: INT | BP7: BAL | BQ7: AL | BS7: VB | BT7: CA | BU7: H | BV7: 2B | BW7: 3B | BX7: HR | BY7: CI | BZ7: K | CA7: BB | CB7: BR | CC7: GP | CD7: SH | CE7: SF | CF7: INT | CG7: BAL | CH7: AL | CJ7: VB | CK7: CA | CL7: H | CM7: 2B | CN7: 3B | CO7: HR | CP7: CI | CQ7: K | CR7: BB | CS7: BR | CT7: GP | CU7: SH | CV7: SF | CW7: INT | CX7: BAL | CY7: AL | DA7: VB | DB7: CA | DC7: H | DD7: 2B | DE7: 3B | DF7: HR | DG7: CI | DH7: K | DI7: BB | DJ7: BR | DK7: GP | DL7: SH | DM7: SF | DN7: INT | DO7: BAL | DP7: AL | DR7: VB | DS7: CA | DT7: H | DU7: 2B | DV7: 3B | DW7: HR | DX7: CI | DY7: K | DZ7: BB | EA7: BR | EB7: GP | EC7: SH | ED7: SF | EE7: INT | EF7: BAL | EG7: AL | EI7: VB | EJ7: CA | EK7: H | EL7: 2B | EM7: 3B | EN7: HR | EO7: CI | EP7: K | EQ7: BB | ER7: BR | ES7: GP | ET7: SH | EU7: SF | EV7: INT | EW7: BAL | EX7: AL | EZ7: VB | FA7: CA | FB7: H | FC7: 2B | FD7: 3B | FE7: HR | FF7: CI | FG7: K | FH7: BB | FI7: BR | FJ7: GP | FK7: SH | FL7: SF | FM7: INT | FN7: BAL | FO7: AL | FQ7: VB | FR7: CA | FS7: H | FT7: 2B | FU7: 3B | FV7: HR | FW7: CI | FX7: K | FY7: BB | FZ7: BR | GA7: GP | GB7: SH | GC7: SF | GD7: INT | GE7: BAL | GF7: AL | GH7: VB | GI7: CA | GJ7: H | GK7: 2B | GL7: 3B | GM7: HR | GN7: CI | GO7: K | GP7: BB | GQ7: BR | GR7: GP | GS7: SH | GT7: SF | GU7: INT | GV7: BAL | GW7: AL | GY7: VB | GZ7: CA | HA7: H | HB7: 2B | HC7: 3B | HD7: HR | HE7: CI | HF7: K | HG7: BB | HH7: BR | HI7: GP | HJ7: SH | HK7: SF | HL7: INT | HM7: BAL | HN7: AL | HP7: VB | HQ7: CA | HR7: H | HS7: 2B | HT7: 3B | HU7: HR | HV7: CI | HW7: K | HX7: BB | HY7: BR | HZ7: GP | IA7: SH | IB7: SF | IC7: INT | ID7: BAL | IE7: AL | IG7: VB | IH7: CA | II7: H | IJ7: 2B | IK7: 3B | IL7: HR | IM7: CI | IN7: K | IO7: BB | IP7: BR | IQ7: GP | IR7: SH | IS7: SF | IT7: INT | IU7: BAL | IV7: AL
A8: JESUS PAEZ EQUIPO 2 | B8: 13 | C8: 4 | D8: 2 | E8: 1 | L8: 1 | Q8: =(E8-(F8+G8+H8))+(F8*2)+(G8*3)+(H8*4) | R8: =C8+K8+M8+N8+O8+P8 | AH8: =(V8-(W8+X8+Y8))+(W8*2)+(X8*3)+(Y8*4) | AI8: =T8+AB8+AD8+AE8+AF8+AG8 | AY8: =(AM8-(AN8+AO8+AP8))+(AN8*2)+(AO8*3)+(AP8*4) | AZ8: =AK8+AS8+AU8+AV8+AW8+AX8 | BP8: =(BD8-(BE8+BF8+BG8))+(BE8*2)+(BF8*3)+(BG8*4) | BQ8: =BB8+BJ8+BL8+BM8+BN8+BO8 | CG8: =(BU8-(BV8+BW8+BX8))+(BV8*2)+(BW8*3)+(BX8*4) | CH8: =BS8+CA8+CC8+CD8+CE8+CF8 | CX8: =(CL8-(CM8+CN8+CO8))+(CM8*2)+(CN8*3)+(CO8*4) | CY8: =CJ8+CR8+CT8+CU8+CV8+CW8 | DO8: =(DC8-(DD8+DE8+DF8))+(DD8*2)+(DE8*3)+(DF8*4) | DP8: =DA8+DI8+DK8+DL8+DM8+DN8 | EF8: =(DT8-(DU8+DV8+DW8))+(DU8*2)+(DV8*3)+(DW8*4) | EG8: =DR8+DZ8+EB8+EC8+ED8+EE8 | EW8: =(EK8-(EL8+EM8+EN8))+(EL8*2)+(EM8*3)+(EN8*4) | EX8: =EI8+EQ8+ES8+ET8+EU8+EV8 | FN8: =(FB8-(FC8+FD8+FE8))+(FC8*2)+(FD8*3)+(FE8*4) | FO8: =EZ8+FH8+FJ8+FK8+FL8+FM8 | GE8: =(FS8-(FT8+FU8+FV8))+(FT8*2)+(FU8*3)+(FV8*4) | GF8: =FQ8+FY8+GA8+GB8+GC8+GD8 | GV8: =(GJ8-(GK8+GL8+GM8))+(GK8*2)+(GL8*3)+(GM8*4) | GW8: =GH8+GP8+GR8+GS8+GT8+GU8 | HM8: =(HA8-(HB8+HC8+HD8))+(HB8*2)+(HC8*3)+(HD8*4) | HN8: =GY8+HG8+HI8+HJ8+HK8+HL8 | ID8: =(HR8-(HS8+HT8+HU8))+(HS8*2)+(HT8*3)+(HU8*4) | IE8: =HP8+HX8+HZ8+IA8+IB8+IC8 | IU8: =(II8-(IJ8+IK8+IL8))+(IJ8*2)+(IK8*3)+(IL8*4) | IV8: =IG8+IO8+IQ8+IR8+IS8+IT8
A9: JOSEPH MENDOZA | B9: 28 | C9: 3 | D9: 1 | E9: 1 | F9: 1 | K9: 1 | Q9: =(E9-(F9+G9+H9))+(F9*2)+(G9*3)+(H9*4) | R9: =C9+K9+M9+N9+O9+P9 | AH9: =(V9-(W9+X9+Y9))+(W9*2)+(X9*3)+(Y9*4) | AI9: =T9+AB9+AD9+AE9+AF9+AG9 | AY9: =(AM9-(AN9+AO9+AP9))+(AN9*2)+(AO9*3)+(AP9*4) | AZ9: =AK9+AS9+AU9+AV9+AW9+AX9 | BP9: =(BD9-(BE9+BF9+BG9))+(BE9*2)+(BF9*3)+(BG9*4) | BQ9: =BB9+BJ9+BL9+BM9+BN9+BO9 | CG9: =(BU9-(BV9+BW9+BX9))+(BV9*2)+(BW9*3)+(BX9*4) | CH9: =BS9+CA9+CC9+CD9+CE9+CF9 | CX9: =(CL9-(CM9+CN9+CO9))+(CM9*2)+(CN9*3)+(CO9*4) | CY9: =CJ9+CR9+CT9+CU9+CV9+CW9 | DO9: =(DC9-(DD9+DE9+DF9))+(DD9*2)+(DE9*3)+(DF9*4) | DP9: =DA9+DI9+DK9+DL9+DM9+DN9 | EF9: =(DT9-(DU9+DV9+DW9))+(DU9*2)+(DV9*3)+(DW9*4) | EG9: =DR9+DZ9+EB9+EC9+ED9+EE9 | EW9: =(EK9-(EL9+EM9+EN9))+(EL9*2)+(EM9*3)+(EN9*4) | EX9: =EI9+EQ9+ES9+ET9+EU9+EV9 | FN9: =(FB9-(FC9+FD9+FE9))+(FC9*2)+(FD9*3)+(FE9*4) | FO9: =EZ9+FH9+FJ9+FK9+FL9+FM9 | GE9: =(FS9-(FT9+FU9+FV9))+(FT9*2)+(FU9*3)+(FV9*4) | GF9: =FQ9+FY9+GA9+GB9+GC9+GD9 | GV9: =(GJ9-(GK9+GL9+GM9))+(GK9*2)+(GL9*3)+(GM9*4) | GW9: =GH9+GP9+GR9+GS9+GT9+GU9 | HM9: =(HA9-(HB9+HC9+HD9))+(HB9*2)+(HC9*3)+(HD9*4) | HN9: =GY9+HG9+HI9+HJ9+HK9+HL9 | ID9: =(HR9-(HS9+HT9+HU9))+(HS9*2)+(HT9*3)+(HU9*4) | IE9: =HP9+HX9+HZ9+IA9+IB9+IC9 | IU9: =(II9-(IJ9+IK9+IL9))+(IJ9*2)+(IK9*3)+(IL9*4) | IV9: =IG9+IO9+IQ9+IR9+IS9+IT9
A10: ABRAHAN RODRIGUZ | C10: 4 | E10: 1 | Q10: =(E10-(F10+G10+H10))+(F10*2)+(G10*3)+(H10*4) | R10: =C10+K10+M10+N10+O10+P10 | AH10: =(V10-(W10+X10+Y10))+(W10*2)+(X10*3)+(Y10*4) | AI10: =T10+AB10+AD10+AE10+AF10+AG10 | AY10: =(AM10-(AN10+AO10+AP10))+(AN10*2)+(AO10*3)+(AP10*4) | AZ10: =AK10+AS10+AU10+AV10+AW10+AX10 | BP10: =(BD10-(BE10+BF10+BG10))+(BE10*2)+(BF10*3)+(BG10*4) | BQ10: =BB10+BJ10+BL10+BM10+BN10+BO10 | CG10: =(BU10-(BV10+BW10+BX10))+(BV10*2)+(BW10*3)+(BX10*4) | CH10: =BS10+CA10+CC10+CD10+CE10+CF10 | CX10: =(CL10-(CM10+CN10+CO10))+(CM10*2)+(CN10*3)+(CO10*4) | CY10: =CJ10+CR10+CT10+CU10+CV10+CW10 | DO10: =(DC10-(DD10+DE10+DF10))+(DD10*2)+(DE10*3)+(DF10*4) | DP10: =DA10+DI10+DK10+DL10+DM10+DN10 | EF10: =(DT10-(DU10+DV10+DW10))+(DU10*2)+(DV10*3)+(DW10*4) | EG10: =DR10+DZ10+EB10+EC10+ED10+EE10 | EW10: =(EK10-(EL10+EM10+EN10))+(EL10*2)+(EM10*3)+(EN10*4) | EX10: =EI10+EQ10+ES10+ET10+EU10+EV10 | FN10: =(FB10-(FC10+FD10+FE10))+(FC10*2)+(FD10*3)+(FE10*4) | FO10: =EZ10+FH10+FJ10+FK10+FL10+FM10 | GE10: =(FS10-(FT10+FU10+FV10))+(FT10*2)+(FU10*3)+(FV10*4) | GF10: =FQ10+FY10+GA10+GB10+GC10+GD10 | GV10: =(GJ10-(GK10+GL10+GM10))+(GK10*2)+(GL10*3)+(GM10*4) | GW10: =GH10+GP10+GR10+GS10+GT10+GU10 | HM10: =(HA10-(HB10+HC10+HD10))+(HB10*2)+(HC10*3)+(HD10*4) | HN10: =GY10+HG10+HI10+HJ10+HK10+HL10 | ID10: =(HR10-(HS10+HT10+HU10))+(HS10*2)+(HT10*3)+(HU10*4) | IE10: =HP10+HX10+HZ10+IA10+IB10+IC10 | IU10: =(II10-(IJ10+IK10+IL10))+(IJ10*2)+(IK10*3)+(IL10*4) | IV10: =IG10+IO10+IQ10+IR10+IS10+IT10
A11: ALEXANDER HERNANDEZ | D11: 1 | I11: 1 | K11: 3 | L11: 3 | Q11: =(E11-(F11+G11+H11))+(F11*2)+(G11*3)+(H11*4) | R11: =C11+K11+M11+N11+O11+P11 | AH11: =(V11-(W11+X11+Y11))+(W11*2)+(X11*3)+(Y11*4) | AI11: =T11+AB11+AD11+AE11+AF11+AG11 | AY11: =(AM11-(AN11+AO11+AP11))+(AN11*2)+(AO11*3)+(AP11*4) | AZ11: =AK11+AS11+AU11+AV11+AW11+AX11 | BP11: =(BD11-(BE11+BF11+BG11))+(BE11*2)+(BF11*3)+(BG11*4) | BQ11: =BB11+BJ11+BL11+BM11+BN11+BO11 | CG11: =(BU11-(BV11+BW11+BX11))+(BV11*2)+(BW11*3)+(BX11*4) | CH11: =BS11+CA11+CC11+CD11+CE11+CF11 | CX11: =(CL11-(CM11+CN11+CO11))+(CM11*2)+(CN11*3)+(CO11*4) | CY11: =CJ11+CR11+CT11+CU11+CV11+CW11 | DO11: =(DC11-(DD11+DE11+DF11))+(DD11*2)+(DE11*3)+(DF11*4) | DP11: =DA11+DI11+DK11+DL11+DM11+DN11 | EF11: =(DT11-(DU11+DV11+DW11))+(DU11*2)+(DV11*3)+(DW11*4) | EG11: =DR11+DZ11+EB11+EC11+ED11+EE11 | EW11: =(EK11-(EL11+EM11+EN11))+(EL11*2)+(EM11*3)+(EN11*4) | EX11: =EI11+EQ11+ES11+ET11+EU11+EV11 | FN11: =(FB11-(FC11+FD11+FE11))+(FC11*2)+(FD11*3)+(FE11*4) | FO11: =EZ11+FH11+FJ11+FK11+FL11+FM11 | GE11: =(FS11-(FT11+FU11+FV11))+(FT11*2)+(FU11*3)+(FV11*4) | GF11: =FQ11+FY11+GA11+GB11+GC11+GD11 | GV11: =(GJ11-(GK11+GL11+GM11))+(GK11*2)+(GL11*3)+(GM11*4) | GW11: =GH11+GP11+GR11+GS11+GT11+GU11 | HM11: =(HA11-(HB11+HC11+HD11))+(HB11*2)+(HC11*3)+(HD11*4) | HN11: =GY11+HG11+HI11+HJ11+HK11+HL11 | ID11: =(HR11-(HS11+HT11+HU11))+(HS11*2)+(HT11*3)+(HU11*4) | IE11: =HP11+HX11+HZ11+IA11+IB11+IC11 | IU11: =(II11-(IJ11+IK11+IL11))+(IJ11*2)+(IK11*3)+(IL11*4) | IV11: =IG11+IO11+IQ11+IR11+IS11+IT11
A12: DANIEL LIENDO | C12: 1 | Q12: =(E12-(F12+G12+H12))+(F12*2)+(G12*3)+(H12*4) | R12: =C12+K12+M12+N12+O12+P12 | AH12: =(V12-(W12+X12+Y12))+(W12*2)+(X12*3)+(Y12*4) | AI12: =T12+AB12+AD12+AE12+AF12+AG12 | AY12: =(AM12-(AN12+AO12+AP12))+(AN12*2)+(AO12*3)+(AP12*4) | AZ12: =AK12+AS12+AU12+AV12+AW12+AX12 | BP12: =(BD12-(BE12+BF12+BG12))+(BE12*2)+(BF12*3)+(BG12*4) | BQ12: =BB12+BJ12+BL12+BM12+BN12+BO12 | CG12: =(BU12-(BV12+BW12+BX12))+(BV12*2)+(BW12*3)+(BX12*4) | CH12: =BS12+CA12+CC12+CD12+CE12+CF12 | CX12: =(CL12-(CM12+CN12+CO12))+(CM12*2)+(CN12*3)+(CO12*4) | CY12: =CJ12+CR12+CT12+CU12+CV12+CW12 | DO12: =(DC12-(DD12+DE12+DF12))+(DD12*2)+(DE12*3)+(DF12*4) | DP12: =DA12+DI12+DK12+DL12+DM12+DN12 | EF12: =(DT12-(DU12+DV12+DW12))+(DU12*2)+(DV12*3)+(DW12*4) | EG12: =DR12+DZ12+EB12+EC12+ED12+EE12 | EW12: =(EK12-(EL12+EM12+EN12))+(EL12*2)+(EM12*3)+(EN12*4) | EX12: =EI12+EQ12+ES12+ET12+EU12+EV12 | FN12: =(FB12-(FC12+FD12+FE12))+(FC12*2)+(FD12*3)+(FE12*4) | FO12: =EZ12+FH12+FJ12+FK12+FL12+FM12 | GE12: =(FS12-(FT12+FU12+FV12))+(FT12*2)+(FU12*3)+(FV12*4) | GF12: =FQ12+FY12+GA12+GB12+GC12+GD12 | GV12: =(GJ12-(GK12+GL12+GM12))+(GK12*2)+(GL12*3)+(GM12*4) | GW12: =GH12+GP12+GR12+GS12+GT12+GU12 | HM12: =(HA12-(HB12+HC12+HD12))+(HB12*2)+(HC12*3)+(HD12*4) | HN12: =GY12+HG12+HI12+HJ12+HK12+HL12 | ID12: =(HR12-(HS12+HT12+HU12))+(HS12*2)+(HT12*3)+(HU12*4) | IE12: =HP12+HX12+HZ12+IA12+IB12+IC12 | IU12: =(II12-(IJ12+IK12+IL12))+(IJ12*2)+(IK12*3)+(IL12*4) | IV12: =IG12+IO12+IQ12+IR12+IS12+IT12
A13: SEBASTIAN MUJICA | C13: 2 | J13: 1 | Q13: =(E13-(F13+G13+H13))+(F13*2)+(G13*3)+(H13*4) | R13: =C13+K13+M13+N13+O13+P13 | AH13: =(V13-(W13+X13+Y13))+(W13*2)+(X13*3)+(Y13*4) | AI13: =T13+AB13+AD13+AE13+AF13+AG13 | AY13: =(AM13-(AN13+AO13+AP13))+(AN13*2)+(AO13*3)+(AP13*4) | AZ13: =AK13+AS13+AU13+AV13+AW13+AX13 | BP13: =(BD13-(BE13+BF13+BG13))+(BE13*2)+(BF13*3)+(BG13*4) | BQ13: =BB13+BJ13+BL13+BM13+BN13+BO13 | CG13: =(BU13-(BV13+BW13+BX13))+(BV13*2)+(BW13*3)+(BX13*4) | CH13: =BS13+CA13+CC13+CD13+CE13+CF13 | CX13: =(CL13-(CM13+CN13+CO13))+(CM13*2)+(CN13*3)+(CO13*4) | CY13: =CJ13+CR13+CT13+CU13+CV13+CW13 | DO13: =(DC13-(DD13+DE13+DF13))+(DD13*2)+(DE13*3)+(DF13*4) | DP13: =DA13+DI13+DK13+DL13+DM13+DN13 | EF13: =(DT13-(DU13+DV13+DW13))+(DU13*2)+(DV13*3)+(DW13*4) | EG13: =DR13+DZ13+EB13+EC13+ED13+EE13 | EW13: =(EK13-(EL13+EM13+EN13))+(EL13*2)+(EM13*3)+(EN13*4) | EX13: =EI13+EQ13+ES13+ET13+EU13+EV13 | FN13: =(FB13-(FC13+FD13+FE13))+(FC13*2)+(FD13*3)+(FE13*4) | FO13: =EZ13+FH13+FJ13+FK13+FL13+FM13 | GE13: =(FS13-(FT13+FU13+FV13))+(FT13*2)+(FU13*3)+(FV13*4) | GF13: =FQ13+FY13+GA13+GB13+GC13+GD13 | GV13: =(GJ13-(GK13+GL13+GM13))+(GK13*2)+(GL13*3)+(GM13*4) | GW13: =GH13+GP13+GR13+GS13+GT13+GU13 | HM13: =(HA13-(HB13+HC13+HD13))+(HB13*2)+(HC13*3)+(HD13*4) | HN13: =GY13+HG13+HI13+HJ13+HK13+HL13 | ID13: =(HR13-(HS13+HT13+HU13))+(HS13*2)+(HT13*3)+(HU13*4) | IE13: =HP13+HX13+HZ13+IA13+IB13+IC13 | IU13: =(II13-(IJ13+IK13+IL13))+(IJ13*2)+(IK13*3)+(IL13*4) | IV13: =IG13+IO13+IQ13+IR13+IS13+IT13
